package beyondspace.world.generation.structures;

import java.util.Random;

import beyondspace.utils.RegistrationsList;
import net.minecraft.block.Block;
import net.minecraft.block.material.Material;
import net.minecraft.init.Blocks;
import net.minecraft.world.World;
import net.minecraft.world.gen.feature.WorldGenerator;

public class HCloud9 extends WorldGenerator {
	protected Block[] GetValidSpawnBlocks() {
		return new Block[] { Blocks.air, };
	}

	public boolean LocationIsValidSpawn(World world, int x, int y, int z) {

		Block checkBlock = world.getBlock(x, y - 1, z);
		Block blockAbove = world.getBlock(x, y, z);
		Block blockBelow = world.getBlock(x, y - 2, z);

		for (Block i : GetValidSpawnBlocks()) {
			if (blockAbove != Blocks.air) {
				return false;
			}
			if (checkBlock == i) {
				return true;
			} else if (checkBlock == Blocks.snow_layer && blockBelow == i) {
				return true;
			} else if (checkBlock.getMaterial() == Material.plants && blockBelow == i) {
				return true;
			}
		}
		return false;
	}

	public boolean generate(World world, Random rand, int x, int y, int z) {
		int i = rand.nextInt(4);

		if (i == 0) {
			generate_r0(world, rand, x, y, z);
		}

		if (i == 1) {
			generate_r1(world, rand, x, y, z);
		}

		if (i == 2) {
			generate_r2(world, rand, x, y, z);
		}

		if (i == 3) {
			generate_r3(world, rand, x, y, z);
		}

		return true;

	}

	public boolean generate_r0(World world, Random rand, int x, int y, int z) {
		if (!LocationIsValidSpawn(world, x + 4, y, z + 7)) {
			return false;
		}

		world.setBlock(x + 7, y + 0, z + 1, RegistrationsList.HCloud, 0, 3);
		world.setBlock(x + 6, y + 0, z + 2, RegistrationsList.HCloud, 0, 3);
		world.setBlock(x + 7, y + 0, z + 2, RegistrationsList.HCloud, 0, 3);
		world.setBlock(x + 8, y + 0, z + 2, RegistrationsList.HCloud, 0, 3);
		world.setBlock(x + 7, y + 0, z + 3, RegistrationsList.HCloud, 0, 3);
		world.setBlock(x + 6, y + 1, z + 0, RegistrationsList.HCloud, 0, 3);
		world.setBlock(x + 5, y + 1, z + 1, RegistrationsList.HCloud, 0, 3);
		world.setBlock(x + 6, y + 1, z + 1, RegistrationsList.HCloud, 0, 3);
		world.setBlock(x + 7, y + 1, z + 1, RegistrationsList.HCloud, 0, 3);
		world.setBlock(x + 8, y + 1, z + 1, RegistrationsList.HCloud, 0, 3);
		world.setBlock(x + 6, y + 1, z + 2, RegistrationsList.HCloud, 0, 3);
		world.setBlock(x + 7, y + 1, z + 2, RegistrationsList.HCloud, 0, 3);
		world.setBlock(x + 8, y + 1, z + 2, RegistrationsList.HCloud, 0, 3);
		world.setBlock(x + 6, y + 1, z + 3, RegistrationsList.HCloud, 0, 3);
		world.setBlock(x + 7, y + 1, z + 3, RegistrationsList.HCloud, 0, 3);
		world.setBlock(x + 8, y + 1, z + 3, RegistrationsList.HCloud, 0, 3);
		world.setBlock(x + 5, y + 2, z + 0, RegistrationsList.HCloud, 0, 3);
		world.setBlock(x + 6, y + 2, z + 0, RegistrationsList.HCloud, 0, 3);
		world.setBlock(x + 7, y + 2, z + 0, RegistrationsList.HCloud, 0, 3);
		world.setBlock(x + 4, y + 2, z + 1, RegistrationsList.HCloud, 0, 3);
		world.setBlock(x + 5, y + 2, z + 1, RegistrationsList.HCloud, 0, 3);
		world.setBlock(x + 6, y + 2, z + 1, RegistrationsList.HCloud, 0, 3);
		world.setBlock(x + 7, y + 2, z + 1, RegistrationsList.HCloud, 0, 3);
		world.setBlock(x + 5, y + 2, z + 2, RegistrationsList.HCloud, 0, 3);
		world.setBlock(x + 6, y + 2, z + 2, RegistrationsList.HCloud, 0, 3);
		world.setBlock(x + 7, y + 2, z + 2, RegistrationsList.HCloud, 0, 3);
		world.setBlock(x + 8, y + 2, z + 2, RegistrationsList.HCloud, 0, 3);
		world.setBlock(x + 7, y + 2, z + 3, RegistrationsList.HCloud, 0, 3);
		world.setBlock(x + 4, y + 3, z + 0, RegistrationsList.HCloud, 0, 3);
		world.setBlock(x + 5, y + 3, z + 0, RegistrationsList.HCloud, 0, 3);
		world.setBlock(x + 6, y + 3, z + 0, RegistrationsList.HCloud, 0, 3);
		world.setBlock(x + 4, y + 3, z + 1, RegistrationsList.HCloud, 0, 3);
		world.setBlock(x + 5, y + 3, z + 1, RegistrationsList.HCloud, 0, 3);
		world.setBlock(x + 6, y + 3, z + 1, RegistrationsList.HCloud, 0, 3);
		world.setBlock(x + 7, y + 3, z + 1, RegistrationsList.HCloud, 0, 3);
		world.setBlock(x + 3, y + 3, z + 2, RegistrationsList.HCloud, 0, 3);
		world.setBlock(x + 4, y + 3, z + 2, RegistrationsList.HCloud, 0, 3);
		world.setBlock(x + 5, y + 3, z + 2, RegistrationsList.HCloud, 0, 3);
		world.setBlock(x + 6, y + 3, z + 2, RegistrationsList.HCloud, 0, 3);
		world.setBlock(x + 4, y + 3, z + 3, RegistrationsList.HCloud, 0, 3);
		world.setBlock(x + 5, y + 4, z + 0, RegistrationsList.HCloud, 0, 3);
		world.setBlock(x + 3, y + 4, z + 1, RegistrationsList.HCloud, 0, 3);
		world.setBlock(x + 4, y + 4, z + 1, RegistrationsList.HCloud, 0, 3);
		world.setBlock(x + 5, y + 4, z + 1, RegistrationsList.HCloud, 0, 3);
		world.setBlock(x + 6, y + 4, z + 1, RegistrationsList.HCloud, 0, 3);
		world.setBlock(x + 3, y + 4, z + 2, RegistrationsList.HCloud, 0, 3);
		world.setBlock(x + 4, y + 4, z + 2, RegistrationsList.HCloud, 0, 3);
		world.setBlock(x + 5, y + 4, z + 2, RegistrationsList.HCloud, 0, 3);
		world.setBlock(x + 3, y + 4, z + 3, RegistrationsList.HCloud, 0, 3);
		world.setBlock(x + 4, y + 4, z + 3, RegistrationsList.HCloud, 0, 3);
		world.setBlock(x + 5, y + 4, z + 3, RegistrationsList.HCloud, 0, 3);
		world.setBlock(x + 3, y + 5, z + 1, RegistrationsList.HCloud, 0, 3);
		world.setBlock(x + 4, y + 5, z + 1, RegistrationsList.HCloud, 0, 3);
		world.setBlock(x + 2, y + 5, z + 2, RegistrationsList.HCloud, 0, 3);
		world.setBlock(x + 3, y + 5, z + 2, RegistrationsList.HCloud, 0, 3);
		world.setBlock(x + 4, y + 5, z + 2, RegistrationsList.HCloud, 0, 3);
		world.setBlock(x + 5, y + 5, z + 2, RegistrationsList.HCloud, 0, 3);
		world.setBlock(x + 3, y + 5, z + 3, RegistrationsList.HCloud, 0, 3);
		world.setBlock(x + 4, y + 5, z + 3, RegistrationsList.HCloud, 0, 3);
		world.setBlock(x + 2, y + 6, z + 1, RegistrationsList.HCloud, 0, 3);
		world.setBlock(x + 3, y + 6, z + 1, RegistrationsList.HCloud, 0, 3);
		world.setBlock(x + 4, y + 6, z + 1, RegistrationsList.HCloud, 0, 3);
		world.setBlock(x + 2, y + 6, z + 2, RegistrationsList.HCloud, 0, 3);
		world.setBlock(x + 3, y + 6, z + 2, RegistrationsList.HCloud, 0, 3);
		world.setBlock(x + 4, y + 6, z + 2, RegistrationsList.HCloud, 0, 3);
		world.setBlock(x + 1, y + 6, z + 3, RegistrationsList.HCloud, 0, 3);
		world.setBlock(x + 2, y + 6, z + 3, RegistrationsList.HCloud, 0, 3);
		world.setBlock(x + 3, y + 6, z + 3, RegistrationsList.HCloud, 0, 3);
		world.setBlock(x + 4, y + 6, z + 3, RegistrationsList.HCloud, 0, 3);
		world.setBlock(x + 0, y + 6, z + 4, RegistrationsList.HCloud, 0, 3);
		world.setBlock(x + 1, y + 6, z + 4, RegistrationsList.HCloud, 0, 3);
		world.setBlock(x + 2, y + 6, z + 4, RegistrationsList.HCloud, 0, 3);
		world.setBlock(x + 3, y + 6, z + 4, RegistrationsList.HCloud, 0, 3);
		world.setBlock(x + 1, y + 6, z + 5, RegistrationsList.HCloud, 0, 3);
		world.setBlock(x + 2, y + 6, z + 5, RegistrationsList.HCloud, 0, 3);
		world.setBlock(x + 3, y + 6, z + 5, RegistrationsList.HCloud, 0, 3);
		world.setBlock(x + 2, y + 6, z + 6, RegistrationsList.HCloud, 0, 3);
		world.setBlock(x + 3, y + 7, z + 1, RegistrationsList.HCloud, 0, 3);
		world.setBlock(x + 1, y + 7, z + 2, RegistrationsList.HCloud, 0, 3);
		world.setBlock(x + 2, y + 7, z + 2, RegistrationsList.HCloud, 0, 3);
		world.setBlock(x + 3, y + 7, z + 2, RegistrationsList.HCloud, 0, 3);
		world.setBlock(x + 4, y + 7, z + 2, RegistrationsList.HCloud, 0, 3);
		world.setBlock(x + 0, y + 7, z + 3, RegistrationsList.HCloud, 0, 3);
		world.setBlock(x + 1, y + 7, z + 3, RegistrationsList.HCloud, 0, 3);
		world.setBlock(x + 2, y + 7, z + 3, RegistrationsList.HCloud, 0, 3);
		world.setBlock(x + 3, y + 7, z + 3, RegistrationsList.HCloud, 0, 3);
		world.setBlock(x + 0, y + 7, z + 4, RegistrationsList.HCloud, 0, 3);
		world.setBlock(x + 1, y + 7, z + 4, RegistrationsList.HCloud, 0, 3);
		world.setBlock(x + 2, y + 7, z + 4, RegistrationsList.HCloud, 0, 3);
		world.setBlock(x + 3, y + 7, z + 4, RegistrationsList.HCloud, 0, 3);
		world.setBlock(x + 0, y + 7, z + 5, RegistrationsList.HCloud, 0, 3);
		world.setBlock(x + 1, y + 7, z + 5, RegistrationsList.HCloud, 0, 3);
		world.setBlock(x + 2, y + 7, z + 5, RegistrationsList.HCloud, 0, 3);
		world.setBlock(x + 3, y + 7, z + 5, RegistrationsList.HCloud, 0, 3);
		world.setBlock(x + 0, y + 7, z + 6, RegistrationsList.HCloud, 0, 3);
		world.setBlock(x + 1, y + 7, z + 6, RegistrationsList.HCloud, 0, 3);
		world.setBlock(x + 2, y + 7, z + 6, RegistrationsList.HCloud, 0, 3);
		world.setBlock(x + 3, y + 7, z + 6, RegistrationsList.HCloud, 0, 3);
		world.setBlock(x + 1, y + 7, z + 7, RegistrationsList.HCloud, 0, 3);
		world.setBlock(x + 2, y + 8, z + 2, RegistrationsList.HCloud, 0, 3);
		world.setBlock(x + 1, y + 8, z + 3, RegistrationsList.HCloud, 0, 3);
		world.setBlock(x + 2, y + 8, z + 3, RegistrationsList.HCloud, 0, 3);
		world.setBlock(x + 0, y + 8, z + 4, RegistrationsList.HCloud, 0, 3);
		world.setBlock(x + 1, y + 8, z + 4, RegistrationsList.HCloud, 0, 3);
		world.setBlock(x + 2, y + 8, z + 4, RegistrationsList.HCloud, 0, 3);
		world.setBlock(x + 3, y + 8, z + 4, RegistrationsList.HCloud, 0, 3);
		world.setBlock(x + 0, y + 8, z + 5, RegistrationsList.HCloud, 0, 3);
		world.setBlock(x + 1, y + 8, z + 5, RegistrationsList.HCloud, 0, 3);
		world.setBlock(x + 2, y + 8, z + 5, RegistrationsList.HCloud, 0, 3);
		world.setBlock(x + 3, y + 8, z + 5, RegistrationsList.HCloud, 0, 3);
		world.setBlock(x + 0, y + 8, z + 6, RegistrationsList.HCloud, 0, 3);
		world.setBlock(x + 1, y + 8, z + 6, RegistrationsList.HCloud, 0, 3);
		world.setBlock(x + 2, y + 8, z + 6, RegistrationsList.HCloud, 0, 3);
		world.setBlock(x + 3, y + 8, z + 6, RegistrationsList.HCloud, 0, 3);
		world.setBlock(x + 0, y + 8, z + 7, RegistrationsList.HCloud, 0, 3);
		world.setBlock(x + 1, y + 8, z + 7, RegistrationsList.HCloud, 0, 3);
		world.setBlock(x + 2, y + 8, z + 7, RegistrationsList.HCloud, 0, 3);
		world.setBlock(x + 0, y + 8, z + 8, RegistrationsList.HCloud, 0, 3);
		world.setBlock(x + 1, y + 8, z + 8, RegistrationsList.HCloud, 0, 3);
		world.setBlock(x + 2, y + 8, z + 8, RegistrationsList.HCloud, 0, 3);
		world.setBlock(x + 1, y + 8, z + 9, RegistrationsList.HCloud, 0, 3);
		world.setBlock(x + 1, y + 9, z + 5, RegistrationsList.HCloud, 0, 3);
		world.setBlock(x + 0, y + 9, z + 6, RegistrationsList.HCloud, 0, 3);
		world.setBlock(x + 1, y + 9, z + 6, RegistrationsList.HCloud, 0, 3);
		world.setBlock(x + 2, y + 9, z + 6, RegistrationsList.HCloud, 0, 3);
		world.setBlock(x + 0, y + 9, z + 7, RegistrationsList.HCloud, 0, 3);
		world.setBlock(x + 1, y + 9, z + 7, RegistrationsList.HCloud, 0, 3);
		world.setBlock(x + 2, y + 9, z + 7, RegistrationsList.HCloud, 0, 3);
		world.setBlock(x + 0, y + 9, z + 8, RegistrationsList.HCloud, 0, 3);
		world.setBlock(x + 1, y + 9, z + 8, RegistrationsList.HCloud, 0, 3);
		world.setBlock(x + 2, y + 9, z + 8, RegistrationsList.HCloud, 0, 3);
		world.setBlock(x + 0, y + 9, z + 9, RegistrationsList.HCloud, 0, 3);
		world.setBlock(x + 1, y + 9, z + 9, RegistrationsList.HCloud, 0, 3);
		world.setBlock(x + 2, y + 9, z + 9, RegistrationsList.HCloud, 0, 3);
		world.setBlock(x + 1, y + 9, z + 10, RegistrationsList.HCloud, 0, 3);
		world.setBlock(x + 1, y + 10, z + 7, RegistrationsList.HCloud, 0, 3);
		world.setBlock(x + 0, y + 10, z + 8, RegistrationsList.HCloud, 0, 3);
		world.setBlock(x + 1, y + 10, z + 8, RegistrationsList.HCloud, 0, 3);
		world.setBlock(x + 2, y + 10, z + 8, RegistrationsList.HCloud, 0, 3);
		world.setBlock(x + 0, y + 10, z + 9, RegistrationsList.HCloud, 0, 3);
		world.setBlock(x + 1, y + 10, z + 9, RegistrationsList.HCloud, 0, 3);
		world.setBlock(x + 2, y + 10, z + 9, RegistrationsList.HCloud, 0, 3);
		world.setBlock(x + 0, y + 10, z + 10, RegistrationsList.HCloud, 0, 3);
		world.setBlock(x + 1, y + 10, z + 10, RegistrationsList.HCloud, 0, 3);
		world.setBlock(x + 2, y + 10, z + 10, RegistrationsList.HCloud, 0, 3);
		world.setBlock(x + 0, y + 10, z + 11, RegistrationsList.HCloud, 0, 3);
		world.setBlock(x + 1, y + 10, z + 11, RegistrationsList.HCloud, 0, 3);
		world.setBlock(x + 2, y + 10, z + 11, RegistrationsList.HCloud, 0, 3);
		world.setBlock(x + 1, y + 10, z + 12, RegistrationsList.HCloud, 0, 3);
		world.setBlock(x + 2, y + 10, z + 12, RegistrationsList.HCloud, 0, 3);
		world.setBlock(x + 3, y + 10, z + 12, RegistrationsList.HCloud, 0, 3);
		world.setBlock(x + 2, y + 10, z + 13, RegistrationsList.HCloud, 0, 3);
		world.setBlock(x + 1, y + 11, z + 8, RegistrationsList.HCloud, 0, 3);
		world.setBlock(x + 0, y + 11, z + 9, RegistrationsList.HCloud, 0, 3);
		world.setBlock(x + 1, y + 11, z + 9, RegistrationsList.HCloud, 0, 3);
		world.setBlock(x + 2, y + 11, z + 9, RegistrationsList.HCloud, 0, 3);
		world.setBlock(x + 0, y + 11, z + 10, RegistrationsList.HCloud, 0, 3);
		world.setBlock(x + 1, y + 11, z + 10, RegistrationsList.HCloud, 0, 3);
		world.setBlock(x + 2, y + 11, z + 10, RegistrationsList.HCloud, 0, 3);
		world.setBlock(x + 0, y + 11, z + 11, RegistrationsList.HCloud, 0, 3);
		world.setBlock(x + 1, y + 11, z + 11, RegistrationsList.HCloud, 0, 3);
		world.setBlock(x + 2, y + 11, z + 11, RegistrationsList.HCloud, 0, 3);
		world.setBlock(x + 3, y + 11, z + 11, RegistrationsList.HCloud, 0, 3);
		world.setBlock(x + 0, y + 11, z + 12, RegistrationsList.HCloud, 0, 3);
		world.setBlock(x + 1, y + 11, z + 12, RegistrationsList.HCloud, 0, 3);
		world.setBlock(x + 2, y + 11, z + 12, RegistrationsList.HCloud, 0, 3);
		world.setBlock(x + 3, y + 11, z + 12, RegistrationsList.HCloud, 0, 3);
		world.setBlock(x + 1, y + 11, z + 13, RegistrationsList.HCloud, 0, 3);
		world.setBlock(x + 2, y + 11, z + 13, RegistrationsList.HCloud, 0, 3);
		world.setBlock(x + 3, y + 11, z + 13, RegistrationsList.HCloud, 0, 3);
		world.setBlock(x + 2, y + 11, z + 14, RegistrationsList.HCloud, 0, 3);
		world.setBlock(x + 1, y + 12, z + 10, RegistrationsList.HCloud, 0, 3);
		world.setBlock(x + 0, y + 12, z + 11, RegistrationsList.HCloud, 0, 3);
		world.setBlock(x + 1, y + 12, z + 11, RegistrationsList.HCloud, 0, 3);
		world.setBlock(x + 2, y + 12, z + 11, RegistrationsList.HCloud, 0, 3);
		world.setBlock(x + 1, y + 12, z + 12, RegistrationsList.HCloud, 0, 3);
		world.setBlock(x + 2, y + 12, z + 12, RegistrationsList.HCloud, 0, 3);
		world.setBlock(x + 3, y + 12, z + 12, RegistrationsList.HCloud, 0, 3);
		world.setBlock(x + 1, y + 12, z + 13, RegistrationsList.HCloud, 0, 3);
		world.setBlock(x + 2, y + 12, z + 13, RegistrationsList.HCloud, 0, 3);
		world.setBlock(x + 3, y + 12, z + 13, RegistrationsList.HCloud, 0, 3);
		world.setBlock(x + 1, y + 12, z + 14, RegistrationsList.HCloud, 0, 3);
		world.setBlock(x + 2, y + 12, z + 14, RegistrationsList.HCloud, 0, 3);
		world.setBlock(x + 3, y + 12, z + 14, RegistrationsList.HCloud, 0, 3);
		world.setBlock(x + 2, y + 13, z + 12, RegistrationsList.HCloud, 0, 3);
		world.setBlock(x + 1, y + 13, z + 13, RegistrationsList.HCloud, 0, 3);
		world.setBlock(x + 2, y + 13, z + 13, RegistrationsList.HCloud, 0, 3);
		world.setBlock(x + 3, y + 13, z + 13, RegistrationsList.HCloud, 0, 3);
		world.setBlock(x + 2, y + 13, z + 14, RegistrationsList.HCloud, 0, 3);
		return true;

	}
	public boolean generate_r1(World world, Random rand, int x, int y, int z)
{
		if(!LocationIsValidSpawn(world, x + 7, y, z + 4))
		{
			return false;
		}

		world.setBlock(x + 1, y + 0, z + 1, RegistrationsList.HCloud, 0, 3);
		world.setBlock(x + 2, y + 0, z + 2, RegistrationsList.HCloud, 0, 3);
		world.setBlock(x + 2, y + 0, z + 1, RegistrationsList.HCloud, 0, 3);
		world.setBlock(x + 2, y + 0, z + 0, RegistrationsList.HCloud, 0, 3);
		world.setBlock(x + 3, y + 0, z + 1, RegistrationsList.HCloud, 0, 3);
		world.setBlock(x + 0, y + 1, z + 2, RegistrationsList.HCloud, 0, 3);
		world.setBlock(x + 1, y + 1, z + 3, RegistrationsList.HCloud, 0, 3);
		world.setBlock(x + 1, y + 1, z + 2, RegistrationsList.HCloud, 0, 3);
		world.setBlock(x + 1, y + 1, z + 1, RegistrationsList.HCloud, 0, 3);
		world.setBlock(x + 1, y + 1, z + 0, RegistrationsList.HCloud, 0, 3);
		world.setBlock(x + 2, y + 1, z + 2, RegistrationsList.HCloud, 0, 3);
		world.setBlock(x + 2, y + 1, z + 1, RegistrationsList.HCloud, 0, 3);
		world.setBlock(x + 2, y + 1, z + 0, RegistrationsList.HCloud, 0, 3);
		world.setBlock(x + 3, y + 1, z + 2, RegistrationsList.HCloud, 0, 3);
		world.setBlock(x + 3, y + 1, z + 1, RegistrationsList.HCloud, 0, 3);
		world.setBlock(x + 3, y + 1, z + 0, RegistrationsList.HCloud, 0, 3);
		world.setBlock(x + 0, y + 2, z + 3, RegistrationsList.HCloud, 0, 3);
		world.setBlock(x + 0, y + 2, z + 2, RegistrationsList.HCloud, 0, 3);
		world.setBlock(x + 0, y + 2, z + 1, RegistrationsList.HCloud, 0, 3);
		world.setBlock(x + 1, y + 2, z + 4, RegistrationsList.HCloud, 0, 3);
		world.setBlock(x + 1, y + 2, z + 3, RegistrationsList.HCloud, 0, 3);
		world.setBlock(x + 1, y + 2, z + 2, RegistrationsList.HCloud, 0, 3);
		world.setBlock(x + 1, y + 2, z + 1, RegistrationsList.HCloud, 0, 3);
		world.setBlock(x + 2, y + 2, z + 3, RegistrationsList.HCloud, 0, 3);
		world.setBlock(x + 2, y + 2, z + 2, RegistrationsList.HCloud, 0, 3);
		world.setBlock(x + 2, y + 2, z + 1, RegistrationsList.HCloud, 0, 3);
		world.setBlock(x + 2, y + 2, z + 0, RegistrationsList.HCloud, 0, 3);
		world.setBlock(x + 3, y + 2, z + 1, RegistrationsList.HCloud, 0, 3);
		world.setBlock(x + 0, y + 3, z + 4, RegistrationsList.HCloud, 0, 3);
		world.setBlock(x + 0, y + 3, z + 3, RegistrationsList.HCloud, 0, 3);
		world.setBlock(x + 0, y + 3, z + 2, RegistrationsList.HCloud, 0, 3);
		world.setBlock(x + 1, y + 3, z + 4, RegistrationsList.HCloud, 0, 3);
		world.setBlock(x + 1, y + 3, z + 3, RegistrationsList.HCloud, 0, 3);
		world.setBlock(x + 1, y + 3, z + 2, RegistrationsList.HCloud, 0, 3);
		world.setBlock(x + 1, y + 3, z + 1, RegistrationsList.HCloud, 0, 3);
		world.setBlock(x + 2, y + 3, z + 5, RegistrationsList.HCloud, 0, 3);
		world.setBlock(x + 2, y + 3, z + 4, RegistrationsList.HCloud, 0, 3);
		world.setBlock(x + 2, y + 3, z + 3, RegistrationsList.HCloud, 0, 3);
		world.setBlock(x + 2, y + 3, z + 2, RegistrationsList.HCloud, 0, 3);
		world.setBlock(x + 3, y + 3, z + 4, RegistrationsList.HCloud, 0, 3);
		world.setBlock(x + 0, y + 4, z + 3, RegistrationsList.HCloud, 0, 3);
		world.setBlock(x + 1, y + 4, z + 5, RegistrationsList.HCloud, 0, 3);
		world.setBlock(x + 1, y + 4, z + 4, RegistrationsList.HCloud, 0, 3);
		world.setBlock(x + 1, y + 4, z + 3, RegistrationsList.HCloud, 0, 3);
		world.setBlock(x + 1, y + 4, z + 2, RegistrationsList.HCloud, 0, 3);
		world.setBlock(x + 2, y + 4, z + 5, RegistrationsList.HCloud, 0, 3);
		world.setBlock(x + 2, y + 4, z + 4, RegistrationsList.HCloud, 0, 3);
		world.setBlock(x + 2, y + 4, z + 3, RegistrationsList.HCloud, 0, 3);
		world.setBlock(x + 3, y + 4, z + 5, RegistrationsList.HCloud, 0, 3);
		world.setBlock(x + 3, y + 4, z + 4, RegistrationsList.HCloud, 0, 3);
		world.setBlock(x + 3, y + 4, z + 3, RegistrationsList.HCloud, 0, 3);
		world.setBlock(x + 1, y + 5, z + 5, RegistrationsList.HCloud, 0, 3);
		world.setBlock(x + 1, y + 5, z + 4, RegistrationsList.HCloud, 0, 3);
		world.setBlock(x + 2, y + 5, z + 6, RegistrationsList.HCloud, 0, 3);
		world.setBlock(x + 2, y + 5, z + 5, RegistrationsList.HCloud, 0, 3);
		world.setBlock(x + 2, y + 5, z + 4, RegistrationsList.HCloud, 0, 3);
		world.setBlock(x + 2, y + 5, z + 3, RegistrationsList.HCloud, 0, 3);
		world.setBlock(x + 3, y + 5, z + 5, RegistrationsList.HCloud, 0, 3);
		world.setBlock(x + 3, y + 5, z + 4, RegistrationsList.HCloud, 0, 3);
		world.setBlock(x + 1, y + 6, z + 6, RegistrationsList.HCloud, 0, 3);
		world.setBlock(x + 1, y + 6, z + 5, RegistrationsList.HCloud, 0, 3);
		world.setBlock(x + 1, y + 6, z + 4, RegistrationsList.HCloud, 0, 3);
		world.setBlock(x + 2, y + 6, z + 6, RegistrationsList.HCloud, 0, 3);
		world.setBlock(x + 2, y + 6, z + 5, RegistrationsList.HCloud, 0, 3);
		world.setBlock(x + 2, y + 6, z + 4, RegistrationsList.HCloud, 0, 3);
		world.setBlock(x + 3, y + 6, z + 7, RegistrationsList.HCloud, 0, 3);
		world.setBlock(x + 3, y + 6, z + 6, RegistrationsList.HCloud, 0, 3);
		world.setBlock(x + 3, y + 6, z + 5, RegistrationsList.HCloud, 0, 3);
		world.setBlock(x + 3, y + 6, z + 4, RegistrationsList.HCloud, 0, 3);
		world.setBlock(x + 4, y + 6, z + 8, RegistrationsList.HCloud, 0, 3);
		world.setBlock(x + 4, y + 6, z + 7, RegistrationsList.HCloud, 0, 3);
		world.setBlock(x + 4, y + 6, z + 6, RegistrationsList.HCloud, 0, 3);
		world.setBlock(x + 4, y + 6, z + 5, RegistrationsList.HCloud, 0, 3);
		world.setBlock(x + 5, y + 6, z + 7, RegistrationsList.HCloud, 0, 3);
		world.setBlock(x + 5, y + 6, z + 6, RegistrationsList.HCloud, 0, 3);
		world.setBlock(x + 5, y + 6, z + 5, RegistrationsList.HCloud, 0, 3);
		world.setBlock(x + 6, y + 6, z + 6, RegistrationsList.HCloud, 0, 3);
		world.setBlock(x + 1, y + 7, z + 5, RegistrationsList.HCloud, 0, 3);
		world.setBlock(x + 2, y + 7, z + 7, RegistrationsList.HCloud, 0, 3);
		world.setBlock(x + 2, y + 7, z + 6, RegistrationsList.HCloud, 0, 3);
		world.setBlock(x + 2, y + 7, z + 5, RegistrationsList.HCloud, 0, 3);
		world.setBlock(x + 2, y + 7, z + 4, RegistrationsList.HCloud, 0, 3);
		world.setBlock(x + 3, y + 7, z + 8, RegistrationsList.HCloud, 0, 3);
		world.setBlock(x + 3, y + 7, z + 7, RegistrationsList.HCloud, 0, 3);
		world.setBlock(x + 3, y + 7, z + 6, RegistrationsList.HCloud, 0, 3);
		world.setBlock(x + 3, y + 7, z + 5, RegistrationsList.HCloud, 0, 3);
		world.setBlock(x + 4, y + 7, z + 8, RegistrationsList.HCloud, 0, 3);
		world.setBlock(x + 4, y + 7, z + 7, RegistrationsList.HCloud, 0, 3);
		world.setBlock(x + 4, y + 7, z + 6, RegistrationsList.HCloud, 0, 3);
		world.setBlock(x + 4, y + 7, z + 5, RegistrationsList.HCloud, 0, 3);
		world.setBlock(x + 5, y + 7, z + 8, RegistrationsList.HCloud, 0, 3);
		world.setBlock(x + 5, y + 7, z + 7, RegistrationsList.HCloud, 0, 3);
		world.setBlock(x + 5, y + 7, z + 6, RegistrationsList.HCloud, 0, 3);
		world.setBlock(x + 5, y + 7, z + 5, RegistrationsList.HCloud, 0, 3);
		world.setBlock(x + 6, y + 7, z + 8, RegistrationsList.HCloud, 0, 3);
		world.setBlock(x + 6, y + 7, z + 7, RegistrationsList.HCloud, 0, 3);
		world.setBlock(x + 6, y + 7, z + 6, RegistrationsList.HCloud, 0, 3);
		world.setBlock(x + 6, y + 7, z + 5, RegistrationsList.HCloud, 0, 3);
		world.setBlock(x + 7, y + 7, z + 7, RegistrationsList.HCloud, 0, 3);
		world.setBlock(x + 2, y + 8, z + 6, RegistrationsList.HCloud, 0, 3);
		world.setBlock(x + 3, y + 8, z + 7, RegistrationsList.HCloud, 0, 3);
		world.setBlock(x + 3, y + 8, z + 6, RegistrationsList.HCloud, 0, 3);
		world.setBlock(x + 4, y + 8, z + 8, RegistrationsList.HCloud, 0, 3);
		world.setBlock(x + 4, y + 8, z + 7, RegistrationsList.HCloud, 0, 3);
		world.setBlock(x + 4, y + 8, z + 6, RegistrationsList.HCloud, 0, 3);
		world.setBlock(x + 4, y + 8, z + 5, RegistrationsList.HCloud, 0, 3);
		world.setBlock(x + 5, y + 8, z + 8, RegistrationsList.HCloud, 0, 3);
		world.setBlock(x + 5, y + 8, z + 7, RegistrationsList.HCloud, 0, 3);
		world.setBlock(x + 5, y + 8, z + 6, RegistrationsList.HCloud, 0, 3);
		world.setBlock(x + 5, y + 8, z + 5, RegistrationsList.HCloud, 0, 3);
		world.setBlock(x + 6, y + 8, z + 8, RegistrationsList.HCloud, 0, 3);
		world.setBlock(x + 6, y + 8, z + 7, RegistrationsList.HCloud, 0, 3);
		world.setBlock(x + 6, y + 8, z + 6, RegistrationsList.HCloud, 0, 3);
		world.setBlock(x + 6, y + 8, z + 5, RegistrationsList.HCloud, 0, 3);
		world.setBlock(x + 7, y + 8, z + 8, RegistrationsList.HCloud, 0, 3);
		world.setBlock(x + 7, y + 8, z + 7, RegistrationsList.HCloud, 0, 3);
		world.setBlock(x + 7, y + 8, z + 6, RegistrationsList.HCloud, 0, 3);
		world.setBlock(x + 8, y + 8, z + 8, RegistrationsList.HCloud, 0, 3);
		world.setBlock(x + 8, y + 8, z + 7, RegistrationsList.HCloud, 0, 3);
		world.setBlock(x + 8, y + 8, z + 6, RegistrationsList.HCloud, 0, 3);
		world.setBlock(x + 9, y + 8, z + 7, RegistrationsList.HCloud, 0, 3);
		world.setBlock(x + 5, y + 9, z + 7, RegistrationsList.HCloud, 0, 3);
		world.setBlock(x + 6, y + 9, z + 8, RegistrationsList.HCloud, 0, 3);
		world.setBlock(x + 6, y + 9, z + 7, RegistrationsList.HCloud, 0, 3);
		world.setBlock(x + 6, y + 9, z + 6, RegistrationsList.HCloud, 0, 3);
		world.setBlock(x + 7, y + 9, z + 8, RegistrationsList.HCloud, 0, 3);
		world.setBlock(x + 7, y + 9, z + 7, RegistrationsList.HCloud, 0, 3);
		world.setBlock(x + 7, y + 9, z + 6, RegistrationsList.HCloud, 0, 3);
		world.setBlock(x + 8, y + 9, z + 8, RegistrationsList.HCloud, 0, 3);
		world.setBlock(x + 8, y + 9, z + 7, RegistrationsList.HCloud, 0, 3);
		world.setBlock(x + 8, y + 9, z + 6, RegistrationsList.HCloud, 0, 3);
		world.setBlock(x + 9, y + 9, z + 8, RegistrationsList.HCloud, 0, 3);
		world.setBlock(x + 9, y + 9, z + 7, RegistrationsList.HCloud, 0, 3);
		world.setBlock(x + 9, y + 9, z + 6, RegistrationsList.HCloud, 0, 3);
		world.setBlock(x + 10, y + 9, z + 7, RegistrationsList.HCloud, 0, 3);
		world.setBlock(x + 7, y + 10, z + 7, RegistrationsList.HCloud, 0, 3);
		world.setBlock(x + 8, y + 10, z + 8, RegistrationsList.HCloud, 0, 3);
		world.setBlock(x + 8, y + 10, z + 7, RegistrationsList.HCloud, 0, 3);
		world.setBlock(x + 8, y + 10, z + 6, RegistrationsList.HCloud, 0, 3);
		world.setBlock(x + 9, y + 10, z + 8, RegistrationsList.HCloud, 0, 3);
		world.setBlock(x + 9, y + 10, z + 7, RegistrationsList.HCloud, 0, 3);
		world.setBlock(x + 9, y + 10, z + 6, RegistrationsList.HCloud, 0, 3);
		world.setBlock(x + 10, y + 10, z + 8, RegistrationsList.HCloud, 0, 3);
		world.setBlock(x + 10, y + 10, z + 7, RegistrationsList.HCloud, 0, 3);
		world.setBlock(x + 10, y + 10, z + 6, RegistrationsList.HCloud, 0, 3);
		world.setBlock(x + 11, y + 10, z + 8, RegistrationsList.HCloud, 0, 3);
		world.setBlock(x + 11, y + 10, z + 7, RegistrationsList.HCloud, 0, 3);
		world.setBlock(x + 11, y + 10, z + 6, RegistrationsList.HCloud, 0, 3);
		world.setBlock(x + 12, y + 10, z + 7, RegistrationsList.HCloud, 0, 3);
		world.setBlock(x + 12, y + 10, z + 6, RegistrationsList.HCloud, 0, 3);
		world.setBlock(x + 12, y + 10, z + 5, RegistrationsList.HCloud, 0, 3);
		world.setBlock(x + 13, y + 10, z + 6, RegistrationsList.HCloud, 0, 3);
		world.setBlock(x + 8, y + 11, z + 7, RegistrationsList.HCloud, 0, 3);
		world.setBlock(x + 9, y + 11, z + 8, RegistrationsList.HCloud, 0, 3);
		world.setBlock(x + 9, y + 11, z + 7, RegistrationsList.HCloud, 0, 3);
		world.setBlock(x + 9, y + 11, z + 6, RegistrationsList.HCloud, 0, 3);
		world.setBlock(x + 10, y + 11, z + 8, RegistrationsList.HCloud, 0, 3);
		world.setBlock(x + 10, y + 11, z + 7, RegistrationsList.HCloud, 0, 3);
		world.setBlock(x + 10, y + 11, z + 6, RegistrationsList.HCloud, 0, 3);
		world.setBlock(x + 11, y + 11, z + 8, RegistrationsList.HCloud, 0, 3);
		world.setBlock(x + 11, y + 11, z + 7, RegistrationsList.HCloud, 0, 3);
		world.setBlock(x + 11, y + 11, z + 6, RegistrationsList.HCloud, 0, 3);
		world.setBlock(x + 11, y + 11, z + 5, RegistrationsList.HCloud, 0, 3);
		world.setBlock(x + 12, y + 11, z + 8, RegistrationsList.HCloud, 0, 3);
		world.setBlock(x + 12, y + 11, z + 7, RegistrationsList.HCloud, 0, 3);
		world.setBlock(x + 12, y + 11, z + 6, RegistrationsList.HCloud, 0, 3);
		world.setBlock(x + 12, y + 11, z + 5, RegistrationsList.HCloud, 0, 3);
		world.setBlock(x + 13, y + 11, z + 7, RegistrationsList.HCloud, 0, 3);
		world.setBlock(x + 13, y + 11, z + 6, RegistrationsList.HCloud, 0, 3);
		world.setBlock(x + 13, y + 11, z + 5, RegistrationsList.HCloud, 0, 3);
		world.setBlock(x + 14, y + 11, z + 6, RegistrationsList.HCloud, 0, 3);
		world.setBlock(x + 10, y + 12, z + 7, RegistrationsList.HCloud, 0, 3);
		world.setBlock(x + 11, y + 12, z + 8, RegistrationsList.HCloud, 0, 3);
		world.setBlock(x + 11, y + 12, z + 7, RegistrationsList.HCloud, 0, 3);
		world.setBlock(x + 11, y + 12, z + 6, RegistrationsList.HCloud, 0, 3);
		world.setBlock(x + 12, y + 12, z + 7, RegistrationsList.HCloud, 0, 3);
		world.setBlock(x + 12, y + 12, z + 6, RegistrationsList.HCloud, 0, 3);
		world.setBlock(x + 12, y + 12, z + 5, RegistrationsList.HCloud, 0, 3);
		world.setBlock(x + 13, y + 12, z + 7, RegistrationsList.HCloud, 0, 3);
		world.setBlock(x + 13, y + 12, z + 6, RegistrationsList.HCloud, 0, 3);
		world.setBlock(x + 13, y + 12, z + 5, RegistrationsList.HCloud, 0, 3);
		world.setBlock(x + 14, y + 12, z + 7, RegistrationsList.HCloud, 0, 3);
		world.setBlock(x + 14, y + 12, z + 6, RegistrationsList.HCloud, 0, 3);
		world.setBlock(x + 14, y + 12, z + 5, RegistrationsList.HCloud, 0, 3);
		world.setBlock(x + 12, y + 13, z + 6, RegistrationsList.HCloud, 0, 3);
		world.setBlock(x + 13, y + 13, z + 7, RegistrationsList.HCloud, 0, 3);
		world.setBlock(x + 13, y + 13, z + 6, RegistrationsList.HCloud, 0, 3);
		world.setBlock(x + 13, y + 13, z + 5, RegistrationsList.HCloud, 0, 3);
		world.setBlock(x + 14, y + 13, z + 6, RegistrationsList.HCloud, 0, 3);
		return true;

	}
	public boolean generate_r2(World world, Random rand, int x, int y, int z)
	{
		if(!LocationIsValidSpawn(world, x + 4, y, z + 7))
		{
			return false;
		}

		world.setBlock(x + 1, y + 0, z + 13, RegistrationsList.HCloud, 0, 3);
		world.setBlock(x + 2, y + 0, z + 12, RegistrationsList.HCloud, 0, 3);
		world.setBlock(x + 1, y + 0, z + 12, RegistrationsList.HCloud, 0, 3);
		world.setBlock(x + 0, y + 0, z + 12, RegistrationsList.HCloud, 0, 3);
		world.setBlock(x + 1, y + 0, z + 11, RegistrationsList.HCloud, 0, 3);
		world.setBlock(x + 2, y + 1, z + 14, RegistrationsList.HCloud, 0, 3);
		world.setBlock(x + 3, y + 1, z + 13, RegistrationsList.HCloud, 0, 3);
		world.setBlock(x + 2, y + 1, z + 13, RegistrationsList.HCloud, 0, 3);
		world.setBlock(x + 1, y + 1, z + 13, RegistrationsList.HCloud, 0, 3);
		world.setBlock(x + 0, y + 1, z + 13, RegistrationsList.HCloud, 0, 3);
		world.setBlock(x + 2, y + 1, z + 12, RegistrationsList.HCloud, 0, 3);
		world.setBlock(x + 1, y + 1, z + 12, RegistrationsList.HCloud, 0, 3);
		world.setBlock(x + 0, y + 1, z + 12, RegistrationsList.HCloud, 0, 3);
		world.setBlock(x + 2, y + 1, z + 11, RegistrationsList.HCloud, 0, 3);
		world.setBlock(x + 1, y + 1, z + 11, RegistrationsList.HCloud, 0, 3);
		world.setBlock(x + 0, y + 1, z + 11, RegistrationsList.HCloud, 0, 3);
		world.setBlock(x + 3, y + 2, z + 14, RegistrationsList.HCloud, 0, 3);
		world.setBlock(x + 2, y + 2, z + 14, RegistrationsList.HCloud, 0, 3);
		world.setBlock(x + 1, y + 2, z + 14, RegistrationsList.HCloud, 0, 3);
		world.setBlock(x + 4, y + 2, z + 13, RegistrationsList.HCloud, 0, 3);
		world.setBlock(x + 3, y + 2, z + 13, RegistrationsList.HCloud, 0, 3);
		world.setBlock(x + 2, y + 2, z + 13, RegistrationsList.HCloud, 0, 3);
		world.setBlock(x + 1, y + 2, z + 13, RegistrationsList.HCloud, 0, 3);
		world.setBlock(x + 3, y + 2, z + 12, RegistrationsList.HCloud, 0, 3);
		world.setBlock(x + 2, y + 2, z + 12, RegistrationsList.HCloud, 0, 3);
		world.setBlock(x + 1, y + 2, z + 12, RegistrationsList.HCloud, 0, 3);
		world.setBlock(x + 0, y + 2, z + 12, RegistrationsList.HCloud, 0, 3);
		world.setBlock(x + 1, y + 2, z + 11, RegistrationsList.HCloud, 0, 3);
		world.setBlock(x + 4, y + 3, z + 14, RegistrationsList.HCloud, 0, 3);
		world.setBlock(x + 3, y + 3, z + 14, RegistrationsList.HCloud, 0, 3);
		world.setBlock(x + 2, y + 3, z + 14, RegistrationsList.HCloud, 0, 3);
		world.setBlock(x + 4, y + 3, z + 13, RegistrationsList.HCloud, 0, 3);
		world.setBlock(x + 3, y + 3, z + 13, RegistrationsList.HCloud, 0, 3);
		world.setBlock(x + 2, y + 3, z + 13, RegistrationsList.HCloud, 0, 3);
		world.setBlock(x + 1, y + 3, z + 13, RegistrationsList.HCloud, 0, 3);
		world.setBlock(x + 5, y + 3, z + 12, RegistrationsList.HCloud, 0, 3);
		world.setBlock(x + 4, y + 3, z + 12, RegistrationsList.HCloud, 0, 3);
		world.setBlock(x + 3, y + 3, z + 12, RegistrationsList.HCloud, 0, 3);
		world.setBlock(x + 2, y + 3, z + 12, RegistrationsList.HCloud, 0, 3);
		world.setBlock(x + 4, y + 3, z + 11, RegistrationsList.HCloud, 0, 3);
		world.setBlock(x + 3, y + 4, z + 14, RegistrationsList.HCloud, 0, 3);
		world.setBlock(x + 5, y + 4, z + 13, RegistrationsList.HCloud, 0, 3);
		world.setBlock(x + 4, y + 4, z + 13, RegistrationsList.HCloud, 0, 3);
		world.setBlock(x + 3, y + 4, z + 13, RegistrationsList.HCloud, 0, 3);
		world.setBlock(x + 2, y + 4, z + 13, RegistrationsList.HCloud, 0, 3);
		world.setBlock(x + 5, y + 4, z + 12, RegistrationsList.HCloud, 0, 3);
		world.setBlock(x + 4, y + 4, z + 12, RegistrationsList.HCloud, 0, 3);
		world.setBlock(x + 3, y + 4, z + 12, RegistrationsList.HCloud, 0, 3);
		world.setBlock(x + 5, y + 4, z + 11, RegistrationsList.HCloud, 0, 3);
		world.setBlock(x + 4, y + 4, z + 11, RegistrationsList.HCloud, 0, 3);
		world.setBlock(x + 3, y + 4, z + 11, RegistrationsList.HCloud, 0, 3);
		world.setBlock(x + 5, y + 5, z + 13, RegistrationsList.HCloud, 0, 3);
		world.setBlock(x + 4, y + 5, z + 13, RegistrationsList.HCloud, 0, 3);
		world.setBlock(x + 6, y + 5, z + 12, RegistrationsList.HCloud, 0, 3);
		world.setBlock(x + 5, y + 5, z + 12, RegistrationsList.HCloud, 0, 3);
		world.setBlock(x + 4, y + 5, z + 12, RegistrationsList.HCloud, 0, 3);
		world.setBlock(x + 3, y + 5, z + 12, RegistrationsList.HCloud, 0, 3);
		world.setBlock(x + 5, y + 5, z + 11, RegistrationsList.HCloud, 0, 3);
		world.setBlock(x + 4, y + 5, z + 11, RegistrationsList.HCloud, 0, 3);
		world.setBlock(x + 6, y + 6, z + 13, RegistrationsList.HCloud, 0, 3);
		world.setBlock(x + 5, y + 6, z + 13, RegistrationsList.HCloud, 0, 3);
		world.setBlock(x + 4, y + 6, z + 13, RegistrationsList.HCloud, 0, 3);
		world.setBlock(x + 6, y + 6, z + 12, RegistrationsList.HCloud, 0, 3);
		world.setBlock(x + 5, y + 6, z + 12, RegistrationsList.HCloud, 0, 3);
		world.setBlock(x + 4, y + 6, z + 12, RegistrationsList.HCloud, 0, 3);
		world.setBlock(x + 7, y + 6, z + 11, RegistrationsList.HCloud, 0, 3);
		world.setBlock(x + 6, y + 6, z + 11, RegistrationsList.HCloud, 0, 3);
		world.setBlock(x + 5, y + 6, z + 11, RegistrationsList.HCloud, 0, 3);
		world.setBlock(x + 4, y + 6, z + 11, RegistrationsList.HCloud, 0, 3);
		world.setBlock(x + 8, y + 6, z + 10, RegistrationsList.HCloud, 0, 3);
		world.setBlock(x + 7, y + 6, z + 10, RegistrationsList.HCloud, 0, 3);
		world.setBlock(x + 6, y + 6, z + 10, RegistrationsList.HCloud, 0, 3);
		world.setBlock(x + 5, y + 6, z + 10, RegistrationsList.HCloud, 0, 3);
		world.setBlock(x + 7, y + 6, z + 9, RegistrationsList.HCloud, 0, 3);
		world.setBlock(x + 6, y + 6, z + 9, RegistrationsList.HCloud, 0, 3);
		world.setBlock(x + 5, y + 6, z + 9, RegistrationsList.HCloud, 0, 3);
		world.setBlock(x + 6, y + 6, z + 8, RegistrationsList.HCloud, 0, 3);
		world.setBlock(x + 5, y + 7, z + 13, RegistrationsList.HCloud, 0, 3);
		world.setBlock(x + 7, y + 7, z + 12, RegistrationsList.HCloud, 0, 3);
		world.setBlock(x + 6, y + 7, z + 12, RegistrationsList.HCloud, 0, 3);
		world.setBlock(x + 5, y + 7, z + 12, RegistrationsList.HCloud, 0, 3);
		world.setBlock(x + 4, y + 7, z + 12, RegistrationsList.HCloud, 0, 3);
		world.setBlock(x + 8, y + 7, z + 11, RegistrationsList.HCloud, 0, 3);
		world.setBlock(x + 7, y + 7, z + 11, RegistrationsList.HCloud, 0, 3);
		world.setBlock(x + 6, y + 7, z + 11, RegistrationsList.HCloud, 0, 3);
		world.setBlock(x + 5, y + 7, z + 11, RegistrationsList.HCloud, 0, 3);
		world.setBlock(x + 8, y + 7, z + 10, RegistrationsList.HCloud, 0, 3);
		world.setBlock(x + 7, y + 7, z + 10, RegistrationsList.HCloud, 0, 3);
		world.setBlock(x + 6, y + 7, z + 10, RegistrationsList.HCloud, 0, 3);
		world.setBlock(x + 5, y + 7, z + 10, RegistrationsList.HCloud, 0, 3);
		world.setBlock(x + 8, y + 7, z + 9, RegistrationsList.HCloud, 0, 3);
		world.setBlock(x + 7, y + 7, z + 9, RegistrationsList.HCloud, 0, 3);
		world.setBlock(x + 6, y + 7, z + 9, RegistrationsList.HCloud, 0, 3);
		world.setBlock(x + 5, y + 7, z + 9, RegistrationsList.HCloud, 0, 3);
		world.setBlock(x + 8, y + 7, z + 8, RegistrationsList.HCloud, 0, 3);
		world.setBlock(x + 7, y + 7, z + 8, RegistrationsList.HCloud, 0, 3);
		world.setBlock(x + 6, y + 7, z + 8, RegistrationsList.HCloud, 0, 3);
		world.setBlock(x + 5, y + 7, z + 8, RegistrationsList.HCloud, 0, 3);
		world.setBlock(x + 7, y + 7, z + 7, RegistrationsList.HCloud, 0, 3);
		world.setBlock(x + 6, y + 8, z + 12, RegistrationsList.HCloud, 0, 3);
		world.setBlock(x + 7, y + 8, z + 11, RegistrationsList.HCloud, 0, 3);
		world.setBlock(x + 6, y + 8, z + 11, RegistrationsList.HCloud, 0, 3);
		world.setBlock(x + 8, y + 8, z + 10, RegistrationsList.HCloud, 0, 3);
		world.setBlock(x + 7, y + 8, z + 10, RegistrationsList.HCloud, 0, 3);
		world.setBlock(x + 6, y + 8, z + 10, RegistrationsList.HCloud, 0, 3);
		world.setBlock(x + 5, y + 8, z + 10, RegistrationsList.HCloud, 0, 3);
		world.setBlock(x + 8, y + 8, z + 9, RegistrationsList.HCloud, 0, 3);
		world.setBlock(x + 7, y + 8, z + 9, RegistrationsList.HCloud, 0, 3);
		world.setBlock(x + 6, y + 8, z + 9, RegistrationsList.HCloud, 0, 3);
		world.setBlock(x + 5, y + 8, z + 9, RegistrationsList.HCloud, 0, 3);
		world.setBlock(x + 8, y + 8, z + 8, RegistrationsList.HCloud, 0, 3);
		world.setBlock(x + 7, y + 8, z + 8, RegistrationsList.HCloud, 0, 3);
		world.setBlock(x + 6, y + 8, z + 8, RegistrationsList.HCloud, 0, 3);
		world.setBlock(x + 5, y + 8, z + 8, RegistrationsList.HCloud, 0, 3);
		world.setBlock(x + 8, y + 8, z + 7, RegistrationsList.HCloud, 0, 3);
		world.setBlock(x + 7, y + 8, z + 7, RegistrationsList.HCloud, 0, 3);
		world.setBlock(x + 6, y + 8, z + 7, RegistrationsList.HCloud, 0, 3);
		world.setBlock(x + 8, y + 8, z + 6, RegistrationsList.HCloud, 0, 3);
		world.setBlock(x + 7, y + 8, z + 6, RegistrationsList.HCloud, 0, 3);
		world.setBlock(x + 6, y + 8, z + 6, RegistrationsList.HCloud, 0, 3);
		world.setBlock(x + 7, y + 8, z + 5, RegistrationsList.HCloud, 0, 3);
		world.setBlock(x + 7, y + 9, z + 9, RegistrationsList.HCloud, 0, 3);
		world.setBlock(x + 8, y + 9, z + 8, RegistrationsList.HCloud, 0, 3);
		world.setBlock(x + 7, y + 9, z + 8, RegistrationsList.HCloud, 0, 3);
		world.setBlock(x + 6, y + 9, z + 8, RegistrationsList.HCloud, 0, 3);
		world.setBlock(x + 8, y + 9, z + 7, RegistrationsList.HCloud, 0, 3);
		world.setBlock(x + 7, y + 9, z + 7, RegistrationsList.HCloud, 0, 3);
		world.setBlock(x + 6, y + 9, z + 7, RegistrationsList.HCloud, 0, 3);
		world.setBlock(x + 8, y + 9, z + 6, RegistrationsList.HCloud, 0, 3);
		world.setBlock(x + 7, y + 9, z + 6, RegistrationsList.HCloud, 0, 3);
		world.setBlock(x + 6, y + 9, z + 6, RegistrationsList.HCloud, 0, 3);
		world.setBlock(x + 8, y + 9, z + 5, RegistrationsList.HCloud, 0, 3);
		world.setBlock(x + 7, y + 9, z + 5, RegistrationsList.HCloud, 0, 3);
		world.setBlock(x + 6, y + 9, z + 5, RegistrationsList.HCloud, 0, 3);
		world.setBlock(x + 7, y + 9, z + 4, RegistrationsList.HCloud, 0, 3);
		world.setBlock(x + 7, y + 10, z + 7, RegistrationsList.HCloud, 0, 3);
		world.setBlock(x + 8, y + 10, z + 6, RegistrationsList.HCloud, 0, 3);
		world.setBlock(x + 7, y + 10, z + 6, RegistrationsList.HCloud, 0, 3);
		world.setBlock(x + 6, y + 10, z + 6, RegistrationsList.HCloud, 0, 3);
		world.setBlock(x + 8, y + 10, z + 5, RegistrationsList.HCloud, 0, 3);
		world.setBlock(x + 7, y + 10, z + 5, RegistrationsList.HCloud, 0, 3);
		world.setBlock(x + 6, y + 10, z + 5, RegistrationsList.HCloud, 0, 3);
		world.setBlock(x + 8, y + 10, z + 4, RegistrationsList.HCloud, 0, 3);
		world.setBlock(x + 7, y + 10, z + 4, RegistrationsList.HCloud, 0, 3);
		world.setBlock(x + 6, y + 10, z + 4, RegistrationsList.HCloud, 0, 3);
		world.setBlock(x + 8, y + 10, z + 3, RegistrationsList.HCloud, 0, 3);
		world.setBlock(x + 7, y + 10, z + 3, RegistrationsList.HCloud, 0, 3);
		world.setBlock(x + 6, y + 10, z + 3, RegistrationsList.HCloud, 0, 3);
		world.setBlock(x + 7, y + 10, z + 2, RegistrationsList.HCloud, 0, 3);
		world.setBlock(x + 6, y + 10, z + 2, RegistrationsList.HCloud, 0, 3);
		world.setBlock(x + 5, y + 10, z + 2, RegistrationsList.HCloud, 0, 3);
		world.setBlock(x + 6, y + 10, z + 1, RegistrationsList.HCloud, 0, 3);
		world.setBlock(x + 7, y + 11, z + 6, RegistrationsList.HCloud, 0, 3);
		world.setBlock(x + 8, y + 11, z + 5, RegistrationsList.HCloud, 0, 3);
		world.setBlock(x + 7, y + 11, z + 5, RegistrationsList.HCloud, 0, 3);
		world.setBlock(x + 6, y + 11, z + 5, RegistrationsList.HCloud, 0, 3);
		world.setBlock(x + 8, y + 11, z + 4, RegistrationsList.HCloud, 0, 3);
		world.setBlock(x + 7, y + 11, z + 4, RegistrationsList.HCloud, 0, 3);
		world.setBlock(x + 6, y + 11, z + 4, RegistrationsList.HCloud, 0, 3);
		world.setBlock(x + 8, y + 11, z + 3, RegistrationsList.HCloud, 0, 3);
		world.setBlock(x + 7, y + 11, z + 3, RegistrationsList.HCloud, 0, 3);
		world.setBlock(x + 6, y + 11, z + 3, RegistrationsList.HCloud, 0, 3);
		world.setBlock(x + 5, y + 11, z + 3, RegistrationsList.HCloud, 0, 3);
		world.setBlock(x + 8, y + 11, z + 2, RegistrationsList.HCloud, 0, 3);
		world.setBlock(x + 7, y + 11, z + 2, RegistrationsList.HCloud, 0, 3);
		world.setBlock(x + 6, y + 11, z + 2, RegistrationsList.HCloud, 0, 3);
		world.setBlock(x + 5, y + 11, z + 2, RegistrationsList.HCloud, 0, 3);
		world.setBlock(x + 7, y + 11, z + 1, RegistrationsList.HCloud, 0, 3);
		world.setBlock(x + 6, y + 11, z + 1, RegistrationsList.HCloud, 0, 3);
		world.setBlock(x + 5, y + 11, z + 1, RegistrationsList.HCloud, 0, 3);
		world.setBlock(x + 6, y + 11, z + 0, RegistrationsList.HCloud, 0, 3);
		world.setBlock(x + 7, y + 12, z + 4, RegistrationsList.HCloud, 0, 3);
		world.setBlock(x + 8, y + 12, z + 3, RegistrationsList.HCloud, 0, 3);
		world.setBlock(x + 7, y + 12, z + 3, RegistrationsList.HCloud, 0, 3);
		world.setBlock(x + 6, y + 12, z + 3, RegistrationsList.HCloud, 0, 3);
		world.setBlock(x + 7, y + 12, z + 2, RegistrationsList.HCloud, 0, 3);
		world.setBlock(x + 6, y + 12, z + 2, RegistrationsList.HCloud, 0, 3);
		world.setBlock(x + 5, y + 12, z + 2, RegistrationsList.HCloud, 0, 3);
		world.setBlock(x + 7, y + 12, z + 1, RegistrationsList.HCloud, 0, 3);
		world.setBlock(x + 6, y + 12, z + 1, RegistrationsList.HCloud, 0, 3);
		world.setBlock(x + 5, y + 12, z + 1, RegistrationsList.HCloud, 0, 3);
		world.setBlock(x + 7, y + 12, z + 0, RegistrationsList.HCloud, 0, 3);
		world.setBlock(x + 6, y + 12, z + 0, RegistrationsList.HCloud, 0, 3);
		world.setBlock(x + 5, y + 12, z + 0, RegistrationsList.HCloud, 0, 3);
		world.setBlock(x + 6, y + 13, z + 2, RegistrationsList.HCloud, 0, 3);
		world.setBlock(x + 7, y + 13, z + 1, RegistrationsList.HCloud, 0, 3);
		world.setBlock(x + 6, y + 13, z + 1, RegistrationsList.HCloud, 0, 3);
		world.setBlock(x + 5, y + 13, z + 1, RegistrationsList.HCloud, 0, 3);
		world.setBlock(x + 6, y + 13, z + 0, RegistrationsList.HCloud, 0, 3);
		return true;

	}
	public boolean generate_r3(World world, Random rand, int x, int y, int z)
{
		if(!LocationIsValidSpawn(world, x + 7, y, z + 4))
		{
			return false;
		}

		world.setBlock(x + 13, y + 0, z + 7, RegistrationsList.HCloud, 0, 3);
		world.setBlock(x + 12, y + 0, z + 6, RegistrationsList.HCloud, 0, 3);
		world.setBlock(x + 12, y + 0, z + 7, RegistrationsList.HCloud, 0, 3);
		world.setBlock(x + 12, y + 0, z + 8, RegistrationsList.HCloud, 0, 3);
		world.setBlock(x + 11, y + 0, z + 7, RegistrationsList.HCloud, 0, 3);
		world.setBlock(x + 14, y + 1, z + 6, RegistrationsList.HCloud, 0, 3);
		world.setBlock(x + 13, y + 1, z + 5, RegistrationsList.HCloud, 0, 3);
		world.setBlock(x + 13, y + 1, z + 6, RegistrationsList.HCloud, 0, 3);
		world.setBlock(x + 13, y + 1, z + 7, RegistrationsList.HCloud, 0, 3);
		world.setBlock(x + 13, y + 1, z + 8, RegistrationsList.HCloud, 0, 3);
		world.setBlock(x + 12, y + 1, z + 6, RegistrationsList.HCloud, 0, 3);
		world.setBlock(x + 12, y + 1, z + 7, RegistrationsList.HCloud, 0, 3);
		world.setBlock(x + 12, y + 1, z + 8, RegistrationsList.HCloud, 0, 3);
		world.setBlock(x + 11, y + 1, z + 6, RegistrationsList.HCloud, 0, 3);
		world.setBlock(x + 11, y + 1, z + 7, RegistrationsList.HCloud, 0, 3);
		world.setBlock(x + 11, y + 1, z + 8, RegistrationsList.HCloud, 0, 3);
		world.setBlock(x + 14, y + 2, z + 5, RegistrationsList.HCloud, 0, 3);
		world.setBlock(x + 14, y + 2, z + 6, RegistrationsList.HCloud, 0, 3);
		world.setBlock(x + 14, y + 2, z + 7, RegistrationsList.HCloud, 0, 3);
		world.setBlock(x + 13, y + 2, z + 4, RegistrationsList.HCloud, 0, 3);
		world.setBlock(x + 13, y + 2, z + 5, RegistrationsList.HCloud, 0, 3);
		world.setBlock(x + 13, y + 2, z + 6, RegistrationsList.HCloud, 0, 3);
		world.setBlock(x + 13, y + 2, z + 7, RegistrationsList.HCloud, 0, 3);
		world.setBlock(x + 12, y + 2, z + 5, RegistrationsList.HCloud, 0, 3);
		world.setBlock(x + 12, y + 2, z + 6, RegistrationsList.HCloud, 0, 3);
		world.setBlock(x + 12, y + 2, z + 7, RegistrationsList.HCloud, 0, 3);
		world.setBlock(x + 12, y + 2, z + 8, RegistrationsList.HCloud, 0, 3);
		world.setBlock(x + 11, y + 2, z + 7, RegistrationsList.HCloud, 0, 3);
		world.setBlock(x + 14, y + 3, z + 4, RegistrationsList.HCloud, 0, 3);
		world.setBlock(x + 14, y + 3, z + 5, RegistrationsList.HCloud, 0, 3);
		world.setBlock(x + 14, y + 3, z + 6, RegistrationsList.HCloud, 0, 3);
		world.setBlock(x + 13, y + 3, z + 4, RegistrationsList.HCloud, 0, 3);
		world.setBlock(x + 13, y + 3, z + 5, RegistrationsList.HCloud, 0, 3);
		world.setBlock(x + 13, y + 3, z + 6, RegistrationsList.HCloud, 0, 3);
		world.setBlock(x + 13, y + 3, z + 7, RegistrationsList.HCloud, 0, 3);
		world.setBlock(x + 12, y + 3, z + 3, RegistrationsList.HCloud, 0, 3);
		world.setBlock(x + 12, y + 3, z + 4, RegistrationsList.HCloud, 0, 3);
		world.setBlock(x + 12, y + 3, z + 5, RegistrationsList.HCloud, 0, 3);
		world.setBlock(x + 12, y + 3, z + 6, RegistrationsList.HCloud, 0, 3);
		world.setBlock(x + 11, y + 3, z + 4, RegistrationsList.HCloud, 0, 3);
		world.setBlock(x + 14, y + 4, z + 5, RegistrationsList.HCloud, 0, 3);
		world.setBlock(x + 13, y + 4, z + 3, RegistrationsList.HCloud, 0, 3);
		world.setBlock(x + 13, y + 4, z + 4, RegistrationsList.HCloud, 0, 3);
		world.setBlock(x + 13, y + 4, z + 5, RegistrationsList.HCloud, 0, 3);
		world.setBlock(x + 13, y + 4, z + 6, RegistrationsList.HCloud, 0, 3);
		world.setBlock(x + 12, y + 4, z + 3, RegistrationsList.HCloud, 0, 3);
		world.setBlock(x + 12, y + 4, z + 4, RegistrationsList.HCloud, 0, 3);
		world.setBlock(x + 12, y + 4, z + 5, RegistrationsList.HCloud, 0, 3);
		world.setBlock(x + 11, y + 4, z + 3, RegistrationsList.HCloud, 0, 3);
		world.setBlock(x + 11, y + 4, z + 4, RegistrationsList.HCloud, 0, 3);
		world.setBlock(x + 11, y + 4, z + 5, RegistrationsList.HCloud, 0, 3);
		world.setBlock(x + 13, y + 5, z + 3, RegistrationsList.HCloud, 0, 3);
		world.setBlock(x + 13, y + 5, z + 4, RegistrationsList.HCloud, 0, 3);
		world.setBlock(x + 12, y + 5, z + 2, RegistrationsList.HCloud, 0, 3);
		world.setBlock(x + 12, y + 5, z + 3, RegistrationsList.HCloud, 0, 3);
		world.setBlock(x + 12, y + 5, z + 4, RegistrationsList.HCloud, 0, 3);
		world.setBlock(x + 12, y + 5, z + 5, RegistrationsList.HCloud, 0, 3);
		world.setBlock(x + 11, y + 5, z + 3, RegistrationsList.HCloud, 0, 3);
		world.setBlock(x + 11, y + 5, z + 4, RegistrationsList.HCloud, 0, 3);
		world.setBlock(x + 13, y + 6, z + 2, RegistrationsList.HCloud, 0, 3);
		world.setBlock(x + 13, y + 6, z + 3, RegistrationsList.HCloud, 0, 3);
		world.setBlock(x + 13, y + 6, z + 4, RegistrationsList.HCloud, 0, 3);
		world.setBlock(x + 12, y + 6, z + 2, RegistrationsList.HCloud, 0, 3);
		world.setBlock(x + 12, y + 6, z + 3, RegistrationsList.HCloud, 0, 3);
		world.setBlock(x + 12, y + 6, z + 4, RegistrationsList.HCloud, 0, 3);
		world.setBlock(x + 11, y + 6, z + 1, RegistrationsList.HCloud, 0, 3);
		world.setBlock(x + 11, y + 6, z + 2, RegistrationsList.HCloud, 0, 3);
		world.setBlock(x + 11, y + 6, z + 3, RegistrationsList.HCloud, 0, 3);
		world.setBlock(x + 11, y + 6, z + 4, RegistrationsList.HCloud, 0, 3);
		world.setBlock(x + 10, y + 6, z + 0, RegistrationsList.HCloud, 0, 3);
		world.setBlock(x + 10, y + 6, z + 1, RegistrationsList.HCloud, 0, 3);
		world.setBlock(x + 10, y + 6, z + 2, RegistrationsList.HCloud, 0, 3);
		world.setBlock(x + 10, y + 6, z + 3, RegistrationsList.HCloud, 0, 3);
		world.setBlock(x + 9, y + 6, z + 1, RegistrationsList.HCloud, 0, 3);
		world.setBlock(x + 9, y + 6, z + 2, RegistrationsList.HCloud, 0, 3);
		world.setBlock(x + 9, y + 6, z + 3, RegistrationsList.HCloud, 0, 3);
		world.setBlock(x + 8, y + 6, z + 2, RegistrationsList.HCloud, 0, 3);
		world.setBlock(x + 13, y + 7, z + 3, RegistrationsList.HCloud, 0, 3);
		world.setBlock(x + 12, y + 7, z + 1, RegistrationsList.HCloud, 0, 3);
		world.setBlock(x + 12, y + 7, z + 2, RegistrationsList.HCloud, 0, 3);
		world.setBlock(x + 12, y + 7, z + 3, RegistrationsList.HCloud, 0, 3);
		world.setBlock(x + 12, y + 7, z + 4, RegistrationsList.HCloud, 0, 3);
		world.setBlock(x + 11, y + 7, z + 0, RegistrationsList.HCloud, 0, 3);
		world.setBlock(x + 11, y + 7, z + 1, RegistrationsList.HCloud, 0, 3);
		world.setBlock(x + 11, y + 7, z + 2, RegistrationsList.HCloud, 0, 3);
		world.setBlock(x + 11, y + 7, z + 3, RegistrationsList.HCloud, 0, 3);
		world.setBlock(x + 10, y + 7, z + 0, RegistrationsList.HCloud, 0, 3);
		world.setBlock(x + 10, y + 7, z + 1, RegistrationsList.HCloud, 0, 3);
		world.setBlock(x + 10, y + 7, z + 2, RegistrationsList.HCloud, 0, 3);
		world.setBlock(x + 10, y + 7, z + 3, RegistrationsList.HCloud, 0, 3);
		world.setBlock(x + 9, y + 7, z + 0, RegistrationsList.HCloud, 0, 3);
		world.setBlock(x + 9, y + 7, z + 1, RegistrationsList.HCloud, 0, 3);
		world.setBlock(x + 9, y + 7, z + 2, RegistrationsList.HCloud, 0, 3);
		world.setBlock(x + 9, y + 7, z + 3, RegistrationsList.HCloud, 0, 3);
		world.setBlock(x + 8, y + 7, z + 0, RegistrationsList.HCloud, 0, 3);
		world.setBlock(x + 8, y + 7, z + 1, RegistrationsList.HCloud, 0, 3);
		world.setBlock(x + 8, y + 7, z + 2, RegistrationsList.HCloud, 0, 3);
		world.setBlock(x + 8, y + 7, z + 3, RegistrationsList.HCloud, 0, 3);
		world.setBlock(x + 7, y + 7, z + 1, RegistrationsList.HCloud, 0, 3);
		world.setBlock(x + 12, y + 8, z + 2, RegistrationsList.HCloud, 0, 3);
		world.setBlock(x + 11, y + 8, z + 1, RegistrationsList.HCloud, 0, 3);
		world.setBlock(x + 11, y + 8, z + 2, RegistrationsList.HCloud, 0, 3);
		world.setBlock(x + 10, y + 8, z + 0, RegistrationsList.HCloud, 0, 3);
		world.setBlock(x + 10, y + 8, z + 1, RegistrationsList.HCloud, 0, 3);
		world.setBlock(x + 10, y + 8, z + 2, RegistrationsList.HCloud, 0, 3);
		world.setBlock(x + 10, y + 8, z + 3, RegistrationsList.HCloud, 0, 3);
		world.setBlock(x + 9, y + 8, z + 0, RegistrationsList.HCloud, 0, 3);
		world.setBlock(x + 9, y + 8, z + 1, RegistrationsList.HCloud, 0, 3);
		world.setBlock(x + 9, y + 8, z + 2, RegistrationsList.HCloud, 0, 3);
		world.setBlock(x + 9, y + 8, z + 3, RegistrationsList.HCloud, 0, 3);
		world.setBlock(x + 8, y + 8, z + 0, RegistrationsList.HCloud, 0, 3);
		world.setBlock(x + 8, y + 8, z + 1, RegistrationsList.HCloud, 0, 3);
		world.setBlock(x + 8, y + 8, z + 2, RegistrationsList.HCloud, 0, 3);
		world.setBlock(x + 8, y + 8, z + 3, RegistrationsList.HCloud, 0, 3);
		world.setBlock(x + 7, y + 8, z + 0, RegistrationsList.HCloud, 0, 3);
		world.setBlock(x + 7, y + 8, z + 1, RegistrationsList.HCloud, 0, 3);
		world.setBlock(x + 7, y + 8, z + 2, RegistrationsList.HCloud, 0, 3);
		world.setBlock(x + 6, y + 8, z + 0, RegistrationsList.HCloud, 0, 3);
		world.setBlock(x + 6, y + 8, z + 1, RegistrationsList.HCloud, 0, 3);
		world.setBlock(x + 6, y + 8, z + 2, RegistrationsList.HCloud, 0, 3);
		world.setBlock(x + 5, y + 8, z + 1, RegistrationsList.HCloud, 0, 3);
		world.setBlock(x + 9, y + 9, z + 1, RegistrationsList.HCloud, 0, 3);
		world.setBlock(x + 8, y + 9, z + 0, RegistrationsList.HCloud, 0, 3);
		world.setBlock(x + 8, y + 9, z + 1, RegistrationsList.HCloud, 0, 3);
		world.setBlock(x + 8, y + 9, z + 2, RegistrationsList.HCloud, 0, 3);
		world.setBlock(x + 7, y + 9, z + 0, RegistrationsList.HCloud, 0, 3);
		world.setBlock(x + 7, y + 9, z + 1, RegistrationsList.HCloud, 0, 3);
		world.setBlock(x + 7, y + 9, z + 2, RegistrationsList.HCloud, 0, 3);
		world.setBlock(x + 6, y + 9, z + 0, RegistrationsList.HCloud, 0, 3);
		world.setBlock(x + 6, y + 9, z + 1, RegistrationsList.HCloud, 0, 3);
		world.setBlock(x + 6, y + 9, z + 2, RegistrationsList.HCloud, 0, 3);
		world.setBlock(x + 5, y + 9, z + 0, RegistrationsList.HCloud, 0, 3);
		world.setBlock(x + 5, y + 9, z + 1, RegistrationsList.HCloud, 0, 3);
		world.setBlock(x + 5, y + 9, z + 2, RegistrationsList.HCloud, 0, 3);
		world.setBlock(x + 4, y + 9, z + 1, RegistrationsList.HCloud, 0, 3);
		world.setBlock(x + 7, y + 10, z + 1, RegistrationsList.HCloud, 0, 3);
		world.setBlock(x + 6, y + 10, z + 0, RegistrationsList.HCloud, 0, 3);
		world.setBlock(x + 6, y + 10, z + 1, RegistrationsList.HCloud, 0, 3);
		world.setBlock(x + 6, y + 10, z + 2, RegistrationsList.HCloud, 0, 3);
		world.setBlock(x + 5, y + 10, z + 0, RegistrationsList.HCloud, 0, 3);
		world.setBlock(x + 5, y + 10, z + 1, RegistrationsList.HCloud, 0, 3);
		world.setBlock(x + 5, y + 10, z + 2, RegistrationsList.HCloud, 0, 3);
		world.setBlock(x + 4, y + 10, z + 0, RegistrationsList.HCloud, 0, 3);
		world.setBlock(x + 4, y + 10, z + 1, RegistrationsList.HCloud, 0, 3);
		world.setBlock(x + 4, y + 10, z + 2, RegistrationsList.HCloud, 0, 3);
		world.setBlock(x + 3, y + 10, z + 0, RegistrationsList.HCloud, 0, 3);
		world.setBlock(x + 3, y + 10, z + 1, RegistrationsList.HCloud, 0, 3);
		world.setBlock(x + 3, y + 10, z + 2, RegistrationsList.HCloud, 0, 3);
		world.setBlock(x + 2, y + 10, z + 1, RegistrationsList.HCloud, 0, 3);
		world.setBlock(x + 2, y + 10, z + 2, RegistrationsList.HCloud, 0, 3);
		world.setBlock(x + 2, y + 10, z + 3, RegistrationsList.HCloud, 0, 3);
		world.setBlock(x + 1, y + 10, z + 2, RegistrationsList.HCloud, 0, 3);
		world.setBlock(x + 6, y + 11, z + 1, RegistrationsList.HCloud, 0, 3);
		world.setBlock(x + 5, y + 11, z + 0, RegistrationsList.HCloud, 0, 3);
		world.setBlock(x + 5, y + 11, z + 1, RegistrationsList.HCloud, 0, 3);
		world.setBlock(x + 5, y + 11, z + 2, RegistrationsList.HCloud, 0, 3);
		world.setBlock(x + 4, y + 11, z + 0, RegistrationsList.HCloud, 0, 3);
		world.setBlock(x + 4, y + 11, z + 1, RegistrationsList.HCloud, 0, 3);
		world.setBlock(x + 4, y + 11, z + 2, RegistrationsList.HCloud, 0, 3);
		world.setBlock(x + 3, y + 11, z + 0, RegistrationsList.HCloud, 0, 3);
		world.setBlock(x + 3, y + 11, z + 1, RegistrationsList.HCloud, 0, 3);
		world.setBlock(x + 3, y + 11, z + 2, RegistrationsList.HCloud, 0, 3);
		world.setBlock(x + 3, y + 11, z + 3, RegistrationsList.HCloud, 0, 3);
		world.setBlock(x + 2, y + 11, z + 0, RegistrationsList.HCloud, 0, 3);
		world.setBlock(x + 2, y + 11, z + 1, RegistrationsList.HCloud, 0, 3);
		world.setBlock(x + 2, y + 11, z + 2, RegistrationsList.HCloud, 0, 3);
		world.setBlock(x + 2, y + 11, z + 3, RegistrationsList.HCloud, 0, 3);
		world.setBlock(x + 1, y + 11, z + 1, RegistrationsList.HCloud, 0, 3);
		world.setBlock(x + 1, y + 11, z + 2, RegistrationsList.HCloud, 0, 3);
		world.setBlock(x + 1, y + 11, z + 3, RegistrationsList.HCloud, 0, 3);
		world.setBlock(x + 0, y + 11, z + 2, RegistrationsList.HCloud, 0, 3);
		world.setBlock(x + 4, y + 12, z + 1, RegistrationsList.HCloud, 0, 3);
		world.setBlock(x + 3, y + 12, z + 0, RegistrationsList.HCloud, 0, 3);
		world.setBlock(x + 3, y + 12, z + 1, RegistrationsList.HCloud, 0, 3);
		world.setBlock(x + 3, y + 12, z + 2, RegistrationsList.HCloud, 0, 3);
		world.setBlock(x + 2, y + 12, z + 1, RegistrationsList.HCloud, 0, 3);
		world.setBlock(x + 2, y + 12, z + 2, RegistrationsList.HCloud, 0, 3);
		world.setBlock(x + 2, y + 12, z + 3, RegistrationsList.HCloud, 0, 3);
		world.setBlock(x + 1, y + 12, z + 1, RegistrationsList.HCloud, 0, 3);
		world.setBlock(x + 1, y + 12, z + 2, RegistrationsList.HCloud, 0, 3);
		world.setBlock(x + 1, y + 12, z + 3, RegistrationsList.HCloud, 0, 3);
		world.setBlock(x + 0, y + 12, z + 1, RegistrationsList.HCloud, 0, 3);
		world.setBlock(x + 0, y + 12, z + 2, RegistrationsList.HCloud, 0, 3);
		world.setBlock(x + 0, y + 12, z + 3, RegistrationsList.HCloud, 0, 3);
		world.setBlock(x + 2, y + 13, z + 2, RegistrationsList.HCloud, 0, 3);
		world.setBlock(x + 1, y + 13, z + 1, RegistrationsList.HCloud, 0, 3);
		world.setBlock(x + 1, y + 13, z + 2, RegistrationsList.HCloud, 0, 3);
		world.setBlock(x + 1, y + 13, z + 3, RegistrationsList.HCloud, 0, 3);
		world.setBlock(x + 0, y + 13, z + 2, RegistrationsList.HCloud, 0, 3);
		return true;

	}

}