package beyondspace.world.generation.structures;

import java.util.Random;

import net.minecraft.init.Blocks;
import net.minecraft.tileentity.TileEntityChest;
import net.minecraft.util.WeightedRandomChestContent;
import net.minecraft.world.World;
import net.minecraft.world.gen.feature.WorldGenerator;
import net.minecraftforge.common.ChestGenHooks;

public class NewYearSpruce extends WorldGenerator {

	public boolean generate(World world, Random rand, int x, int y, int z) {
		for(int i = 0; i < 12; i++) {
	        int xCoord = x + rand.nextInt(32) - 16;
	        if (xCoord > -5 && xCoord < 1) xCoord -= 5;
	        if (xCoord > -1 && xCoord < 5) xCoord += 5;
	        int zCoord = z + rand.nextInt(32) - 16;
	        if (zCoord > -5 && zCoord < 1) zCoord -= 5;
	        if (zCoord > -1 && zCoord < 5) zCoord += 5;
	        int yCoord = world.getHeightValue(xCoord, zCoord) + 1;
			
            if(world.getBlock(xCoord, yCoord, zCoord) != Blocks.chest) {
               world.setBlock(xCoord, yCoord, zCoord, Blocks.chest, 0, 2);
            } else {
            	i--;
            	continue;
            }
	            
			TileEntityChest chest = (TileEntityChest) world.getTileEntity(xCoord, yCoord, zCoord);

			if (chest != null) {
				for (int o = 0; o < chest.getSizeInventory(); o++) {
					chest.setInventorySlotContents(o, null);
				}

				ChestGenHooks info = ChestGenHooks.getInfo(ChestGenHooks.DUNGEON_CHEST);
				WeightedRandomChestContent.generateChestContents(rand, info.getItems(rand), chest, info.getCount(rand));
			}
		}

		generate_r0(world, rand, x - 16, y, z - 16);

        return true;
	}

	public boolean generate_r0(World world, Random rand, int x, int y, int z) {
		world.setBlock(x + 14, y + 0, z + 12, Blocks.log, 1, 3);
		world.setBlock(x + 15, y + 0, z + 12, Blocks.log, 1, 3);
		world.setBlock(x + 16, y + 0, z + 12, Blocks.log, 1, 3);
		world.setBlock(x + 17, y + 0, z + 12, Blocks.log, 1, 3);
		world.setBlock(x + 13, y + 0, z + 13, Blocks.log, 1, 3);
		world.setBlock(x + 14, y + 0, z + 13, Blocks.log, 1, 3);
		world.setBlock(x + 15, y + 0, z + 13, Blocks.log, 1, 3);
		world.setBlock(x + 16, y + 0, z + 13, Blocks.log, 1, 3);
		world.setBlock(x + 17, y + 0, z + 13, Blocks.log, 1, 3);
		world.setBlock(x + 18, y + 0, z + 13, Blocks.log, 1, 3);
		world.setBlock(x + 12, y + 0, z + 14, Blocks.log, 1, 3);
		world.setBlock(x + 13, y + 0, z + 14, Blocks.log, 1, 3);
		world.setBlock(x + 14, y + 0, z + 14, Blocks.log, 1, 3);
		world.setBlock(x + 15, y + 0, z + 14, Blocks.log, 1, 3);
		world.setBlock(x + 16, y + 0, z + 14, Blocks.log, 1, 3);
		world.setBlock(x + 17, y + 0, z + 14, Blocks.log, 1, 3);
		world.setBlock(x + 18, y + 0, z + 14, Blocks.log, 1, 3);
		world.setBlock(x + 19, y + 0, z + 14, Blocks.log, 1, 3);
		world.setBlock(x + 12, y + 0, z + 15, Blocks.log, 1, 3);
		world.setBlock(x + 13, y + 0, z + 15, Blocks.log, 1, 3);
		world.setBlock(x + 14, y + 0, z + 15, Blocks.log, 1, 3);
		world.setBlock(x + 15, y + 0, z + 15, Blocks.log, 1, 3);
		world.setBlock(x + 16, y + 0, z + 15, Blocks.log, 1, 3);
		world.setBlock(x + 17, y + 0, z + 15, Blocks.log, 1, 3);
		world.setBlock(x + 18, y + 0, z + 15, Blocks.log, 1, 3);
		world.setBlock(x + 19, y + 0, z + 15, Blocks.log, 1, 3);
		world.setBlock(x + 12, y + 0, z + 16, Blocks.log, 1, 3);
		world.setBlock(x + 13, y + 0, z + 16, Blocks.log, 1, 3);
		world.setBlock(x + 14, y + 0, z + 16, Blocks.log, 1, 3);
		world.setBlock(x + 15, y + 0, z + 16, Blocks.log, 1, 3);
		world.setBlock(x + 16, y + 0, z + 16, Blocks.log, 1, 3);
		world.setBlock(x + 17, y + 0, z + 16, Blocks.log, 1, 3);
		world.setBlock(x + 18, y + 0, z + 16, Blocks.log, 1, 3);
		world.setBlock(x + 19, y + 0, z + 16, Blocks.log, 1, 3);
		world.setBlock(x + 12, y + 0, z + 17, Blocks.log, 1, 3);
		world.setBlock(x + 13, y + 0, z + 17, Blocks.log, 1, 3);
		world.setBlock(x + 14, y + 0, z + 17, Blocks.log, 1, 3);
		world.setBlock(x + 15, y + 0, z + 17, Blocks.log, 1, 3);
		world.setBlock(x + 16, y + 0, z + 17, Blocks.log, 1, 3);
		world.setBlock(x + 17, y + 0, z + 17, Blocks.log, 1, 3);
		world.setBlock(x + 18, y + 0, z + 17, Blocks.log, 1, 3);
		world.setBlock(x + 19, y + 0, z + 17, Blocks.log, 1, 3);
		world.setBlock(x + 13, y + 0, z + 18, Blocks.log, 1, 3);
		world.setBlock(x + 14, y + 0, z + 18, Blocks.log, 1, 3);
		world.setBlock(x + 15, y + 0, z + 18, Blocks.log, 1, 3);
		world.setBlock(x + 16, y + 0, z + 18, Blocks.log, 1, 3);
		world.setBlock(x + 17, y + 0, z + 18, Blocks.log, 1, 3);
		world.setBlock(x + 18, y + 0, z + 18, Blocks.log, 1, 3);
		world.setBlock(x + 14, y + 0, z + 19, Blocks.log, 1, 3);
		world.setBlock(x + 15, y + 0, z + 19, Blocks.log, 1, 3);
		world.setBlock(x + 16, y + 0, z + 19, Blocks.log, 1, 3);
		world.setBlock(x + 17, y + 0, z + 19, Blocks.log, 1, 3);
		world.setBlock(x + 14, y + 1, z + 12, Blocks.log, 1, 3);
		world.setBlock(x + 15, y + 1, z + 12, Blocks.log, 1, 3);
		world.setBlock(x + 16, y + 1, z + 12, Blocks.log, 1, 3);
		world.setBlock(x + 17, y + 1, z + 12, Blocks.log, 1, 3);
		world.setBlock(x + 13, y + 1, z + 13, Blocks.log, 1, 3);
		world.setBlock(x + 14, y + 1, z + 13, Blocks.log, 1, 3);
		world.setBlock(x + 15, y + 1, z + 13, Blocks.log, 1, 3);
		world.setBlock(x + 16, y + 1, z + 13, Blocks.log, 1, 3);
		world.setBlock(x + 17, y + 1, z + 13, Blocks.log, 1, 3);
		world.setBlock(x + 18, y + 1, z + 13, Blocks.log, 1, 3);
		world.setBlock(x + 12, y + 1, z + 14, Blocks.log, 1, 3);
		world.setBlock(x + 13, y + 1, z + 14, Blocks.log, 1, 3);
		world.setBlock(x + 14, y + 1, z + 14, Blocks.log, 1, 3);
		world.setBlock(x + 15, y + 1, z + 14, Blocks.log, 1, 3);
		world.setBlock(x + 16, y + 1, z + 14, Blocks.log, 1, 3);
		world.setBlock(x + 17, y + 1, z + 14, Blocks.log, 1, 3);
		world.setBlock(x + 18, y + 1, z + 14, Blocks.log, 1, 3);
		world.setBlock(x + 19, y + 1, z + 14, Blocks.log, 1, 3);
		world.setBlock(x + 12, y + 1, z + 15, Blocks.log, 1, 3);
		world.setBlock(x + 13, y + 1, z + 15, Blocks.log, 1, 3);
		world.setBlock(x + 14, y + 1, z + 15, Blocks.log, 1, 3);
		world.setBlock(x + 15, y + 1, z + 15, Blocks.log, 1, 3);
		world.setBlock(x + 16, y + 1, z + 15, Blocks.log, 1, 3);
		world.setBlock(x + 17, y + 1, z + 15, Blocks.log, 1, 3);
		world.setBlock(x + 18, y + 1, z + 15, Blocks.log, 1, 3);
		world.setBlock(x + 19, y + 1, z + 15, Blocks.log, 1, 3);
		world.setBlock(x + 12, y + 1, z + 16, Blocks.log, 1, 3);
		world.setBlock(x + 13, y + 1, z + 16, Blocks.log, 1, 3);
		world.setBlock(x + 14, y + 1, z + 16, Blocks.log, 1, 3);
		world.setBlock(x + 15, y + 1, z + 16, Blocks.log, 1, 3);
		world.setBlock(x + 16, y + 1, z + 16, Blocks.log, 1, 3);
		world.setBlock(x + 17, y + 1, z + 16, Blocks.log, 1, 3);
		world.setBlock(x + 18, y + 1, z + 16, Blocks.log, 1, 3);
		world.setBlock(x + 19, y + 1, z + 16, Blocks.log, 1, 3);
		world.setBlock(x + 12, y + 1, z + 17, Blocks.log, 1, 3);
		world.setBlock(x + 13, y + 1, z + 17, Blocks.log, 1, 3);
		world.setBlock(x + 14, y + 1, z + 17, Blocks.log, 1, 3);
		world.setBlock(x + 15, y + 1, z + 17, Blocks.log, 1, 3);
		world.setBlock(x + 16, y + 1, z + 17, Blocks.log, 1, 3);
		world.setBlock(x + 17, y + 1, z + 17, Blocks.log, 1, 3);
		world.setBlock(x + 18, y + 1, z + 17, Blocks.log, 1, 3);
		world.setBlock(x + 19, y + 1, z + 17, Blocks.log, 1, 3);
		world.setBlock(x + 13, y + 1, z + 18, Blocks.log, 1, 3);
		world.setBlock(x + 14, y + 1, z + 18, Blocks.log, 1, 3);
		world.setBlock(x + 15, y + 1, z + 18, Blocks.log, 1, 3);
		world.setBlock(x + 16, y + 1, z + 18, Blocks.log, 1, 3);
		world.setBlock(x + 17, y + 1, z + 18, Blocks.log, 1, 3);
		world.setBlock(x + 18, y + 1, z + 18, Blocks.log, 1, 3);
		world.setBlock(x + 14, y + 1, z + 19, Blocks.log, 1, 3);
		world.setBlock(x + 15, y + 1, z + 19, Blocks.log, 1, 3);
		world.setBlock(x + 16, y + 1, z + 19, Blocks.log, 1, 3);
		world.setBlock(x + 17, y + 1, z + 19, Blocks.log, 1, 3);
		world.setBlock(x + 14, y + 2, z + 12, Blocks.log, 1, 3);
		world.setBlock(x + 15, y + 2, z + 12, Blocks.log, 1, 3);
		world.setBlock(x + 16, y + 2, z + 12, Blocks.log, 1, 3);
		world.setBlock(x + 17, y + 2, z + 12, Blocks.log, 1, 3);
		world.setBlock(x + 13, y + 2, z + 13, Blocks.log, 1, 3);
		world.setBlock(x + 14, y + 2, z + 13, Blocks.log, 1, 3);
		world.setBlock(x + 15, y + 2, z + 13, Blocks.log, 1, 3);
		world.setBlock(x + 16, y + 2, z + 13, Blocks.log, 1, 3);
		world.setBlock(x + 17, y + 2, z + 13, Blocks.log, 1, 3);
		world.setBlock(x + 18, y + 2, z + 13, Blocks.log, 1, 3);
		world.setBlock(x + 12, y + 2, z + 14, Blocks.log, 1, 3);
		world.setBlock(x + 13, y + 2, z + 14, Blocks.log, 1, 3);
		world.setBlock(x + 14, y + 2, z + 14, Blocks.log, 1, 3);
		world.setBlock(x + 15, y + 2, z + 14, Blocks.log, 1, 3);
		world.setBlock(x + 16, y + 2, z + 14, Blocks.log, 1, 3);
		world.setBlock(x + 17, y + 2, z + 14, Blocks.log, 1, 3);
		world.setBlock(x + 18, y + 2, z + 14, Blocks.log, 1, 3);
		world.setBlock(x + 19, y + 2, z + 14, Blocks.log, 1, 3);
		world.setBlock(x + 12, y + 2, z + 15, Blocks.log, 1, 3);
		world.setBlock(x + 13, y + 2, z + 15, Blocks.log, 1, 3);
		world.setBlock(x + 14, y + 2, z + 15, Blocks.log, 1, 3);
		world.setBlock(x + 15, y + 2, z + 15, Blocks.log, 1, 3);
		world.setBlock(x + 16, y + 2, z + 15, Blocks.log, 1, 3);
		world.setBlock(x + 17, y + 2, z + 15, Blocks.log, 1, 3);
		world.setBlock(x + 18, y + 2, z + 15, Blocks.log, 1, 3);
		world.setBlock(x + 19, y + 2, z + 15, Blocks.log, 1, 3);
		world.setBlock(x + 12, y + 2, z + 16, Blocks.log, 1, 3);
		world.setBlock(x + 13, y + 2, z + 16, Blocks.log, 1, 3);
		world.setBlock(x + 14, y + 2, z + 16, Blocks.log, 1, 3);
		world.setBlock(x + 15, y + 2, z + 16, Blocks.log, 1, 3);
		world.setBlock(x + 16, y + 2, z + 16, Blocks.log, 1, 3);
		world.setBlock(x + 17, y + 2, z + 16, Blocks.log, 1, 3);
		world.setBlock(x + 18, y + 2, z + 16, Blocks.log, 1, 3);
		world.setBlock(x + 19, y + 2, z + 16, Blocks.log, 1, 3);
		world.setBlock(x + 12, y + 2, z + 17, Blocks.log, 1, 3);
		world.setBlock(x + 13, y + 2, z + 17, Blocks.log, 1, 3);
		world.setBlock(x + 14, y + 2, z + 17, Blocks.log, 1, 3);
		world.setBlock(x + 15, y + 2, z + 17, Blocks.log, 1, 3);
		world.setBlock(x + 16, y + 2, z + 17, Blocks.log, 1, 3);
		world.setBlock(x + 17, y + 2, z + 17, Blocks.log, 1, 3);
		world.setBlock(x + 18, y + 2, z + 17, Blocks.log, 1, 3);
		world.setBlock(x + 19, y + 2, z + 17, Blocks.log, 1, 3);
		world.setBlock(x + 13, y + 2, z + 18, Blocks.log, 1, 3);
		world.setBlock(x + 14, y + 2, z + 18, Blocks.log, 1, 3);
		world.setBlock(x + 15, y + 2, z + 18, Blocks.log, 1, 3);
		world.setBlock(x + 16, y + 2, z + 18, Blocks.log, 1, 3);
		world.setBlock(x + 17, y + 2, z + 18, Blocks.log, 1, 3);
		world.setBlock(x + 18, y + 2, z + 18, Blocks.log, 1, 3);
		world.setBlock(x + 14, y + 2, z + 19, Blocks.log, 1, 3);
		world.setBlock(x + 15, y + 2, z + 19, Blocks.log, 1, 3);
		world.setBlock(x + 16, y + 2, z + 19, Blocks.log, 1, 3);
		world.setBlock(x + 17, y + 2, z + 19, Blocks.log, 1, 3);
		world.setBlock(x + 14, y + 3, z + 12, Blocks.log, 1, 3);
		world.setBlock(x + 15, y + 3, z + 12, Blocks.log, 1, 3);
		world.setBlock(x + 16, y + 3, z + 12, Blocks.log, 1, 3);
		world.setBlock(x + 17, y + 3, z + 12, Blocks.log, 1, 3);
		world.setBlock(x + 13, y + 3, z + 13, Blocks.log, 1, 3);
		world.setBlock(x + 14, y + 3, z + 13, Blocks.log, 1, 3);
		world.setBlock(x + 15, y + 3, z + 13, Blocks.log, 1, 3);
		world.setBlock(x + 16, y + 3, z + 13, Blocks.log, 1, 3);
		world.setBlock(x + 17, y + 3, z + 13, Blocks.log, 1, 3);
		world.setBlock(x + 18, y + 3, z + 13, Blocks.log, 1, 3);
		world.setBlock(x + 12, y + 3, z + 14, Blocks.log, 1, 3);
		world.setBlock(x + 13, y + 3, z + 14, Blocks.log, 1, 3);
		world.setBlock(x + 14, y + 3, z + 14, Blocks.log, 1, 3);
		world.setBlock(x + 15, y + 3, z + 14, Blocks.log, 1, 3);
		world.setBlock(x + 16, y + 3, z + 14, Blocks.log, 1, 3);
		world.setBlock(x + 17, y + 3, z + 14, Blocks.log, 1, 3);
		world.setBlock(x + 18, y + 3, z + 14, Blocks.log, 1, 3);
		world.setBlock(x + 19, y + 3, z + 14, Blocks.log, 1, 3);
		world.setBlock(x + 12, y + 3, z + 15, Blocks.log, 1, 3);
		world.setBlock(x + 13, y + 3, z + 15, Blocks.log, 1, 3);
		world.setBlock(x + 14, y + 3, z + 15, Blocks.log, 1, 3);
		world.setBlock(x + 15, y + 3, z + 15, Blocks.log, 1, 3);
		world.setBlock(x + 16, y + 3, z + 15, Blocks.log, 1, 3);
		world.setBlock(x + 17, y + 3, z + 15, Blocks.log, 1, 3);
		world.setBlock(x + 18, y + 3, z + 15, Blocks.log, 1, 3);
		world.setBlock(x + 19, y + 3, z + 15, Blocks.log, 1, 3);
		world.setBlock(x + 12, y + 3, z + 16, Blocks.log, 1, 3);
		world.setBlock(x + 13, y + 3, z + 16, Blocks.log, 1, 3);
		world.setBlock(x + 14, y + 3, z + 16, Blocks.log, 1, 3);
		world.setBlock(x + 15, y + 3, z + 16, Blocks.log, 1, 3);
		world.setBlock(x + 16, y + 3, z + 16, Blocks.log, 1, 3);
		world.setBlock(x + 17, y + 3, z + 16, Blocks.log, 1, 3);
		world.setBlock(x + 18, y + 3, z + 16, Blocks.log, 1, 3);
		world.setBlock(x + 19, y + 3, z + 16, Blocks.log, 1, 3);
		world.setBlock(x + 12, y + 3, z + 17, Blocks.log, 1, 3);
		world.setBlock(x + 13, y + 3, z + 17, Blocks.log, 1, 3);
		world.setBlock(x + 14, y + 3, z + 17, Blocks.log, 1, 3);
		world.setBlock(x + 15, y + 3, z + 17, Blocks.log, 1, 3);
		world.setBlock(x + 16, y + 3, z + 17, Blocks.log, 1, 3);
		world.setBlock(x + 17, y + 3, z + 17, Blocks.log, 1, 3);
		world.setBlock(x + 18, y + 3, z + 17, Blocks.log, 1, 3);
		world.setBlock(x + 19, y + 3, z + 17, Blocks.log, 1, 3);
		world.setBlock(x + 13, y + 3, z + 18, Blocks.log, 1, 3);
		world.setBlock(x + 14, y + 3, z + 18, Blocks.log, 1, 3);
		world.setBlock(x + 15, y + 3, z + 18, Blocks.log, 1, 3);
		world.setBlock(x + 16, y + 3, z + 18, Blocks.log, 1, 3);
		world.setBlock(x + 17, y + 3, z + 18, Blocks.log, 1, 3);
		world.setBlock(x + 18, y + 3, z + 18, Blocks.log, 1, 3);
		world.setBlock(x + 14, y + 3, z + 19, Blocks.log, 1, 3);
		world.setBlock(x + 15, y + 3, z + 19, Blocks.log, 1, 3);
		world.setBlock(x + 16, y + 3, z + 19, Blocks.log, 1, 3);
		world.setBlock(x + 17, y + 3, z + 19, Blocks.log, 1, 3);
		world.setBlock(x + 14, y + 4, z + 12, Blocks.log, 1, 3);
		world.setBlock(x + 15, y + 4, z + 12, Blocks.log, 1, 3);
		world.setBlock(x + 16, y + 4, z + 12, Blocks.log, 1, 3);
		world.setBlock(x + 17, y + 4, z + 12, Blocks.log, 1, 3);
		world.setBlock(x + 13, y + 4, z + 13, Blocks.log, 1, 3);
		world.setBlock(x + 14, y + 4, z + 13, Blocks.log, 1, 3);
		world.setBlock(x + 15, y + 4, z + 13, Blocks.log, 1, 3);
		world.setBlock(x + 16, y + 4, z + 13, Blocks.log, 1, 3);
		world.setBlock(x + 17, y + 4, z + 13, Blocks.log, 1, 3);
		world.setBlock(x + 18, y + 4, z + 13, Blocks.log, 1, 3);
		world.setBlock(x + 12, y + 4, z + 14, Blocks.log, 1, 3);
		world.setBlock(x + 13, y + 4, z + 14, Blocks.log, 1, 3);
		world.setBlock(x + 14, y + 4, z + 14, Blocks.log, 1, 3);
		world.setBlock(x + 15, y + 4, z + 14, Blocks.log, 1, 3);
		world.setBlock(x + 16, y + 4, z + 14, Blocks.log, 1, 3);
		world.setBlock(x + 17, y + 4, z + 14, Blocks.log, 1, 3);
		world.setBlock(x + 18, y + 4, z + 14, Blocks.log, 1, 3);
		world.setBlock(x + 19, y + 4, z + 14, Blocks.log, 1, 3);
		world.setBlock(x + 12, y + 4, z + 15, Blocks.log, 1, 3);
		world.setBlock(x + 13, y + 4, z + 15, Blocks.log, 1, 3);
		world.setBlock(x + 14, y + 4, z + 15, Blocks.log, 1, 3);
		world.setBlock(x + 15, y + 4, z + 15, Blocks.log, 1, 3);
		world.setBlock(x + 16, y + 4, z + 15, Blocks.log, 1, 3);
		world.setBlock(x + 17, y + 4, z + 15, Blocks.log, 1, 3);
		world.setBlock(x + 18, y + 4, z + 15, Blocks.log, 1, 3);
		world.setBlock(x + 19, y + 4, z + 15, Blocks.log, 1, 3);
		world.setBlock(x + 12, y + 4, z + 16, Blocks.log, 1, 3);
		world.setBlock(x + 13, y + 4, z + 16, Blocks.log, 1, 3);
		world.setBlock(x + 14, y + 4, z + 16, Blocks.log, 1, 3);
		world.setBlock(x + 15, y + 4, z + 16, Blocks.log, 1, 3);
		world.setBlock(x + 16, y + 4, z + 16, Blocks.log, 1, 3);
		world.setBlock(x + 17, y + 4, z + 16, Blocks.log, 1, 3);
		world.setBlock(x + 18, y + 4, z + 16, Blocks.log, 1, 3);
		world.setBlock(x + 19, y + 4, z + 16, Blocks.log, 1, 3);
		world.setBlock(x + 12, y + 4, z + 17, Blocks.log, 1, 3);
		world.setBlock(x + 13, y + 4, z + 17, Blocks.log, 1, 3);
		world.setBlock(x + 14, y + 4, z + 17, Blocks.log, 1, 3);
		world.setBlock(x + 15, y + 4, z + 17, Blocks.log, 1, 3);
		world.setBlock(x + 16, y + 4, z + 17, Blocks.log, 1, 3);
		world.setBlock(x + 17, y + 4, z + 17, Blocks.log, 1, 3);
		world.setBlock(x + 18, y + 4, z + 17, Blocks.log, 1, 3);
		world.setBlock(x + 19, y + 4, z + 17, Blocks.log, 1, 3);
		world.setBlock(x + 13, y + 4, z + 18, Blocks.log, 1, 3);
		world.setBlock(x + 14, y + 4, z + 18, Blocks.log, 1, 3);
		world.setBlock(x + 15, y + 4, z + 18, Blocks.log, 1, 3);
		world.setBlock(x + 16, y + 4, z + 18, Blocks.log, 1, 3);
		world.setBlock(x + 17, y + 4, z + 18, Blocks.log, 1, 3);
		world.setBlock(x + 18, y + 4, z + 18, Blocks.log, 1, 3);
		world.setBlock(x + 14, y + 4, z + 19, Blocks.log, 1, 3);
		world.setBlock(x + 15, y + 4, z + 19, Blocks.log, 1, 3);
		world.setBlock(x + 16, y + 4, z + 19, Blocks.log, 1, 3);
		world.setBlock(x + 17, y + 4, z + 19, Blocks.log, 1, 3);
		world.setBlock(x + 14, y + 5, z + 12, Blocks.log, 1, 3);
		world.setBlock(x + 15, y + 5, z + 12, Blocks.log, 1, 3);
		world.setBlock(x + 16, y + 5, z + 12, Blocks.log, 1, 3);
		world.setBlock(x + 17, y + 5, z + 12, Blocks.log, 1, 3);
		world.setBlock(x + 13, y + 5, z + 13, Blocks.log, 1, 3);
		world.setBlock(x + 14, y + 5, z + 13, Blocks.log, 1, 3);
		world.setBlock(x + 15, y + 5, z + 13, Blocks.log, 1, 3);
		world.setBlock(x + 16, y + 5, z + 13, Blocks.log, 1, 3);
		world.setBlock(x + 17, y + 5, z + 13, Blocks.log, 1, 3);
		world.setBlock(x + 18, y + 5, z + 13, Blocks.log, 1, 3);
		world.setBlock(x + 12, y + 5, z + 14, Blocks.log, 1, 3);
		world.setBlock(x + 13, y + 5, z + 14, Blocks.log, 1, 3);
		world.setBlock(x + 14, y + 5, z + 14, Blocks.log, 1, 3);
		world.setBlock(x + 15, y + 5, z + 14, Blocks.log, 1, 3);
		world.setBlock(x + 16, y + 5, z + 14, Blocks.log, 1, 3);
		world.setBlock(x + 17, y + 5, z + 14, Blocks.log, 1, 3);
		world.setBlock(x + 18, y + 5, z + 14, Blocks.log, 1, 3);
		world.setBlock(x + 19, y + 5, z + 14, Blocks.log, 1, 3);
		world.setBlock(x + 12, y + 5, z + 15, Blocks.log, 1, 3);
		world.setBlock(x + 13, y + 5, z + 15, Blocks.log, 1, 3);
		world.setBlock(x + 14, y + 5, z + 15, Blocks.log, 1, 3);
		world.setBlock(x + 15, y + 5, z + 15, Blocks.log, 1, 3);
		world.setBlock(x + 16, y + 5, z + 15, Blocks.log, 1, 3);
		world.setBlock(x + 17, y + 5, z + 15, Blocks.log, 1, 3);
		world.setBlock(x + 18, y + 5, z + 15, Blocks.log, 1, 3);
		world.setBlock(x + 19, y + 5, z + 15, Blocks.log, 1, 3);
		world.setBlock(x + 12, y + 5, z + 16, Blocks.log, 1, 3);
		world.setBlock(x + 13, y + 5, z + 16, Blocks.log, 1, 3);
		world.setBlock(x + 14, y + 5, z + 16, Blocks.log, 1, 3);
		world.setBlock(x + 15, y + 5, z + 16, Blocks.log, 1, 3);
		world.setBlock(x + 16, y + 5, z + 16, Blocks.log, 1, 3);
		world.setBlock(x + 17, y + 5, z + 16, Blocks.log, 1, 3);
		world.setBlock(x + 18, y + 5, z + 16, Blocks.log, 1, 3);
		world.setBlock(x + 19, y + 5, z + 16, Blocks.log, 1, 3);
		world.setBlock(x + 12, y + 5, z + 17, Blocks.log, 1, 3);
		world.setBlock(x + 13, y + 5, z + 17, Blocks.log, 1, 3);
		world.setBlock(x + 14, y + 5, z + 17, Blocks.log, 1, 3);
		world.setBlock(x + 15, y + 5, z + 17, Blocks.log, 1, 3);
		world.setBlock(x + 16, y + 5, z + 17, Blocks.log, 1, 3);
		world.setBlock(x + 17, y + 5, z + 17, Blocks.log, 1, 3);
		world.setBlock(x + 18, y + 5, z + 17, Blocks.log, 1, 3);
		world.setBlock(x + 19, y + 5, z + 17, Blocks.log, 1, 3);
		world.setBlock(x + 13, y + 5, z + 18, Blocks.log, 1, 3);
		world.setBlock(x + 14, y + 5, z + 18, Blocks.log, 1, 3);
		world.setBlock(x + 15, y + 5, z + 18, Blocks.log, 1, 3);
		world.setBlock(x + 16, y + 5, z + 18, Blocks.log, 1, 3);
		world.setBlock(x + 17, y + 5, z + 18, Blocks.log, 1, 3);
		world.setBlock(x + 18, y + 5, z + 18, Blocks.log, 1, 3);
		world.setBlock(x + 14, y + 5, z + 19, Blocks.log, 1, 3);
		world.setBlock(x + 15, y + 5, z + 19, Blocks.log, 1, 3);
		world.setBlock(x + 16, y + 5, z + 19, Blocks.log, 1, 3);
		world.setBlock(x + 17, y + 5, z + 19, Blocks.log, 1, 3);
		world.setBlock(x + 14, y + 6, z + 12, Blocks.log, 1, 3);
		world.setBlock(x + 15, y + 6, z + 12, Blocks.log, 1, 3);
		world.setBlock(x + 16, y + 6, z + 12, Blocks.log, 1, 3);
		world.setBlock(x + 17, y + 6, z + 12, Blocks.log, 1, 3);
		world.setBlock(x + 13, y + 6, z + 13, Blocks.log, 1, 3);
		world.setBlock(x + 14, y + 6, z + 13, Blocks.log, 1, 3);
		world.setBlock(x + 15, y + 6, z + 13, Blocks.log, 1, 3);
		world.setBlock(x + 16, y + 6, z + 13, Blocks.log, 1, 3);
		world.setBlock(x + 17, y + 6, z + 13, Blocks.log, 1, 3);
		world.setBlock(x + 18, y + 6, z + 13, Blocks.log, 1, 3);
		world.setBlock(x + 12, y + 6, z + 14, Blocks.log, 1, 3);
		world.setBlock(x + 13, y + 6, z + 14, Blocks.log, 1, 3);
		world.setBlock(x + 14, y + 6, z + 14, Blocks.log, 1, 3);
		world.setBlock(x + 15, y + 6, z + 14, Blocks.log, 1, 3);
		world.setBlock(x + 16, y + 6, z + 14, Blocks.log, 1, 3);
		world.setBlock(x + 17, y + 6, z + 14, Blocks.log, 1, 3);
		world.setBlock(x + 18, y + 6, z + 14, Blocks.log, 1, 3);
		world.setBlock(x + 19, y + 6, z + 14, Blocks.log, 1, 3);
		world.setBlock(x + 12, y + 6, z + 15, Blocks.log, 1, 3);
		world.setBlock(x + 13, y + 6, z + 15, Blocks.log, 1, 3);
		world.setBlock(x + 14, y + 6, z + 15, Blocks.log, 1, 3);
		world.setBlock(x + 15, y + 6, z + 15, Blocks.log, 1, 3);
		world.setBlock(x + 16, y + 6, z + 15, Blocks.log, 1, 3);
		world.setBlock(x + 17, y + 6, z + 15, Blocks.log, 1, 3);
		world.setBlock(x + 18, y + 6, z + 15, Blocks.log, 1, 3);
		world.setBlock(x + 19, y + 6, z + 15, Blocks.log, 1, 3);
		world.setBlock(x + 12, y + 6, z + 16, Blocks.log, 1, 3);
		world.setBlock(x + 13, y + 6, z + 16, Blocks.log, 1, 3);
		world.setBlock(x + 14, y + 6, z + 16, Blocks.log, 1, 3);
		world.setBlock(x + 15, y + 6, z + 16, Blocks.log, 1, 3);
		world.setBlock(x + 16, y + 6, z + 16, Blocks.log, 1, 3);
		world.setBlock(x + 17, y + 6, z + 16, Blocks.log, 1, 3);
		world.setBlock(x + 18, y + 6, z + 16, Blocks.log, 1, 3);
		world.setBlock(x + 19, y + 6, z + 16, Blocks.log, 1, 3);
		world.setBlock(x + 12, y + 6, z + 17, Blocks.log, 1, 3);
		world.setBlock(x + 13, y + 6, z + 17, Blocks.log, 1, 3);
		world.setBlock(x + 14, y + 6, z + 17, Blocks.log, 1, 3);
		world.setBlock(x + 15, y + 6, z + 17, Blocks.log, 1, 3);
		world.setBlock(x + 16, y + 6, z + 17, Blocks.log, 1, 3);
		world.setBlock(x + 17, y + 6, z + 17, Blocks.log, 1, 3);
		world.setBlock(x + 18, y + 6, z + 17, Blocks.log, 1, 3);
		world.setBlock(x + 19, y + 6, z + 17, Blocks.log, 1, 3);
		world.setBlock(x + 13, y + 6, z + 18, Blocks.log, 1, 3);
		world.setBlock(x + 14, y + 6, z + 18, Blocks.log, 1, 3);
		world.setBlock(x + 15, y + 6, z + 18, Blocks.log, 1, 3);
		world.setBlock(x + 16, y + 6, z + 18, Blocks.log, 1, 3);
		world.setBlock(x + 17, y + 6, z + 18, Blocks.log, 1, 3);
		world.setBlock(x + 18, y + 6, z + 18, Blocks.log, 1, 3);
		world.setBlock(x + 14, y + 6, z + 19, Blocks.log, 1, 3);
		world.setBlock(x + 15, y + 6, z + 19, Blocks.log, 1, 3);
		world.setBlock(x + 16, y + 6, z + 19, Blocks.log, 1, 3);
		world.setBlock(x + 17, y + 6, z + 19, Blocks.log, 1, 3);
		world.setBlock(x + 12, y + 7, z + 3, Blocks.wool, 14, 3);
		world.setBlock(x + 15, y + 7, z + 3, Blocks.wool, 10, 3);
		world.setBlock(x + 21, y + 7, z + 3, Blocks.wool, 4, 3);
		world.setBlock(x + 17, y + 7, z + 5, Blocks.wool, 5, 3);
		world.setBlock(x + 14, y + 7, z + 6, Blocks.wool, 11, 3);
		world.setBlock(x + 11, y + 7, z + 7, Blocks.wool, 1, 3);
		world.setBlock(x + 23, y + 7, z + 8, Blocks.wool, 1, 3);
		world.setBlock(x + 9, y + 7, z + 9, Blocks.wool, 10, 3);
		world.setBlock(x + 20, y + 7, z + 9, Blocks.wool, 11, 3);
		world.setBlock(x + 27, y + 7, z + 9, Blocks.wool, 4, 3);
		world.setBlock(x + 5, y + 7, z + 10, Blocks.wool, 4, 3);
		world.setBlock(x + 27, y + 7, z + 11, Blocks.wool, 14, 3);
		world.setBlock(x + 14, y + 7, z + 12, Blocks.log, 1, 3);
		world.setBlock(x + 15, y + 7, z + 12, Blocks.log, 1, 3);
		world.setBlock(x + 16, y + 7, z + 12, Blocks.log, 1, 3);
		world.setBlock(x + 17, y + 7, z + 12, Blocks.log, 1, 3);
		world.setBlock(x + 13, y + 7, z + 13, Blocks.log, 1, 3);
		world.setBlock(x + 14, y + 7, z + 13, Blocks.log, 1, 3);
		world.setBlock(x + 15, y + 7, z + 13, Blocks.log, 1, 3);
		world.setBlock(x + 16, y + 7, z + 13, Blocks.log, 1, 3);
		world.setBlock(x + 17, y + 7, z + 13, Blocks.log, 1, 3);
		world.setBlock(x + 18, y + 7, z + 13, Blocks.log, 1, 3);
		world.setBlock(x + 23, y + 7, z + 13, Blocks.wool, 5, 3);
		world.setBlock(x + 7, y + 7, z + 14, Blocks.wool, 5, 3);
		world.setBlock(x + 12, y + 7, z + 14, Blocks.log, 1, 3);
		world.setBlock(x + 13, y + 7, z + 14, Blocks.log, 1, 3);
		world.setBlock(x + 14, y + 7, z + 14, Blocks.log, 1, 3);
		world.setBlock(x + 15, y + 7, z + 14, Blocks.log, 1, 3);
		world.setBlock(x + 16, y + 7, z + 14, Blocks.log, 1, 3);
		world.setBlock(x + 17, y + 7, z + 14, Blocks.log, 1, 3);
		world.setBlock(x + 18, y + 7, z + 14, Blocks.log, 1, 3);
		world.setBlock(x + 19, y + 7, z + 14, Blocks.log, 1, 3);
		world.setBlock(x + 5, y + 7, z + 15, Blocks.wool, 14, 3);
		world.setBlock(x + 12, y + 7, z + 15, Blocks.log, 1, 3);
		world.setBlock(x + 13, y + 7, z + 15, Blocks.log, 1, 3);
		world.setBlock(x + 14, y + 7, z + 15, Blocks.log, 1, 3);
		world.setBlock(x + 15, y + 7, z + 15, Blocks.log, 1, 3);
		world.setBlock(x + 16, y + 7, z + 15, Blocks.log, 1, 3);
		world.setBlock(x + 17, y + 7, z + 15, Blocks.log, 1, 3);
		world.setBlock(x + 18, y + 7, z + 15, Blocks.log, 1, 3);
		world.setBlock(x + 19, y + 7, z + 15, Blocks.log, 1, 3);
		world.setBlock(x + 27, y + 7, z + 15, Blocks.wool, 1, 3);
		world.setBlock(x + 12, y + 7, z + 16, Blocks.log, 1, 3);
		world.setBlock(x + 13, y + 7, z + 16, Blocks.log, 1, 3);
		world.setBlock(x + 14, y + 7, z + 16, Blocks.log, 1, 3);
		world.setBlock(x + 15, y + 7, z + 16, Blocks.log, 1, 3);
		world.setBlock(x + 16, y + 7, z + 16, Blocks.log, 1, 3);
		world.setBlock(x + 17, y + 7, z + 16, Blocks.log, 1, 3);
		world.setBlock(x + 18, y + 7, z + 16, Blocks.log, 1, 3);
		world.setBlock(x + 19, y + 7, z + 16, Blocks.log, 1, 3);
		world.setBlock(x + 12, y + 7, z + 17, Blocks.log, 1, 3);
		world.setBlock(x + 13, y + 7, z + 17, Blocks.log, 1, 3);
		world.setBlock(x + 14, y + 7, z + 17, Blocks.log, 1, 3);
		world.setBlock(x + 15, y + 7, z + 17, Blocks.log, 1, 3);
		world.setBlock(x + 16, y + 7, z + 17, Blocks.log, 1, 3);
		world.setBlock(x + 17, y + 7, z + 17, Blocks.log, 1, 3);
		world.setBlock(x + 18, y + 7, z + 17, Blocks.log, 1, 3);
		world.setBlock(x + 19, y + 7, z + 17, Blocks.log, 1, 3);
		world.setBlock(x + 3, y + 7, z + 18, Blocks.wool, 1, 3);
		world.setBlock(x + 13, y + 7, z + 18, Blocks.log, 1, 3);
		world.setBlock(x + 14, y + 7, z + 18, Blocks.log, 1, 3);
		world.setBlock(x + 15, y + 7, z + 18, Blocks.log, 1, 3);
		world.setBlock(x + 16, y + 7, z + 18, Blocks.log, 1, 3);
		world.setBlock(x + 17, y + 7, z + 18, Blocks.log, 1, 3);
		world.setBlock(x + 18, y + 7, z + 18, Blocks.log, 1, 3);
		world.setBlock(x + 24, y + 7, z + 18, Blocks.wool, 10, 3);
		world.setBlock(x + 14, y + 7, z + 19, Blocks.log, 1, 3);
		world.setBlock(x + 15, y + 7, z + 19, Blocks.log, 1, 3);
		world.setBlock(x + 16, y + 7, z + 19, Blocks.log, 1, 3);
		world.setBlock(x + 17, y + 7, z + 19, Blocks.log, 1, 3);
		world.setBlock(x + 9, y + 7, z + 21, Blocks.wool, 4, 3);
		world.setBlock(x + 20, y + 7, z + 21, Blocks.wool, 4, 3);
		world.setBlock(x + 24, y + 7, z + 21, Blocks.wool, 5, 3);
		world.setBlock(x + 27, y + 7, z + 21, Blocks.wool, 14, 3);
		world.setBlock(x + 6, y + 7, z + 22, Blocks.wool, 11, 3);
		world.setBlock(x + 17, y + 7, z + 24, Blocks.wool, 11, 3);
		world.setBlock(x + 24, y + 7, z + 24, Blocks.wool, 11, 3);
		world.setBlock(x + 12, y + 7, z + 25, Blocks.wool, 5, 3);
		world.setBlock(x + 22, y + 7, z + 25, Blocks.wool, 10, 3);
		world.setBlock(x + 8, y + 7, z + 26, Blocks.wool, 10, 3);
		world.setBlock(x + 14, y + 7, z + 28, Blocks.wool, 14, 3);
		world.setBlock(x + 19, y + 7, z + 28, Blocks.wool, 1, 3);
		world.setBlock(x + 12, y + 8, z + 0, Blocks.leaves, 5, 3);
		world.setBlock(x + 13, y + 8, z + 0, Blocks.leaves, 5, 3);
		world.setBlock(x + 14, y + 8, z + 0, Blocks.leaves, 5, 3);
		world.setBlock(x + 15, y + 8, z + 0, Blocks.leaves, 5, 3);
		world.setBlock(x + 16, y + 8, z + 0, Blocks.leaves, 5, 3);
		world.setBlock(x + 17, y + 8, z + 0, Blocks.leaves, 5, 3);
		world.setBlock(x + 18, y + 8, z + 0, Blocks.leaves, 5, 3);
		world.setBlock(x + 19, y + 8, z + 0, Blocks.leaves, 5, 3);
		world.setBlock(x + 9, y + 8, z + 1, Blocks.leaves, 5, 3);
		world.setBlock(x + 10, y + 8, z + 1, Blocks.leaves, 5, 3);
		world.setBlock(x + 11, y + 8, z + 1, Blocks.leaves, 5, 3);
		world.setBlock(x + 12, y + 8, z + 1, Blocks.leaves, 5, 3);
		world.setBlock(x + 13, y + 8, z + 1, Blocks.leaves, 5, 3);
		world.setBlock(x + 14, y + 8, z + 1, Blocks.leaves, 5, 3);
		world.setBlock(x + 15, y + 8, z + 1, Blocks.leaves, 5, 3);
		world.setBlock(x + 16, y + 8, z + 1, Blocks.leaves, 5, 3);
		world.setBlock(x + 17, y + 8, z + 1, Blocks.leaves, 5, 3);
		world.setBlock(x + 18, y + 8, z + 1, Blocks.leaves, 5, 3);
		world.setBlock(x + 19, y + 8, z + 1, Blocks.leaves, 5, 3);
		world.setBlock(x + 20, y + 8, z + 1, Blocks.leaves, 5, 3);
		world.setBlock(x + 21, y + 8, z + 1, Blocks.leaves, 5, 3);
		world.setBlock(x + 22, y + 8, z + 1, Blocks.leaves, 5, 3);
		world.setBlock(x + 7, y + 8, z + 2, Blocks.leaves, 5, 3);
		world.setBlock(x + 8, y + 8, z + 2, Blocks.leaves, 5, 3);
		world.setBlock(x + 9, y + 8, z + 2, Blocks.leaves, 5, 3);
		world.setBlock(x + 10, y + 8, z + 2, Blocks.leaves, 5, 3);
		world.setBlock(x + 11, y + 8, z + 2, Blocks.leaves, 5, 3);
		world.setBlock(x + 12, y + 8, z + 2, Blocks.leaves, 5, 3);
		world.setBlock(x + 13, y + 8, z + 2, Blocks.leaves, 5, 3);
		world.setBlock(x + 14, y + 8, z + 2, Blocks.leaves, 5, 3);
		world.setBlock(x + 15, y + 8, z + 2, Blocks.leaves, 5, 3);
		world.setBlock(x + 16, y + 8, z + 2, Blocks.leaves, 5, 3);
		world.setBlock(x + 17, y + 8, z + 2, Blocks.leaves, 5, 3);
		world.setBlock(x + 18, y + 8, z + 2, Blocks.leaves, 5, 3);
		world.setBlock(x + 19, y + 8, z + 2, Blocks.leaves, 5, 3);
		world.setBlock(x + 20, y + 8, z + 2, Blocks.leaves, 5, 3);
		world.setBlock(x + 21, y + 8, z + 2, Blocks.leaves, 5, 3);
		world.setBlock(x + 22, y + 8, z + 2, Blocks.leaves, 5, 3);
		world.setBlock(x + 23, y + 8, z + 2, Blocks.leaves, 5, 3);
		world.setBlock(x + 24, y + 8, z + 2, Blocks.leaves, 5, 3);
		world.setBlock(x + 6, y + 8, z + 3, Blocks.leaves, 5, 3);
		world.setBlock(x + 7, y + 8, z + 3, Blocks.leaves, 5, 3);
		world.setBlock(x + 8, y + 8, z + 3, Blocks.leaves, 5, 3);
		world.setBlock(x + 9, y + 8, z + 3, Blocks.leaves, 5, 3);
		world.setBlock(x + 10, y + 8, z + 3, Blocks.leaves, 5, 3);
		world.setBlock(x + 11, y + 8, z + 3, Blocks.leaves, 5, 3);
		world.setBlock(x + 12, y + 8, z + 3, Blocks.leaves, 5, 3);
		world.setBlock(x + 13, y + 8, z + 3, Blocks.leaves, 5, 3);
		world.setBlock(x + 14, y + 8, z + 3, Blocks.leaves, 5, 3);
		world.setBlock(x + 15, y + 8, z + 3, Blocks.leaves, 5, 3);
		world.setBlock(x + 16, y + 8, z + 3, Blocks.leaves, 5, 3);
		world.setBlock(x + 17, y + 8, z + 3, Blocks.leaves, 5, 3);
		world.setBlock(x + 18, y + 8, z + 3, Blocks.leaves, 5, 3);
		world.setBlock(x + 19, y + 8, z + 3, Blocks.leaves, 5, 3);
		world.setBlock(x + 20, y + 8, z + 3, Blocks.leaves, 5, 3);
		world.setBlock(x + 21, y + 8, z + 3, Blocks.leaves, 5, 3);
		world.setBlock(x + 22, y + 8, z + 3, Blocks.leaves, 5, 3);
		world.setBlock(x + 23, y + 8, z + 3, Blocks.leaves, 5, 3);
		world.setBlock(x + 24, y + 8, z + 3, Blocks.leaves, 5, 3);
		world.setBlock(x + 25, y + 8, z + 3, Blocks.leaves, 5, 3);
		world.setBlock(x + 5, y + 8, z + 4, Blocks.leaves, 5, 3);
		world.setBlock(x + 6, y + 8, z + 4, Blocks.leaves, 5, 3);
		world.setBlock(x + 7, y + 8, z + 4, Blocks.leaves, 5, 3);
		world.setBlock(x + 8, y + 8, z + 4, Blocks.leaves, 5, 3);
		world.setBlock(x + 9, y + 8, z + 4, Blocks.leaves, 5, 3);
		world.setBlock(x + 10, y + 8, z + 4, Blocks.leaves, 5, 3);
		world.setBlock(x + 11, y + 8, z + 4, Blocks.leaves, 5, 3);
		world.setBlock(x + 12, y + 8, z + 4, Blocks.leaves, 5, 3);
		world.setBlock(x + 13, y + 8, z + 4, Blocks.leaves, 5, 3);
		world.setBlock(x + 14, y + 8, z + 4, Blocks.leaves, 5, 3);
		world.setBlock(x + 15, y + 8, z + 4, Blocks.leaves, 5, 3);
		world.setBlock(x + 16, y + 8, z + 4, Blocks.leaves, 5, 3);
		world.setBlock(x + 17, y + 8, z + 4, Blocks.leaves, 5, 3);
		world.setBlock(x + 18, y + 8, z + 4, Blocks.leaves, 5, 3);
		world.setBlock(x + 19, y + 8, z + 4, Blocks.leaves, 5, 3);
		world.setBlock(x + 20, y + 8, z + 4, Blocks.leaves, 5, 3);
		world.setBlock(x + 21, y + 8, z + 4, Blocks.leaves, 5, 3);
		world.setBlock(x + 22, y + 8, z + 4, Blocks.leaves, 5, 3);
		world.setBlock(x + 23, y + 8, z + 4, Blocks.leaves, 5, 3);
		world.setBlock(x + 24, y + 8, z + 4, Blocks.leaves, 5, 3);
		world.setBlock(x + 25, y + 8, z + 4, Blocks.leaves, 5, 3);
		world.setBlock(x + 26, y + 8, z + 4, Blocks.leaves, 5, 3);
		world.setBlock(x + 4, y + 8, z + 5, Blocks.leaves, 5, 3);
		world.setBlock(x + 5, y + 8, z + 5, Blocks.leaves, 5, 3);
		world.setBlock(x + 6, y + 8, z + 5, Blocks.leaves, 5, 3);
		world.setBlock(x + 7, y + 8, z + 5, Blocks.leaves, 5, 3);
		world.setBlock(x + 8, y + 8, z + 5, Blocks.leaves, 5, 3);
		world.setBlock(x + 9, y + 8, z + 5, Blocks.leaves, 5, 3);
		world.setBlock(x + 10, y + 8, z + 5, Blocks.leaves, 5, 3);
		world.setBlock(x + 11, y + 8, z + 5, Blocks.leaves, 5, 3);
		world.setBlock(x + 12, y + 8, z + 5, Blocks.leaves, 5, 3);
		world.setBlock(x + 13, y + 8, z + 5, Blocks.leaves, 5, 3);
		world.setBlock(x + 14, y + 8, z + 5, Blocks.leaves, 5, 3);
		world.setBlock(x + 15, y + 8, z + 5, Blocks.leaves, 5, 3);
		world.setBlock(x + 16, y + 8, z + 5, Blocks.leaves, 5, 3);
		world.setBlock(x + 17, y + 8, z + 5, Blocks.leaves, 5, 3);
		world.setBlock(x + 18, y + 8, z + 5, Blocks.leaves, 5, 3);
		world.setBlock(x + 19, y + 8, z + 5, Blocks.leaves, 5, 3);
		world.setBlock(x + 20, y + 8, z + 5, Blocks.leaves, 5, 3);
		world.setBlock(x + 21, y + 8, z + 5, Blocks.leaves, 5, 3);
		world.setBlock(x + 22, y + 8, z + 5, Blocks.leaves, 5, 3);
		world.setBlock(x + 23, y + 8, z + 5, Blocks.leaves, 5, 3);
		world.setBlock(x + 24, y + 8, z + 5, Blocks.leaves, 5, 3);
		world.setBlock(x + 25, y + 8, z + 5, Blocks.leaves, 5, 3);
		world.setBlock(x + 26, y + 8, z + 5, Blocks.leaves, 5, 3);
		world.setBlock(x + 27, y + 8, z + 5, Blocks.leaves, 5, 3);
		world.setBlock(x + 3, y + 8, z + 6, Blocks.leaves, 5, 3);
		world.setBlock(x + 4, y + 8, z + 6, Blocks.leaves, 5, 3);
		world.setBlock(x + 5, y + 8, z + 6, Blocks.leaves, 5, 3);
		world.setBlock(x + 6, y + 8, z + 6, Blocks.leaves, 5, 3);
		world.setBlock(x + 7, y + 8, z + 6, Blocks.leaves, 5, 3);
		world.setBlock(x + 8, y + 8, z + 6, Blocks.leaves, 5, 3);
		world.setBlock(x + 9, y + 8, z + 6, Blocks.leaves, 5, 3);
		world.setBlock(x + 10, y + 8, z + 6, Blocks.leaves, 5, 3);
		world.setBlock(x + 11, y + 8, z + 6, Blocks.leaves, 5, 3);
		world.setBlock(x + 12, y + 8, z + 6, Blocks.leaves, 5, 3);
		world.setBlock(x + 13, y + 8, z + 6, Blocks.leaves, 5, 3);
		world.setBlock(x + 14, y + 8, z + 6, Blocks.leaves, 5, 3);
		world.setBlock(x + 15, y + 8, z + 6, Blocks.leaves, 5, 3);
		world.setBlock(x + 16, y + 8, z + 6, Blocks.leaves, 5, 3);
		world.setBlock(x + 17, y + 8, z + 6, Blocks.leaves, 5, 3);
		world.setBlock(x + 18, y + 8, z + 6, Blocks.leaves, 5, 3);
		world.setBlock(x + 19, y + 8, z + 6, Blocks.leaves, 5, 3);
		world.setBlock(x + 20, y + 8, z + 6, Blocks.leaves, 5, 3);
		world.setBlock(x + 21, y + 8, z + 6, Blocks.leaves, 5, 3);
		world.setBlock(x + 22, y + 8, z + 6, Blocks.leaves, 5, 3);
		world.setBlock(x + 23, y + 8, z + 6, Blocks.leaves, 5, 3);
		world.setBlock(x + 24, y + 8, z + 6, Blocks.leaves, 5, 3);
		world.setBlock(x + 25, y + 8, z + 6, Blocks.leaves, 5, 3);
		world.setBlock(x + 26, y + 8, z + 6, Blocks.leaves, 5, 3);
		world.setBlock(x + 27, y + 8, z + 6, Blocks.leaves, 5, 3);
		world.setBlock(x + 28, y + 8, z + 6, Blocks.leaves, 5, 3);
		world.setBlock(x + 2, y + 8, z + 7, Blocks.leaves, 5, 3);
		world.setBlock(x + 3, y + 8, z + 7, Blocks.leaves, 5, 3);
		world.setBlock(x + 4, y + 8, z + 7, Blocks.leaves, 5, 3);
		world.setBlock(x + 5, y + 8, z + 7, Blocks.leaves, 5, 3);
		world.setBlock(x + 6, y + 8, z + 7, Blocks.leaves, 5, 3);
		world.setBlock(x + 7, y + 8, z + 7, Blocks.leaves, 5, 3);
		world.setBlock(x + 8, y + 8, z + 7, Blocks.leaves, 5, 3);
		world.setBlock(x + 9, y + 8, z + 7, Blocks.leaves, 5, 3);
		world.setBlock(x + 10, y + 8, z + 7, Blocks.leaves, 5, 3);
		world.setBlock(x + 11, y + 8, z + 7, Blocks.leaves, 5, 3);
		world.setBlock(x + 12, y + 8, z + 7, Blocks.leaves, 5, 3);
		world.setBlock(x + 13, y + 8, z + 7, Blocks.leaves, 5, 3);
		world.setBlock(x + 14, y + 8, z + 7, Blocks.leaves, 5, 3);
		world.setBlock(x + 15, y + 8, z + 7, Blocks.leaves, 5, 3);
		world.setBlock(x + 16, y + 8, z + 7, Blocks.leaves, 5, 3);
		world.setBlock(x + 17, y + 8, z + 7, Blocks.leaves, 5, 3);
		world.setBlock(x + 18, y + 8, z + 7, Blocks.leaves, 5, 3);
		world.setBlock(x + 19, y + 8, z + 7, Blocks.leaves, 5, 3);
		world.setBlock(x + 20, y + 8, z + 7, Blocks.leaves, 5, 3);
		world.setBlock(x + 21, y + 8, z + 7, Blocks.leaves, 5, 3);
		world.setBlock(x + 22, y + 8, z + 7, Blocks.leaves, 5, 3);
		world.setBlock(x + 23, y + 8, z + 7, Blocks.leaves, 5, 3);
		world.setBlock(x + 24, y + 8, z + 7, Blocks.leaves, 5, 3);
		world.setBlock(x + 25, y + 8, z + 7, Blocks.leaves, 5, 3);
		world.setBlock(x + 26, y + 8, z + 7, Blocks.leaves, 5, 3);
		world.setBlock(x + 27, y + 8, z + 7, Blocks.leaves, 5, 3);
		world.setBlock(x + 28, y + 8, z + 7, Blocks.leaves, 5, 3);
		world.setBlock(x + 29, y + 8, z + 7, Blocks.leaves, 5, 3);
		world.setBlock(x + 2, y + 8, z + 8, Blocks.leaves, 5, 3);
		world.setBlock(x + 3, y + 8, z + 8, Blocks.leaves, 5, 3);
		world.setBlock(x + 4, y + 8, z + 8, Blocks.leaves, 5, 3);
		world.setBlock(x + 5, y + 8, z + 8, Blocks.leaves, 5, 3);
		world.setBlock(x + 6, y + 8, z + 8, Blocks.leaves, 5, 3);
		world.setBlock(x + 7, y + 8, z + 8, Blocks.leaves, 5, 3);
		world.setBlock(x + 8, y + 8, z + 8, Blocks.leaves, 5, 3);
		world.setBlock(x + 9, y + 8, z + 8, Blocks.leaves, 5, 3);
		world.setBlock(x + 10, y + 8, z + 8, Blocks.leaves, 5, 3);
		world.setBlock(x + 11, y + 8, z + 8, Blocks.leaves, 5, 3);
		world.setBlock(x + 12, y + 8, z + 8, Blocks.leaves, 5, 3);
		world.setBlock(x + 13, y + 8, z + 8, Blocks.leaves, 5, 3);
		world.setBlock(x + 14, y + 8, z + 8, Blocks.leaves, 5, 3);
		world.setBlock(x + 15, y + 8, z + 8, Blocks.leaves, 5, 3);
		world.setBlock(x + 16, y + 8, z + 8, Blocks.leaves, 5, 3);
		world.setBlock(x + 17, y + 8, z + 8, Blocks.leaves, 5, 3);
		world.setBlock(x + 18, y + 8, z + 8, Blocks.leaves, 5, 3);
		world.setBlock(x + 19, y + 8, z + 8, Blocks.leaves, 5, 3);
		world.setBlock(x + 20, y + 8, z + 8, Blocks.leaves, 5, 3);
		world.setBlock(x + 21, y + 8, z + 8, Blocks.leaves, 5, 3);
		world.setBlock(x + 22, y + 8, z + 8, Blocks.leaves, 5, 3);
		world.setBlock(x + 23, y + 8, z + 8, Blocks.leaves, 5, 3);
		world.setBlock(x + 24, y + 8, z + 8, Blocks.leaves, 5, 3);
		world.setBlock(x + 25, y + 8, z + 8, Blocks.leaves, 5, 3);
		world.setBlock(x + 26, y + 8, z + 8, Blocks.leaves, 5, 3);
		world.setBlock(x + 27, y + 8, z + 8, Blocks.leaves, 5, 3);
		world.setBlock(x + 28, y + 8, z + 8, Blocks.leaves, 5, 3);
		world.setBlock(x + 29, y + 8, z + 8, Blocks.leaves, 5, 3);
		world.setBlock(x + 1, y + 8, z + 9, Blocks.leaves, 5, 3);
		world.setBlock(x + 2, y + 8, z + 9, Blocks.leaves, 5, 3);
		world.setBlock(x + 3, y + 8, z + 9, Blocks.leaves, 5, 3);
		world.setBlock(x + 4, y + 8, z + 9, Blocks.leaves, 5, 3);
		world.setBlock(x + 5, y + 8, z + 9, Blocks.leaves, 5, 3);
		world.setBlock(x + 6, y + 8, z + 9, Blocks.leaves, 5, 3);
		world.setBlock(x + 7, y + 8, z + 9, Blocks.leaves, 5, 3);
		world.setBlock(x + 8, y + 8, z + 9, Blocks.leaves, 5, 3);
		world.setBlock(x + 9, y + 8, z + 9, Blocks.leaves, 5, 3);
		world.setBlock(x + 10, y + 8, z + 9, Blocks.leaves, 5, 3);
		world.setBlock(x + 11, y + 8, z + 9, Blocks.leaves, 5, 3);
		world.setBlock(x + 12, y + 8, z + 9, Blocks.leaves, 5, 3);
		world.setBlock(x + 13, y + 8, z + 9, Blocks.leaves, 5, 3);
		world.setBlock(x + 14, y + 8, z + 9, Blocks.leaves, 5, 3);
		world.setBlock(x + 15, y + 8, z + 9, Blocks.leaves, 5, 3);
		world.setBlock(x + 16, y + 8, z + 9, Blocks.leaves, 5, 3);
		world.setBlock(x + 17, y + 8, z + 9, Blocks.leaves, 5, 3);
		world.setBlock(x + 18, y + 8, z + 9, Blocks.leaves, 5, 3);
		world.setBlock(x + 19, y + 8, z + 9, Blocks.leaves, 5, 3);
		world.setBlock(x + 20, y + 8, z + 9, Blocks.leaves, 5, 3);
		world.setBlock(x + 21, y + 8, z + 9, Blocks.leaves, 5, 3);
		world.setBlock(x + 22, y + 8, z + 9, Blocks.leaves, 5, 3);
		world.setBlock(x + 23, y + 8, z + 9, Blocks.leaves, 5, 3);
		world.setBlock(x + 24, y + 8, z + 9, Blocks.leaves, 5, 3);
		world.setBlock(x + 25, y + 8, z + 9, Blocks.leaves, 5, 3);
		world.setBlock(x + 26, y + 8, z + 9, Blocks.leaves, 5, 3);
		world.setBlock(x + 27, y + 8, z + 9, Blocks.leaves, 5, 3);
		world.setBlock(x + 28, y + 8, z + 9, Blocks.leaves, 5, 3);
		world.setBlock(x + 29, y + 8, z + 9, Blocks.leaves, 5, 3);
		world.setBlock(x + 30, y + 8, z + 9, Blocks.leaves, 5, 3);
		world.setBlock(x + 1, y + 8, z + 10, Blocks.leaves, 5, 3);
		world.setBlock(x + 2, y + 8, z + 10, Blocks.leaves, 5, 3);
		world.setBlock(x + 3, y + 8, z + 10, Blocks.leaves, 5, 3);
		world.setBlock(x + 4, y + 8, z + 10, Blocks.leaves, 5, 3);
		world.setBlock(x + 5, y + 8, z + 10, Blocks.leaves, 5, 3);
		world.setBlock(x + 6, y + 8, z + 10, Blocks.leaves, 5, 3);
		world.setBlock(x + 7, y + 8, z + 10, Blocks.leaves, 5, 3);
		world.setBlock(x + 8, y + 8, z + 10, Blocks.leaves, 5, 3);
		world.setBlock(x + 9, y + 8, z + 10, Blocks.leaves, 5, 3);
		world.setBlock(x + 10, y + 8, z + 10, Blocks.leaves, 5, 3);
		world.setBlock(x + 11, y + 8, z + 10, Blocks.leaves, 5, 3);
		world.setBlock(x + 12, y + 8, z + 10, Blocks.leaves, 5, 3);
		world.setBlock(x + 13, y + 8, z + 10, Blocks.leaves, 5, 3);
		world.setBlock(x + 14, y + 8, z + 10, Blocks.leaves, 5, 3);
		world.setBlock(x + 15, y + 8, z + 10, Blocks.leaves, 5, 3);
		world.setBlock(x + 16, y + 8, z + 10, Blocks.leaves, 5, 3);
		world.setBlock(x + 17, y + 8, z + 10, Blocks.leaves, 5, 3);
		world.setBlock(x + 18, y + 8, z + 10, Blocks.leaves, 5, 3);
		world.setBlock(x + 19, y + 8, z + 10, Blocks.leaves, 5, 3);
		world.setBlock(x + 20, y + 8, z + 10, Blocks.leaves, 5, 3);
		world.setBlock(x + 21, y + 8, z + 10, Blocks.leaves, 5, 3);
		world.setBlock(x + 22, y + 8, z + 10, Blocks.leaves, 5, 3);
		world.setBlock(x + 23, y + 8, z + 10, Blocks.leaves, 5, 3);
		world.setBlock(x + 24, y + 8, z + 10, Blocks.leaves, 5, 3);
		world.setBlock(x + 25, y + 8, z + 10, Blocks.leaves, 5, 3);
		world.setBlock(x + 26, y + 8, z + 10, Blocks.leaves, 5, 3);
		world.setBlock(x + 27, y + 8, z + 10, Blocks.leaves, 5, 3);
		world.setBlock(x + 28, y + 8, z + 10, Blocks.leaves, 5, 3);
		world.setBlock(x + 29, y + 8, z + 10, Blocks.leaves, 5, 3);
		world.setBlock(x + 30, y + 8, z + 10, Blocks.leaves, 5, 3);
		world.setBlock(x + 1, y + 8, z + 11, Blocks.leaves, 5, 3);
		world.setBlock(x + 2, y + 8, z + 11, Blocks.leaves, 5, 3);
		world.setBlock(x + 3, y + 8, z + 11, Blocks.leaves, 5, 3);
		world.setBlock(x + 4, y + 8, z + 11, Blocks.leaves, 5, 3);
		world.setBlock(x + 5, y + 8, z + 11, Blocks.leaves, 5, 3);
		world.setBlock(x + 6, y + 8, z + 11, Blocks.leaves, 5, 3);
		world.setBlock(x + 7, y + 8, z + 11, Blocks.leaves, 5, 3);
		world.setBlock(x + 8, y + 8, z + 11, Blocks.leaves, 5, 3);
		world.setBlock(x + 9, y + 8, z + 11, Blocks.leaves, 5, 3);
		world.setBlock(x + 10, y + 8, z + 11, Blocks.leaves, 5, 3);
		world.setBlock(x + 11, y + 8, z + 11, Blocks.leaves, 5, 3);
		world.setBlock(x + 12, y + 8, z + 11, Blocks.leaves, 5, 3);
		world.setBlock(x + 13, y + 8, z + 11, Blocks.leaves, 5, 3);
		world.setBlock(x + 14, y + 8, z + 11, Blocks.leaves, 5, 3);
		world.setBlock(x + 15, y + 8, z + 11, Blocks.leaves, 5, 3);
		world.setBlock(x + 16, y + 8, z + 11, Blocks.leaves, 5, 3);
		world.setBlock(x + 17, y + 8, z + 11, Blocks.leaves, 5, 3);
		world.setBlock(x + 18, y + 8, z + 11, Blocks.leaves, 5, 3);
		world.setBlock(x + 19, y + 8, z + 11, Blocks.leaves, 5, 3);
		world.setBlock(x + 20, y + 8, z + 11, Blocks.leaves, 5, 3);
		world.setBlock(x + 21, y + 8, z + 11, Blocks.leaves, 5, 3);
		world.setBlock(x + 22, y + 8, z + 11, Blocks.leaves, 5, 3);
		world.setBlock(x + 23, y + 8, z + 11, Blocks.leaves, 5, 3);
		world.setBlock(x + 24, y + 8, z + 11, Blocks.leaves, 5, 3);
		world.setBlock(x + 25, y + 8, z + 11, Blocks.leaves, 5, 3);
		world.setBlock(x + 26, y + 8, z + 11, Blocks.leaves, 5, 3);
		world.setBlock(x + 27, y + 8, z + 11, Blocks.leaves, 5, 3);
		world.setBlock(x + 28, y + 8, z + 11, Blocks.leaves, 5, 3);
		world.setBlock(x + 29, y + 8, z + 11, Blocks.leaves, 5, 3);
		world.setBlock(x + 30, y + 8, z + 11, Blocks.leaves, 5, 3);
		world.setBlock(x + 0, y + 8, z + 12, Blocks.leaves, 5, 3);
		world.setBlock(x + 1, y + 8, z + 12, Blocks.leaves, 5, 3);
		world.setBlock(x + 2, y + 8, z + 12, Blocks.leaves, 5, 3);
		world.setBlock(x + 3, y + 8, z + 12, Blocks.leaves, 5, 3);
		world.setBlock(x + 4, y + 8, z + 12, Blocks.leaves, 5, 3);
		world.setBlock(x + 5, y + 8, z + 12, Blocks.leaves, 5, 3);
		world.setBlock(x + 6, y + 8, z + 12, Blocks.leaves, 5, 3);
		world.setBlock(x + 7, y + 8, z + 12, Blocks.leaves, 5, 3);
		world.setBlock(x + 8, y + 8, z + 12, Blocks.leaves, 5, 3);
		world.setBlock(x + 9, y + 8, z + 12, Blocks.leaves, 5, 3);
		world.setBlock(x + 10, y + 8, z + 12, Blocks.leaves, 5, 3);
		world.setBlock(x + 11, y + 8, z + 12, Blocks.leaves, 5, 3);
		world.setBlock(x + 12, y + 8, z + 12, Blocks.leaves, 5, 3);
		world.setBlock(x + 13, y + 8, z + 12, Blocks.leaves, 5, 3);
		world.setBlock(x + 14, y + 8, z + 12, Blocks.log, 1, 3);
		world.setBlock(x + 15, y + 8, z + 12, Blocks.log, 1, 3);
		world.setBlock(x + 16, y + 8, z + 12, Blocks.log, 1, 3);
		world.setBlock(x + 17, y + 8, z + 12, Blocks.log, 1, 3);
		world.setBlock(x + 18, y + 8, z + 12, Blocks.leaves, 5, 3);
		world.setBlock(x + 19, y + 8, z + 12, Blocks.leaves, 5, 3);
		world.setBlock(x + 20, y + 8, z + 12, Blocks.leaves, 5, 3);
		world.setBlock(x + 21, y + 8, z + 12, Blocks.leaves, 5, 3);
		world.setBlock(x + 22, y + 8, z + 12, Blocks.leaves, 5, 3);
		world.setBlock(x + 23, y + 8, z + 12, Blocks.leaves, 5, 3);
		world.setBlock(x + 24, y + 8, z + 12, Blocks.leaves, 5, 3);
		world.setBlock(x + 25, y + 8, z + 12, Blocks.leaves, 5, 3);
		world.setBlock(x + 26, y + 8, z + 12, Blocks.leaves, 5, 3);
		world.setBlock(x + 27, y + 8, z + 12, Blocks.leaves, 5, 3);
		world.setBlock(x + 28, y + 8, z + 12, Blocks.leaves, 5, 3);
		world.setBlock(x + 29, y + 8, z + 12, Blocks.leaves, 5, 3);
		world.setBlock(x + 30, y + 8, z + 12, Blocks.leaves, 5, 3);
		world.setBlock(x + 31, y + 8, z + 12, Blocks.leaves, 5, 3);
		world.setBlock(x + 0, y + 8, z + 13, Blocks.leaves, 5, 3);
		world.setBlock(x + 1, y + 8, z + 13, Blocks.leaves, 5, 3);
		world.setBlock(x + 2, y + 8, z + 13, Blocks.leaves, 5, 3);
		world.setBlock(x + 3, y + 8, z + 13, Blocks.leaves, 5, 3);
		world.setBlock(x + 4, y + 8, z + 13, Blocks.leaves, 5, 3);
		world.setBlock(x + 5, y + 8, z + 13, Blocks.leaves, 5, 3);
		world.setBlock(x + 6, y + 8, z + 13, Blocks.leaves, 5, 3);
		world.setBlock(x + 7, y + 8, z + 13, Blocks.leaves, 5, 3);
		world.setBlock(x + 8, y + 8, z + 13, Blocks.leaves, 5, 3);
		world.setBlock(x + 9, y + 8, z + 13, Blocks.leaves, 5, 3);
		world.setBlock(x + 10, y + 8, z + 13, Blocks.leaves, 5, 3);
		world.setBlock(x + 11, y + 8, z + 13, Blocks.leaves, 5, 3);
		world.setBlock(x + 12, y + 8, z + 13, Blocks.leaves, 5, 3);
		world.setBlock(x + 13, y + 8, z + 13, Blocks.log, 1, 3);
		world.setBlock(x + 14, y + 8, z + 13, Blocks.log, 1, 3);
		world.setBlock(x + 15, y + 8, z + 13, Blocks.log, 1, 3);
		world.setBlock(x + 16, y + 8, z + 13, Blocks.log, 1, 3);
		world.setBlock(x + 17, y + 8, z + 13, Blocks.log, 1, 3);
		world.setBlock(x + 18, y + 8, z + 13, Blocks.log, 1, 3);
		world.setBlock(x + 19, y + 8, z + 13, Blocks.leaves, 5, 3);
		world.setBlock(x + 20, y + 8, z + 13, Blocks.leaves, 5, 3);
		world.setBlock(x + 21, y + 8, z + 13, Blocks.leaves, 5, 3);
		world.setBlock(x + 22, y + 8, z + 13, Blocks.leaves, 5, 3);
		world.setBlock(x + 23, y + 8, z + 13, Blocks.leaves, 5, 3);
		world.setBlock(x + 24, y + 8, z + 13, Blocks.leaves, 5, 3);
		world.setBlock(x + 25, y + 8, z + 13, Blocks.leaves, 5, 3);
		world.setBlock(x + 26, y + 8, z + 13, Blocks.leaves, 5, 3);
		world.setBlock(x + 27, y + 8, z + 13, Blocks.leaves, 5, 3);
		world.setBlock(x + 28, y + 8, z + 13, Blocks.leaves, 5, 3);
		world.setBlock(x + 29, y + 8, z + 13, Blocks.leaves, 5, 3);
		world.setBlock(x + 30, y + 8, z + 13, Blocks.leaves, 5, 3);
		world.setBlock(x + 31, y + 8, z + 13, Blocks.leaves, 5, 3);
		world.setBlock(x + 0, y + 8, z + 14, Blocks.leaves, 5, 3);
		world.setBlock(x + 1, y + 8, z + 14, Blocks.leaves, 5, 3);
		world.setBlock(x + 2, y + 8, z + 14, Blocks.leaves, 5, 3);
		world.setBlock(x + 3, y + 8, z + 14, Blocks.leaves, 5, 3);
		world.setBlock(x + 4, y + 8, z + 14, Blocks.leaves, 5, 3);
		world.setBlock(x + 5, y + 8, z + 14, Blocks.leaves, 5, 3);
		world.setBlock(x + 6, y + 8, z + 14, Blocks.leaves, 5, 3);
		world.setBlock(x + 7, y + 8, z + 14, Blocks.leaves, 5, 3);
		world.setBlock(x + 8, y + 8, z + 14, Blocks.leaves, 5, 3);
		world.setBlock(x + 9, y + 8, z + 14, Blocks.leaves, 5, 3);
		world.setBlock(x + 10, y + 8, z + 14, Blocks.leaves, 5, 3);
		world.setBlock(x + 11, y + 8, z + 14, Blocks.leaves, 5, 3);
		world.setBlock(x + 12, y + 8, z + 14, Blocks.log, 1, 3);
		world.setBlock(x + 13, y + 8, z + 14, Blocks.log, 1, 3);
		world.setBlock(x + 14, y + 8, z + 14, Blocks.log, 1, 3);
		world.setBlock(x + 15, y + 8, z + 14, Blocks.log, 1, 3);
		world.setBlock(x + 16, y + 8, z + 14, Blocks.log, 1, 3);
		world.setBlock(x + 17, y + 8, z + 14, Blocks.log, 1, 3);
		world.setBlock(x + 18, y + 8, z + 14, Blocks.log, 1, 3);
		world.setBlock(x + 19, y + 8, z + 14, Blocks.log, 1, 3);
		world.setBlock(x + 20, y + 8, z + 14, Blocks.leaves, 5, 3);
		world.setBlock(x + 21, y + 8, z + 14, Blocks.leaves, 5, 3);
		world.setBlock(x + 22, y + 8, z + 14, Blocks.leaves, 5, 3);
		world.setBlock(x + 23, y + 8, z + 14, Blocks.leaves, 5, 3);
		world.setBlock(x + 24, y + 8, z + 14, Blocks.leaves, 5, 3);
		world.setBlock(x + 25, y + 8, z + 14, Blocks.leaves, 5, 3);
		world.setBlock(x + 26, y + 8, z + 14, Blocks.leaves, 5, 3);
		world.setBlock(x + 27, y + 8, z + 14, Blocks.leaves, 5, 3);
		world.setBlock(x + 28, y + 8, z + 14, Blocks.leaves, 5, 3);
		world.setBlock(x + 29, y + 8, z + 14, Blocks.leaves, 5, 3);
		world.setBlock(x + 30, y + 8, z + 14, Blocks.leaves, 5, 3);
		world.setBlock(x + 31, y + 8, z + 14, Blocks.leaves, 5, 3);
		world.setBlock(x + 0, y + 8, z + 15, Blocks.leaves, 5, 3);
		world.setBlock(x + 1, y + 8, z + 15, Blocks.leaves, 5, 3);
		world.setBlock(x + 2, y + 8, z + 15, Blocks.leaves, 5, 3);
		world.setBlock(x + 3, y + 8, z + 15, Blocks.leaves, 5, 3);
		world.setBlock(x + 4, y + 8, z + 15, Blocks.leaves, 5, 3);
		world.setBlock(x + 5, y + 8, z + 15, Blocks.leaves, 5, 3);
		world.setBlock(x + 6, y + 8, z + 15, Blocks.leaves, 5, 3);
		world.setBlock(x + 7, y + 8, z + 15, Blocks.leaves, 5, 3);
		world.setBlock(x + 8, y + 8, z + 15, Blocks.leaves, 5, 3);
		world.setBlock(x + 9, y + 8, z + 15, Blocks.leaves, 5, 3);
		world.setBlock(x + 10, y + 8, z + 15, Blocks.leaves, 5, 3);
		world.setBlock(x + 11, y + 8, z + 15, Blocks.leaves, 5, 3);
		world.setBlock(x + 12, y + 8, z + 15, Blocks.log, 1, 3);
		world.setBlock(x + 13, y + 8, z + 15, Blocks.log, 1, 3);
		world.setBlock(x + 14, y + 8, z + 15, Blocks.log, 1, 3);
		world.setBlock(x + 15, y + 8, z + 15, Blocks.log, 1, 3);
		world.setBlock(x + 16, y + 8, z + 15, Blocks.log, 1, 3);
		world.setBlock(x + 17, y + 8, z + 15, Blocks.log, 1, 3);
		world.setBlock(x + 18, y + 8, z + 15, Blocks.log, 1, 3);
		world.setBlock(x + 19, y + 8, z + 15, Blocks.log, 1, 3);
		world.setBlock(x + 20, y + 8, z + 15, Blocks.leaves, 5, 3);
		world.setBlock(x + 21, y + 8, z + 15, Blocks.leaves, 5, 3);
		world.setBlock(x + 22, y + 8, z + 15, Blocks.leaves, 5, 3);
		world.setBlock(x + 23, y + 8, z + 15, Blocks.leaves, 5, 3);
		world.setBlock(x + 24, y + 8, z + 15, Blocks.leaves, 5, 3);
		world.setBlock(x + 25, y + 8, z + 15, Blocks.leaves, 5, 3);
		world.setBlock(x + 26, y + 8, z + 15, Blocks.leaves, 5, 3);
		world.setBlock(x + 27, y + 8, z + 15, Blocks.leaves, 5, 3);
		world.setBlock(x + 28, y + 8, z + 15, Blocks.leaves, 5, 3);
		world.setBlock(x + 29, y + 8, z + 15, Blocks.leaves, 5, 3);
		world.setBlock(x + 30, y + 8, z + 15, Blocks.leaves, 5, 3);
		world.setBlock(x + 31, y + 8, z + 15, Blocks.leaves, 5, 3);
		world.setBlock(x + 0, y + 8, z + 16, Blocks.leaves, 5, 3);
		world.setBlock(x + 1, y + 8, z + 16, Blocks.leaves, 5, 3);
		world.setBlock(x + 2, y + 8, z + 16, Blocks.leaves, 5, 3);
		world.setBlock(x + 3, y + 8, z + 16, Blocks.leaves, 5, 3);
		world.setBlock(x + 4, y + 8, z + 16, Blocks.leaves, 5, 3);
		world.setBlock(x + 5, y + 8, z + 16, Blocks.leaves, 5, 3);
		world.setBlock(x + 6, y + 8, z + 16, Blocks.leaves, 5, 3);
		world.setBlock(x + 7, y + 8, z + 16, Blocks.leaves, 5, 3);
		world.setBlock(x + 8, y + 8, z + 16, Blocks.leaves, 5, 3);
		world.setBlock(x + 9, y + 8, z + 16, Blocks.leaves, 5, 3);
		world.setBlock(x + 10, y + 8, z + 16, Blocks.leaves, 5, 3);
		world.setBlock(x + 11, y + 8, z + 16, Blocks.leaves, 5, 3);
		world.setBlock(x + 12, y + 8, z + 16, Blocks.log, 1, 3);
		world.setBlock(x + 13, y + 8, z + 16, Blocks.log, 1, 3);
		world.setBlock(x + 14, y + 8, z + 16, Blocks.log, 1, 3);
		world.setBlock(x + 15, y + 8, z + 16, Blocks.log, 1, 3);
		world.setBlock(x + 16, y + 8, z + 16, Blocks.log, 1, 3);
		world.setBlock(x + 17, y + 8, z + 16, Blocks.log, 1, 3);
		world.setBlock(x + 18, y + 8, z + 16, Blocks.log, 1, 3);
		world.setBlock(x + 19, y + 8, z + 16, Blocks.log, 1, 3);
		world.setBlock(x + 20, y + 8, z + 16, Blocks.leaves, 5, 3);
		world.setBlock(x + 21, y + 8, z + 16, Blocks.leaves, 5, 3);
		world.setBlock(x + 22, y + 8, z + 16, Blocks.leaves, 5, 3);
		world.setBlock(x + 23, y + 8, z + 16, Blocks.leaves, 5, 3);
		world.setBlock(x + 24, y + 8, z + 16, Blocks.leaves, 5, 3);
		world.setBlock(x + 25, y + 8, z + 16, Blocks.leaves, 5, 3);
		world.setBlock(x + 26, y + 8, z + 16, Blocks.leaves, 5, 3);
		world.setBlock(x + 27, y + 8, z + 16, Blocks.leaves, 5, 3);
		world.setBlock(x + 28, y + 8, z + 16, Blocks.leaves, 5, 3);
		world.setBlock(x + 29, y + 8, z + 16, Blocks.leaves, 5, 3);
		world.setBlock(x + 30, y + 8, z + 16, Blocks.leaves, 5, 3);
		world.setBlock(x + 31, y + 8, z + 16, Blocks.leaves, 5, 3);
		world.setBlock(x + 0, y + 8, z + 17, Blocks.leaves, 5, 3);
		world.setBlock(x + 1, y + 8, z + 17, Blocks.leaves, 5, 3);
		world.setBlock(x + 2, y + 8, z + 17, Blocks.leaves, 5, 3);
		world.setBlock(x + 3, y + 8, z + 17, Blocks.leaves, 5, 3);
		world.setBlock(x + 4, y + 8, z + 17, Blocks.leaves, 5, 3);
		world.setBlock(x + 5, y + 8, z + 17, Blocks.leaves, 5, 3);
		world.setBlock(x + 6, y + 8, z + 17, Blocks.leaves, 5, 3);
		world.setBlock(x + 7, y + 8, z + 17, Blocks.leaves, 5, 3);
		world.setBlock(x + 8, y + 8, z + 17, Blocks.leaves, 5, 3);
		world.setBlock(x + 9, y + 8, z + 17, Blocks.leaves, 5, 3);
		world.setBlock(x + 10, y + 8, z + 17, Blocks.leaves, 5, 3);
		world.setBlock(x + 11, y + 8, z + 17, Blocks.leaves, 5, 3);
		world.setBlock(x + 12, y + 8, z + 17, Blocks.log, 1, 3);
		world.setBlock(x + 13, y + 8, z + 17, Blocks.log, 1, 3);
		world.setBlock(x + 14, y + 8, z + 17, Blocks.log, 1, 3);
		world.setBlock(x + 15, y + 8, z + 17, Blocks.log, 1, 3);
		world.setBlock(x + 16, y + 8, z + 17, Blocks.log, 1, 3);
		world.setBlock(x + 17, y + 8, z + 17, Blocks.log, 1, 3);
		world.setBlock(x + 18, y + 8, z + 17, Blocks.log, 1, 3);
		world.setBlock(x + 19, y + 8, z + 17, Blocks.log, 1, 3);
		world.setBlock(x + 20, y + 8, z + 17, Blocks.leaves, 5, 3);
		world.setBlock(x + 21, y + 8, z + 17, Blocks.leaves, 5, 3);
		world.setBlock(x + 22, y + 8, z + 17, Blocks.leaves, 5, 3);
		world.setBlock(x + 23, y + 8, z + 17, Blocks.leaves, 5, 3);
		world.setBlock(x + 24, y + 8, z + 17, Blocks.leaves, 5, 3);
		world.setBlock(x + 25, y + 8, z + 17, Blocks.leaves, 5, 3);
		world.setBlock(x + 26, y + 8, z + 17, Blocks.leaves, 5, 3);
		world.setBlock(x + 27, y + 8, z + 17, Blocks.leaves, 5, 3);
		world.setBlock(x + 28, y + 8, z + 17, Blocks.leaves, 5, 3);
		world.setBlock(x + 29, y + 8, z + 17, Blocks.leaves, 5, 3);
		world.setBlock(x + 30, y + 8, z + 17, Blocks.leaves, 5, 3);
		world.setBlock(x + 31, y + 8, z + 17, Blocks.leaves, 5, 3);
		world.setBlock(x + 0, y + 8, z + 18, Blocks.leaves, 5, 3);
		world.setBlock(x + 1, y + 8, z + 18, Blocks.leaves, 5, 3);
		world.setBlock(x + 2, y + 8, z + 18, Blocks.leaves, 5, 3);
		world.setBlock(x + 3, y + 8, z + 18, Blocks.leaves, 5, 3);
		world.setBlock(x + 4, y + 8, z + 18, Blocks.leaves, 5, 3);
		world.setBlock(x + 5, y + 8, z + 18, Blocks.leaves, 5, 3);
		world.setBlock(x + 6, y + 8, z + 18, Blocks.leaves, 5, 3);
		world.setBlock(x + 7, y + 8, z + 18, Blocks.leaves, 5, 3);
		world.setBlock(x + 8, y + 8, z + 18, Blocks.leaves, 5, 3);
		world.setBlock(x + 9, y + 8, z + 18, Blocks.leaves, 5, 3);
		world.setBlock(x + 10, y + 8, z + 18, Blocks.leaves, 5, 3);
		world.setBlock(x + 11, y + 8, z + 18, Blocks.leaves, 5, 3);
		world.setBlock(x + 12, y + 8, z + 18, Blocks.leaves, 5, 3);
		world.setBlock(x + 13, y + 8, z + 18, Blocks.log, 1, 3);
		world.setBlock(x + 14, y + 8, z + 18, Blocks.log, 1, 3);
		world.setBlock(x + 15, y + 8, z + 18, Blocks.log, 1, 3);
		world.setBlock(x + 16, y + 8, z + 18, Blocks.log, 1, 3);
		world.setBlock(x + 17, y + 8, z + 18, Blocks.log, 1, 3);
		world.setBlock(x + 18, y + 8, z + 18, Blocks.log, 1, 3);
		world.setBlock(x + 19, y + 8, z + 18, Blocks.leaves, 5, 3);
		world.setBlock(x + 20, y + 8, z + 18, Blocks.leaves, 5, 3);
		world.setBlock(x + 21, y + 8, z + 18, Blocks.leaves, 5, 3);
		world.setBlock(x + 22, y + 8, z + 18, Blocks.leaves, 5, 3);
		world.setBlock(x + 23, y + 8, z + 18, Blocks.leaves, 5, 3);
		world.setBlock(x + 24, y + 8, z + 18, Blocks.leaves, 5, 3);
		world.setBlock(x + 25, y + 8, z + 18, Blocks.leaves, 5, 3);
		world.setBlock(x + 26, y + 8, z + 18, Blocks.leaves, 5, 3);
		world.setBlock(x + 27, y + 8, z + 18, Blocks.leaves, 5, 3);
		world.setBlock(x + 28, y + 8, z + 18, Blocks.leaves, 5, 3);
		world.setBlock(x + 29, y + 8, z + 18, Blocks.leaves, 5, 3);
		world.setBlock(x + 30, y + 8, z + 18, Blocks.leaves, 5, 3);
		world.setBlock(x + 31, y + 8, z + 18, Blocks.leaves, 5, 3);
		world.setBlock(x + 0, y + 8, z + 19, Blocks.leaves, 5, 3);
		world.setBlock(x + 1, y + 8, z + 19, Blocks.leaves, 5, 3);
		world.setBlock(x + 2, y + 8, z + 19, Blocks.leaves, 5, 3);
		world.setBlock(x + 3, y + 8, z + 19, Blocks.leaves, 5, 3);
		world.setBlock(x + 4, y + 8, z + 19, Blocks.leaves, 5, 3);
		world.setBlock(x + 5, y + 8, z + 19, Blocks.leaves, 5, 3);
		world.setBlock(x + 6, y + 8, z + 19, Blocks.leaves, 5, 3);
		world.setBlock(x + 7, y + 8, z + 19, Blocks.leaves, 5, 3);
		world.setBlock(x + 8, y + 8, z + 19, Blocks.leaves, 5, 3);
		world.setBlock(x + 9, y + 8, z + 19, Blocks.leaves, 5, 3);
		world.setBlock(x + 10, y + 8, z + 19, Blocks.leaves, 5, 3);
		world.setBlock(x + 11, y + 8, z + 19, Blocks.leaves, 5, 3);
		world.setBlock(x + 12, y + 8, z + 19, Blocks.leaves, 5, 3);
		world.setBlock(x + 13, y + 8, z + 19, Blocks.leaves, 5, 3);
		world.setBlock(x + 14, y + 8, z + 19, Blocks.log, 1, 3);
		world.setBlock(x + 15, y + 8, z + 19, Blocks.log, 1, 3);
		world.setBlock(x + 16, y + 8, z + 19, Blocks.log, 1, 3);
		world.setBlock(x + 17, y + 8, z + 19, Blocks.log, 1, 3);
		world.setBlock(x + 18, y + 8, z + 19, Blocks.leaves, 5, 3);
		world.setBlock(x + 19, y + 8, z + 19, Blocks.leaves, 5, 3);
		world.setBlock(x + 20, y + 8, z + 19, Blocks.leaves, 5, 3);
		world.setBlock(x + 21, y + 8, z + 19, Blocks.leaves, 5, 3);
		world.setBlock(x + 22, y + 8, z + 19, Blocks.leaves, 5, 3);
		world.setBlock(x + 23, y + 8, z + 19, Blocks.leaves, 5, 3);
		world.setBlock(x + 24, y + 8, z + 19, Blocks.leaves, 5, 3);
		world.setBlock(x + 25, y + 8, z + 19, Blocks.leaves, 5, 3);
		world.setBlock(x + 26, y + 8, z + 19, Blocks.leaves, 5, 3);
		world.setBlock(x + 27, y + 8, z + 19, Blocks.leaves, 5, 3);
		world.setBlock(x + 28, y + 8, z + 19, Blocks.leaves, 5, 3);
		world.setBlock(x + 29, y + 8, z + 19, Blocks.leaves, 5, 3);
		world.setBlock(x + 30, y + 8, z + 19, Blocks.leaves, 5, 3);
		world.setBlock(x + 31, y + 8, z + 19, Blocks.leaves, 5, 3);
		world.setBlock(x + 1, y + 8, z + 20, Blocks.leaves, 5, 3);
		world.setBlock(x + 2, y + 8, z + 20, Blocks.leaves, 5, 3);
		world.setBlock(x + 3, y + 8, z + 20, Blocks.leaves, 5, 3);
		world.setBlock(x + 4, y + 8, z + 20, Blocks.leaves, 5, 3);
		world.setBlock(x + 5, y + 8, z + 20, Blocks.leaves, 5, 3);
		world.setBlock(x + 6, y + 8, z + 20, Blocks.leaves, 5, 3);
		world.setBlock(x + 7, y + 8, z + 20, Blocks.leaves, 5, 3);
		world.setBlock(x + 8, y + 8, z + 20, Blocks.leaves, 5, 3);
		world.setBlock(x + 9, y + 8, z + 20, Blocks.leaves, 5, 3);
		world.setBlock(x + 10, y + 8, z + 20, Blocks.leaves, 5, 3);
		world.setBlock(x + 11, y + 8, z + 20, Blocks.leaves, 5, 3);
		world.setBlock(x + 12, y + 8, z + 20, Blocks.leaves, 5, 3);
		world.setBlock(x + 13, y + 8, z + 20, Blocks.leaves, 5, 3);
		world.setBlock(x + 14, y + 8, z + 20, Blocks.leaves, 5, 3);
		world.setBlock(x + 15, y + 8, z + 20, Blocks.leaves, 5, 3);
		world.setBlock(x + 16, y + 8, z + 20, Blocks.leaves, 5, 3);
		world.setBlock(x + 17, y + 8, z + 20, Blocks.leaves, 5, 3);
		world.setBlock(x + 18, y + 8, z + 20, Blocks.leaves, 5, 3);
		world.setBlock(x + 19, y + 8, z + 20, Blocks.leaves, 5, 3);
		world.setBlock(x + 20, y + 8, z + 20, Blocks.leaves, 5, 3);
		world.setBlock(x + 21, y + 8, z + 20, Blocks.leaves, 5, 3);
		world.setBlock(x + 22, y + 8, z + 20, Blocks.leaves, 5, 3);
		world.setBlock(x + 23, y + 8, z + 20, Blocks.leaves, 5, 3);
		world.setBlock(x + 24, y + 8, z + 20, Blocks.leaves, 5, 3);
		world.setBlock(x + 25, y + 8, z + 20, Blocks.leaves, 5, 3);
		world.setBlock(x + 26, y + 8, z + 20, Blocks.leaves, 5, 3);
		world.setBlock(x + 27, y + 8, z + 20, Blocks.leaves, 5, 3);
		world.setBlock(x + 28, y + 8, z + 20, Blocks.leaves, 5, 3);
		world.setBlock(x + 29, y + 8, z + 20, Blocks.leaves, 5, 3);
		world.setBlock(x + 30, y + 8, z + 20, Blocks.leaves, 5, 3);
		world.setBlock(x + 1, y + 8, z + 21, Blocks.leaves, 5, 3);
		world.setBlock(x + 2, y + 8, z + 21, Blocks.leaves, 5, 3);
		world.setBlock(x + 3, y + 8, z + 21, Blocks.leaves, 5, 3);
		world.setBlock(x + 4, y + 8, z + 21, Blocks.leaves, 5, 3);
		world.setBlock(x + 5, y + 8, z + 21, Blocks.leaves, 5, 3);
		world.setBlock(x + 6, y + 8, z + 21, Blocks.leaves, 5, 3);
		world.setBlock(x + 7, y + 8, z + 21, Blocks.leaves, 5, 3);
		world.setBlock(x + 8, y + 8, z + 21, Blocks.leaves, 5, 3);
		world.setBlock(x + 9, y + 8, z + 21, Blocks.leaves, 5, 3);
		world.setBlock(x + 10, y + 8, z + 21, Blocks.leaves, 5, 3);
		world.setBlock(x + 11, y + 8, z + 21, Blocks.leaves, 5, 3);
		world.setBlock(x + 12, y + 8, z + 21, Blocks.leaves, 5, 3);
		world.setBlock(x + 13, y + 8, z + 21, Blocks.leaves, 5, 3);
		world.setBlock(x + 14, y + 8, z + 21, Blocks.leaves, 5, 3);
		world.setBlock(x + 15, y + 8, z + 21, Blocks.leaves, 5, 3);
		world.setBlock(x + 16, y + 8, z + 21, Blocks.leaves, 5, 3);
		world.setBlock(x + 17, y + 8, z + 21, Blocks.leaves, 5, 3);
		world.setBlock(x + 18, y + 8, z + 21, Blocks.leaves, 5, 3);
		world.setBlock(x + 19, y + 8, z + 21, Blocks.leaves, 5, 3);
		world.setBlock(x + 20, y + 8, z + 21, Blocks.leaves, 5, 3);
		world.setBlock(x + 21, y + 8, z + 21, Blocks.leaves, 5, 3);
		world.setBlock(x + 22, y + 8, z + 21, Blocks.leaves, 5, 3);
		world.setBlock(x + 23, y + 8, z + 21, Blocks.leaves, 5, 3);
		world.setBlock(x + 24, y + 8, z + 21, Blocks.leaves, 5, 3);
		world.setBlock(x + 25, y + 8, z + 21, Blocks.leaves, 5, 3);
		world.setBlock(x + 26, y + 8, z + 21, Blocks.leaves, 5, 3);
		world.setBlock(x + 27, y + 8, z + 21, Blocks.leaves, 5, 3);
		world.setBlock(x + 28, y + 8, z + 21, Blocks.leaves, 5, 3);
		world.setBlock(x + 29, y + 8, z + 21, Blocks.leaves, 5, 3);
		world.setBlock(x + 30, y + 8, z + 21, Blocks.leaves, 5, 3);
		world.setBlock(x + 1, y + 8, z + 22, Blocks.leaves, 5, 3);
		world.setBlock(x + 2, y + 8, z + 22, Blocks.leaves, 5, 3);
		world.setBlock(x + 3, y + 8, z + 22, Blocks.leaves, 5, 3);
		world.setBlock(x + 4, y + 8, z + 22, Blocks.leaves, 5, 3);
		world.setBlock(x + 5, y + 8, z + 22, Blocks.leaves, 5, 3);
		world.setBlock(x + 6, y + 8, z + 22, Blocks.leaves, 5, 3);
		world.setBlock(x + 7, y + 8, z + 22, Blocks.leaves, 5, 3);
		world.setBlock(x + 8, y + 8, z + 22, Blocks.leaves, 5, 3);
		world.setBlock(x + 9, y + 8, z + 22, Blocks.leaves, 5, 3);
		world.setBlock(x + 10, y + 8, z + 22, Blocks.leaves, 5, 3);
		world.setBlock(x + 11, y + 8, z + 22, Blocks.leaves, 5, 3);
		world.setBlock(x + 12, y + 8, z + 22, Blocks.leaves, 5, 3);
		world.setBlock(x + 13, y + 8, z + 22, Blocks.leaves, 5, 3);
		world.setBlock(x + 14, y + 8, z + 22, Blocks.leaves, 5, 3);
		world.setBlock(x + 15, y + 8, z + 22, Blocks.leaves, 5, 3);
		world.setBlock(x + 16, y + 8, z + 22, Blocks.leaves, 5, 3);
		world.setBlock(x + 17, y + 8, z + 22, Blocks.leaves, 5, 3);
		world.setBlock(x + 18, y + 8, z + 22, Blocks.leaves, 5, 3);
		world.setBlock(x + 19, y + 8, z + 22, Blocks.leaves, 5, 3);
		world.setBlock(x + 20, y + 8, z + 22, Blocks.leaves, 5, 3);
		world.setBlock(x + 21, y + 8, z + 22, Blocks.leaves, 5, 3);
		world.setBlock(x + 22, y + 8, z + 22, Blocks.leaves, 5, 3);
		world.setBlock(x + 23, y + 8, z + 22, Blocks.leaves, 5, 3);
		world.setBlock(x + 24, y + 8, z + 22, Blocks.leaves, 5, 3);
		world.setBlock(x + 25, y + 8, z + 22, Blocks.leaves, 5, 3);
		world.setBlock(x + 26, y + 8, z + 22, Blocks.leaves, 5, 3);
		world.setBlock(x + 27, y + 8, z + 22, Blocks.leaves, 5, 3);
		world.setBlock(x + 28, y + 8, z + 22, Blocks.leaves, 5, 3);
		world.setBlock(x + 29, y + 8, z + 22, Blocks.leaves, 5, 3);
		world.setBlock(x + 30, y + 8, z + 22, Blocks.leaves, 5, 3);
		world.setBlock(x + 2, y + 8, z + 23, Blocks.leaves, 5, 3);
		world.setBlock(x + 3, y + 8, z + 23, Blocks.leaves, 5, 3);
		world.setBlock(x + 4, y + 8, z + 23, Blocks.leaves, 5, 3);
		world.setBlock(x + 5, y + 8, z + 23, Blocks.leaves, 5, 3);
		world.setBlock(x + 6, y + 8, z + 23, Blocks.leaves, 5, 3);
		world.setBlock(x + 7, y + 8, z + 23, Blocks.leaves, 5, 3);
		world.setBlock(x + 8, y + 8, z + 23, Blocks.leaves, 5, 3);
		world.setBlock(x + 9, y + 8, z + 23, Blocks.leaves, 5, 3);
		world.setBlock(x + 10, y + 8, z + 23, Blocks.leaves, 5, 3);
		world.setBlock(x + 11, y + 8, z + 23, Blocks.leaves, 5, 3);
		world.setBlock(x + 12, y + 8, z + 23, Blocks.leaves, 5, 3);
		world.setBlock(x + 13, y + 8, z + 23, Blocks.leaves, 5, 3);
		world.setBlock(x + 14, y + 8, z + 23, Blocks.leaves, 5, 3);
		world.setBlock(x + 15, y + 8, z + 23, Blocks.leaves, 5, 3);
		world.setBlock(x + 16, y + 8, z + 23, Blocks.leaves, 5, 3);
		world.setBlock(x + 17, y + 8, z + 23, Blocks.leaves, 5, 3);
		world.setBlock(x + 18, y + 8, z + 23, Blocks.leaves, 5, 3);
		world.setBlock(x + 19, y + 8, z + 23, Blocks.leaves, 5, 3);
		world.setBlock(x + 20, y + 8, z + 23, Blocks.leaves, 5, 3);
		world.setBlock(x + 21, y + 8, z + 23, Blocks.leaves, 5, 3);
		world.setBlock(x + 22, y + 8, z + 23, Blocks.leaves, 5, 3);
		world.setBlock(x + 23, y + 8, z + 23, Blocks.leaves, 5, 3);
		world.setBlock(x + 24, y + 8, z + 23, Blocks.leaves, 5, 3);
		world.setBlock(x + 25, y + 8, z + 23, Blocks.leaves, 5, 3);
		world.setBlock(x + 26, y + 8, z + 23, Blocks.leaves, 5, 3);
		world.setBlock(x + 27, y + 8, z + 23, Blocks.leaves, 5, 3);
		world.setBlock(x + 28, y + 8, z + 23, Blocks.leaves, 5, 3);
		world.setBlock(x + 29, y + 8, z + 23, Blocks.leaves, 5, 3);
		world.setBlock(x + 2, y + 8, z + 24, Blocks.leaves, 5, 3);
		world.setBlock(x + 3, y + 8, z + 24, Blocks.leaves, 5, 3);
		world.setBlock(x + 4, y + 8, z + 24, Blocks.leaves, 5, 3);
		world.setBlock(x + 5, y + 8, z + 24, Blocks.leaves, 5, 3);
		world.setBlock(x + 6, y + 8, z + 24, Blocks.leaves, 5, 3);
		world.setBlock(x + 7, y + 8, z + 24, Blocks.leaves, 5, 3);
		world.setBlock(x + 8, y + 8, z + 24, Blocks.leaves, 5, 3);
		world.setBlock(x + 9, y + 8, z + 24, Blocks.leaves, 5, 3);
		world.setBlock(x + 10, y + 8, z + 24, Blocks.leaves, 5, 3);
		world.setBlock(x + 11, y + 8, z + 24, Blocks.leaves, 5, 3);
		world.setBlock(x + 12, y + 8, z + 24, Blocks.leaves, 5, 3);
		world.setBlock(x + 13, y + 8, z + 24, Blocks.leaves, 5, 3);
		world.setBlock(x + 14, y + 8, z + 24, Blocks.leaves, 5, 3);
		world.setBlock(x + 15, y + 8, z + 24, Blocks.leaves, 5, 3);
		world.setBlock(x + 16, y + 8, z + 24, Blocks.leaves, 5, 3);
		world.setBlock(x + 17, y + 8, z + 24, Blocks.leaves, 5, 3);
		world.setBlock(x + 18, y + 8, z + 24, Blocks.leaves, 5, 3);
		world.setBlock(x + 19, y + 8, z + 24, Blocks.leaves, 5, 3);
		world.setBlock(x + 20, y + 8, z + 24, Blocks.leaves, 5, 3);
		world.setBlock(x + 21, y + 8, z + 24, Blocks.leaves, 5, 3);
		world.setBlock(x + 22, y + 8, z + 24, Blocks.leaves, 5, 3);
		world.setBlock(x + 23, y + 8, z + 24, Blocks.leaves, 5, 3);
		world.setBlock(x + 24, y + 8, z + 24, Blocks.leaves, 5, 3);
		world.setBlock(x + 25, y + 8, z + 24, Blocks.leaves, 5, 3);
		world.setBlock(x + 26, y + 8, z + 24, Blocks.leaves, 5, 3);
		world.setBlock(x + 27, y + 8, z + 24, Blocks.leaves, 5, 3);
		world.setBlock(x + 28, y + 8, z + 24, Blocks.leaves, 5, 3);
		world.setBlock(x + 29, y + 8, z + 24, Blocks.leaves, 5, 3);
		world.setBlock(x + 3, y + 8, z + 25, Blocks.leaves, 5, 3);
		world.setBlock(x + 4, y + 8, z + 25, Blocks.leaves, 5, 3);
		world.setBlock(x + 5, y + 8, z + 25, Blocks.leaves, 5, 3);
		world.setBlock(x + 6, y + 8, z + 25, Blocks.leaves, 5, 3);
		world.setBlock(x + 7, y + 8, z + 25, Blocks.leaves, 5, 3);
		world.setBlock(x + 8, y + 8, z + 25, Blocks.leaves, 5, 3);
		world.setBlock(x + 9, y + 8, z + 25, Blocks.leaves, 5, 3);
		world.setBlock(x + 10, y + 8, z + 25, Blocks.leaves, 5, 3);
		world.setBlock(x + 11, y + 8, z + 25, Blocks.leaves, 5, 3);
		world.setBlock(x + 12, y + 8, z + 25, Blocks.leaves, 5, 3);
		world.setBlock(x + 13, y + 8, z + 25, Blocks.leaves, 5, 3);
		world.setBlock(x + 14, y + 8, z + 25, Blocks.leaves, 5, 3);
		world.setBlock(x + 15, y + 8, z + 25, Blocks.leaves, 5, 3);
		world.setBlock(x + 16, y + 8, z + 25, Blocks.leaves, 5, 3);
		world.setBlock(x + 17, y + 8, z + 25, Blocks.leaves, 5, 3);
		world.setBlock(x + 18, y + 8, z + 25, Blocks.leaves, 5, 3);
		world.setBlock(x + 19, y + 8, z + 25, Blocks.leaves, 5, 3);
		world.setBlock(x + 20, y + 8, z + 25, Blocks.leaves, 5, 3);
		world.setBlock(x + 21, y + 8, z + 25, Blocks.leaves, 5, 3);
		world.setBlock(x + 22, y + 8, z + 25, Blocks.leaves, 5, 3);
		world.setBlock(x + 23, y + 8, z + 25, Blocks.leaves, 5, 3);
		world.setBlock(x + 24, y + 8, z + 25, Blocks.leaves, 5, 3);
		world.setBlock(x + 25, y + 8, z + 25, Blocks.leaves, 5, 3);
		world.setBlock(x + 26, y + 8, z + 25, Blocks.leaves, 5, 3);
		world.setBlock(x + 27, y + 8, z + 25, Blocks.leaves, 5, 3);
		world.setBlock(x + 28, y + 8, z + 25, Blocks.leaves, 5, 3);
		world.setBlock(x + 4, y + 8, z + 26, Blocks.leaves, 5, 3);
		world.setBlock(x + 5, y + 8, z + 26, Blocks.leaves, 5, 3);
		world.setBlock(x + 6, y + 8, z + 26, Blocks.leaves, 5, 3);
		world.setBlock(x + 7, y + 8, z + 26, Blocks.leaves, 5, 3);
		world.setBlock(x + 8, y + 8, z + 26, Blocks.leaves, 5, 3);
		world.setBlock(x + 9, y + 8, z + 26, Blocks.leaves, 5, 3);
		world.setBlock(x + 10, y + 8, z + 26, Blocks.leaves, 5, 3);
		world.setBlock(x + 11, y + 8, z + 26, Blocks.leaves, 5, 3);
		world.setBlock(x + 12, y + 8, z + 26, Blocks.leaves, 5, 3);
		world.setBlock(x + 13, y + 8, z + 26, Blocks.leaves, 5, 3);
		world.setBlock(x + 14, y + 8, z + 26, Blocks.leaves, 5, 3);
		world.setBlock(x + 15, y + 8, z + 26, Blocks.leaves, 5, 3);
		world.setBlock(x + 16, y + 8, z + 26, Blocks.leaves, 5, 3);
		world.setBlock(x + 17, y + 8, z + 26, Blocks.leaves, 5, 3);
		world.setBlock(x + 18, y + 8, z + 26, Blocks.leaves, 5, 3);
		world.setBlock(x + 19, y + 8, z + 26, Blocks.leaves, 5, 3);
		world.setBlock(x + 20, y + 8, z + 26, Blocks.leaves, 5, 3);
		world.setBlock(x + 21, y + 8, z + 26, Blocks.leaves, 5, 3);
		world.setBlock(x + 22, y + 8, z + 26, Blocks.leaves, 5, 3);
		world.setBlock(x + 23, y + 8, z + 26, Blocks.leaves, 5, 3);
		world.setBlock(x + 24, y + 8, z + 26, Blocks.leaves, 5, 3);
		world.setBlock(x + 25, y + 8, z + 26, Blocks.leaves, 5, 3);
		world.setBlock(x + 26, y + 8, z + 26, Blocks.leaves, 5, 3);
		world.setBlock(x + 27, y + 8, z + 26, Blocks.leaves, 5, 3);
		world.setBlock(x + 5, y + 8, z + 27, Blocks.leaves, 5, 3);
		world.setBlock(x + 6, y + 8, z + 27, Blocks.leaves, 5, 3);
		world.setBlock(x + 7, y + 8, z + 27, Blocks.leaves, 5, 3);
		world.setBlock(x + 8, y + 8, z + 27, Blocks.leaves, 5, 3);
		world.setBlock(x + 9, y + 8, z + 27, Blocks.leaves, 5, 3);
		world.setBlock(x + 10, y + 8, z + 27, Blocks.leaves, 5, 3);
		world.setBlock(x + 11, y + 8, z + 27, Blocks.leaves, 5, 3);
		world.setBlock(x + 12, y + 8, z + 27, Blocks.leaves, 5, 3);
		world.setBlock(x + 13, y + 8, z + 27, Blocks.leaves, 5, 3);
		world.setBlock(x + 14, y + 8, z + 27, Blocks.leaves, 5, 3);
		world.setBlock(x + 15, y + 8, z + 27, Blocks.leaves, 5, 3);
		world.setBlock(x + 16, y + 8, z + 27, Blocks.leaves, 5, 3);
		world.setBlock(x + 17, y + 8, z + 27, Blocks.leaves, 5, 3);
		world.setBlock(x + 18, y + 8, z + 27, Blocks.leaves, 5, 3);
		world.setBlock(x + 19, y + 8, z + 27, Blocks.leaves, 5, 3);
		world.setBlock(x + 20, y + 8, z + 27, Blocks.leaves, 5, 3);
		world.setBlock(x + 21, y + 8, z + 27, Blocks.leaves, 5, 3);
		world.setBlock(x + 22, y + 8, z + 27, Blocks.leaves, 5, 3);
		world.setBlock(x + 23, y + 8, z + 27, Blocks.leaves, 5, 3);
		world.setBlock(x + 24, y + 8, z + 27, Blocks.leaves, 5, 3);
		world.setBlock(x + 25, y + 8, z + 27, Blocks.leaves, 5, 3);
		world.setBlock(x + 26, y + 8, z + 27, Blocks.leaves, 5, 3);
		world.setBlock(x + 6, y + 8, z + 28, Blocks.leaves, 5, 3);
		world.setBlock(x + 7, y + 8, z + 28, Blocks.leaves, 5, 3);
		world.setBlock(x + 8, y + 8, z + 28, Blocks.leaves, 5, 3);
		world.setBlock(x + 9, y + 8, z + 28, Blocks.leaves, 5, 3);
		world.setBlock(x + 10, y + 8, z + 28, Blocks.leaves, 5, 3);
		world.setBlock(x + 11, y + 8, z + 28, Blocks.leaves, 5, 3);
		world.setBlock(x + 12, y + 8, z + 28, Blocks.leaves, 5, 3);
		world.setBlock(x + 13, y + 8, z + 28, Blocks.leaves, 5, 3);
		world.setBlock(x + 14, y + 8, z + 28, Blocks.leaves, 5, 3);
		world.setBlock(x + 15, y + 8, z + 28, Blocks.leaves, 5, 3);
		world.setBlock(x + 16, y + 8, z + 28, Blocks.leaves, 5, 3);
		world.setBlock(x + 17, y + 8, z + 28, Blocks.leaves, 5, 3);
		world.setBlock(x + 18, y + 8, z + 28, Blocks.leaves, 5, 3);
		world.setBlock(x + 19, y + 8, z + 28, Blocks.leaves, 5, 3);
		world.setBlock(x + 20, y + 8, z + 28, Blocks.leaves, 5, 3);
		world.setBlock(x + 21, y + 8, z + 28, Blocks.leaves, 5, 3);
		world.setBlock(x + 22, y + 8, z + 28, Blocks.leaves, 5, 3);
		world.setBlock(x + 23, y + 8, z + 28, Blocks.leaves, 5, 3);
		world.setBlock(x + 24, y + 8, z + 28, Blocks.leaves, 5, 3);
		world.setBlock(x + 25, y + 8, z + 28, Blocks.leaves, 5, 3);
		world.setBlock(x + 7, y + 8, z + 29, Blocks.leaves, 5, 3);
		world.setBlock(x + 8, y + 8, z + 29, Blocks.leaves, 5, 3);
		world.setBlock(x + 9, y + 8, z + 29, Blocks.leaves, 5, 3);
		world.setBlock(x + 10, y + 8, z + 29, Blocks.leaves, 5, 3);
		world.setBlock(x + 11, y + 8, z + 29, Blocks.leaves, 5, 3);
		world.setBlock(x + 12, y + 8, z + 29, Blocks.leaves, 5, 3);
		world.setBlock(x + 13, y + 8, z + 29, Blocks.leaves, 5, 3);
		world.setBlock(x + 14, y + 8, z + 29, Blocks.leaves, 5, 3);
		world.setBlock(x + 15, y + 8, z + 29, Blocks.leaves, 5, 3);
		world.setBlock(x + 16, y + 8, z + 29, Blocks.leaves, 5, 3);
		world.setBlock(x + 17, y + 8, z + 29, Blocks.leaves, 5, 3);
		world.setBlock(x + 18, y + 8, z + 29, Blocks.leaves, 5, 3);
		world.setBlock(x + 19, y + 8, z + 29, Blocks.leaves, 5, 3);
		world.setBlock(x + 20, y + 8, z + 29, Blocks.leaves, 5, 3);
		world.setBlock(x + 21, y + 8, z + 29, Blocks.leaves, 5, 3);
		world.setBlock(x + 22, y + 8, z + 29, Blocks.leaves, 5, 3);
		world.setBlock(x + 23, y + 8, z + 29, Blocks.leaves, 5, 3);
		world.setBlock(x + 24, y + 8, z + 29, Blocks.leaves, 5, 3);
		world.setBlock(x + 9, y + 8, z + 30, Blocks.leaves, 5, 3);
		world.setBlock(x + 10, y + 8, z + 30, Blocks.leaves, 5, 3);
		world.setBlock(x + 11, y + 8, z + 30, Blocks.leaves, 5, 3);
		world.setBlock(x + 12, y + 8, z + 30, Blocks.leaves, 5, 3);
		world.setBlock(x + 13, y + 8, z + 30, Blocks.leaves, 5, 3);
		world.setBlock(x + 14, y + 8, z + 30, Blocks.leaves, 5, 3);
		world.setBlock(x + 15, y + 8, z + 30, Blocks.leaves, 5, 3);
		world.setBlock(x + 16, y + 8, z + 30, Blocks.leaves, 5, 3);
		world.setBlock(x + 17, y + 8, z + 30, Blocks.leaves, 5, 3);
		world.setBlock(x + 18, y + 8, z + 30, Blocks.leaves, 5, 3);
		world.setBlock(x + 19, y + 8, z + 30, Blocks.leaves, 5, 3);
		world.setBlock(x + 20, y + 8, z + 30, Blocks.leaves, 5, 3);
		world.setBlock(x + 21, y + 8, z + 30, Blocks.leaves, 5, 3);
		world.setBlock(x + 22, y + 8, z + 30, Blocks.leaves, 5, 3);
		world.setBlock(x + 12, y + 8, z + 31, Blocks.leaves, 5, 3);
		world.setBlock(x + 13, y + 8, z + 31, Blocks.leaves, 5, 3);
		world.setBlock(x + 14, y + 8, z + 31, Blocks.leaves, 5, 3);
		world.setBlock(x + 15, y + 8, z + 31, Blocks.leaves, 5, 3);
		world.setBlock(x + 16, y + 8, z + 31, Blocks.leaves, 5, 3);
		world.setBlock(x + 17, y + 8, z + 31, Blocks.leaves, 5, 3);
		world.setBlock(x + 18, y + 8, z + 31, Blocks.leaves, 5, 3);
		world.setBlock(x + 19, y + 8, z + 31, Blocks.leaves, 5, 3);
		world.setBlock(x + 12, y + 9, z + 0, Blocks.snow_layer, 0, 3);
		world.setBlock(x + 13, y + 9, z + 0, Blocks.snow_layer, 3, 3);
		world.setBlock(x + 14, y + 9, z + 0, Blocks.snow_layer, 0, 3);
		world.setBlock(x + 15, y + 9, z + 0, Blocks.snow_layer, 1, 3);
		world.setBlock(x + 16, y + 9, z + 0, Blocks.snow_layer, 1, 3);
		world.setBlock(x + 17, y + 9, z + 0, Blocks.snow_layer, 0, 3);
		world.setBlock(x + 18, y + 9, z + 0, Blocks.snow_layer, 0, 3);
		world.setBlock(x + 19, y + 9, z + 0, Blocks.wool, 10, 3);
		world.setBlock(x + 9, y + 9, z + 1, Blocks.snow_layer, 1, 3);
		world.setBlock(x + 10, y + 9, z + 1, Blocks.snow_layer, 0, 3);
		world.setBlock(x + 11, y + 9, z + 1, Blocks.snow_layer, 1, 3);
		world.setBlock(x + 12, y + 9, z + 1, Blocks.snow_layer, 1, 3);
		world.setBlock(x + 13, y + 9, z + 1, Blocks.snow_layer, 0, 3);
		world.setBlock(x + 14, y + 9, z + 1, Blocks.snow_layer, 0, 3);
		world.setBlock(x + 15, y + 9, z + 1, Blocks.snow_layer, 2, 3);
		world.setBlock(x + 16, y + 9, z + 1, Blocks.snow_layer, 0, 3);
		world.setBlock(x + 17, y + 9, z + 1, Blocks.snow_layer, 1, 3);
		world.setBlock(x + 18, y + 9, z + 1, Blocks.snow_layer, 0, 3);
		world.setBlock(x + 19, y + 9, z + 1, Blocks.snow_layer, 1, 3);
		world.setBlock(x + 20, y + 9, z + 1, Blocks.snow_layer, 1, 3);
		world.setBlock(x + 21, y + 9, z + 1, Blocks.snow_layer, 1, 3);
		world.setBlock(x + 22, y + 9, z + 1, Blocks.snow_layer, 1, 3);
		world.setBlock(x + 7, y + 9, z + 2, Blocks.wool, 4, 3);
		world.setBlock(x + 8, y + 9, z + 2, Blocks.snow_layer, 0, 3);
		world.setBlock(x + 9, y + 9, z + 2, Blocks.snow_layer, 1, 3);
		world.setBlock(x + 10, y + 9, z + 2, Blocks.snow_layer, 1, 3);
		world.setBlock(x + 11, y + 9, z + 2, Blocks.wool, 10, 3);
		world.setBlock(x + 12, y + 9, z + 2, Blocks.leaves, 5, 3);
		world.setBlock(x + 13, y + 9, z + 2, Blocks.leaves, 5, 3);
		world.setBlock(x + 14, y + 9, z + 2, Blocks.leaves, 5, 3);
		world.setBlock(x + 15, y + 9, z + 2, Blocks.leaves, 5, 3);
		world.setBlock(x + 16, y + 9, z + 2, Blocks.leaves, 5, 3);
		world.setBlock(x + 17, y + 9, z + 2, Blocks.leaves, 5, 3);
		world.setBlock(x + 18, y + 9, z + 2, Blocks.leaves, 5, 3);
		world.setBlock(x + 19, y + 9, z + 2, Blocks.leaves, 5, 3);
		world.setBlock(x + 20, y + 9, z + 2, Blocks.snow_layer, 0, 3);
		world.setBlock(x + 21, y + 9, z + 2, Blocks.snow_layer, 1, 3);
		world.setBlock(x + 22, y + 9, z + 2, Blocks.snow_layer, 0, 3);
		world.setBlock(x + 23, y + 9, z + 2, Blocks.snow_layer, 1, 3);
		world.setBlock(x + 24, y + 9, z + 2, Blocks.snow_layer, 0, 3);
		world.setBlock(x + 6, y + 9, z + 3, Blocks.snow_layer, 0, 3);
		world.setBlock(x + 7, y + 9, z + 3, Blocks.snow_layer, 0, 3);
		world.setBlock(x + 8, y + 9, z + 3, Blocks.snow_layer, 0, 3);
		world.setBlock(x + 9, y + 9, z + 3, Blocks.snow_layer, 0, 3);
		world.setBlock(x + 10, y + 9, z + 3, Blocks.leaves, 5, 3);
		world.setBlock(x + 11, y + 9, z + 3, Blocks.leaves, 5, 3);
		world.setBlock(x + 12, y + 9, z + 3, Blocks.leaves, 5, 3);
		world.setBlock(x + 13, y + 9, z + 3, Blocks.leaves, 5, 3);
		world.setBlock(x + 14, y + 9, z + 3, Blocks.leaves, 5, 3);
		world.setBlock(x + 15, y + 9, z + 3, Blocks.leaves, 5, 3);
		world.setBlock(x + 16, y + 9, z + 3, Blocks.leaves, 5, 3);
		world.setBlock(x + 17, y + 9, z + 3, Blocks.leaves, 5, 3);
		world.setBlock(x + 18, y + 9, z + 3, Blocks.leaves, 5, 3);
		world.setBlock(x + 19, y + 9, z + 3, Blocks.leaves, 5, 3);
		world.setBlock(x + 20, y + 9, z + 3, Blocks.leaves, 5, 3);
		world.setBlock(x + 21, y + 9, z + 3, Blocks.leaves, 5, 3);
		world.setBlock(x + 22, y + 9, z + 3, Blocks.snow_layer, 0, 3);
		world.setBlock(x + 23, y + 9, z + 3, Blocks.wool, 4, 3);
		world.setBlock(x + 24, y + 9, z + 3, Blocks.snow_layer, 1, 3);
		world.setBlock(x + 25, y + 9, z + 3, Blocks.snow_layer, 0, 3);
		world.setBlock(x + 5, y + 9, z + 4, Blocks.snow_layer, 0, 3);
		world.setBlock(x + 6, y + 9, z + 4, Blocks.snow_layer, 0, 3);
		world.setBlock(x + 7, y + 9, z + 4, Blocks.snow_layer, 0, 3);
		world.setBlock(x + 8, y + 9, z + 4, Blocks.leaves, 5, 3);
		world.setBlock(x + 9, y + 9, z + 4, Blocks.leaves, 5, 3);
		world.setBlock(x + 10, y + 9, z + 4, Blocks.leaves, 5, 3);
		world.setBlock(x + 11, y + 9, z + 4, Blocks.leaves, 5, 3);
		world.setBlock(x + 12, y + 9, z + 4, Blocks.leaves, 5, 3);
		world.setBlock(x + 13, y + 9, z + 4, Blocks.leaves, 5, 3);
		world.setBlock(x + 14, y + 9, z + 4, Blocks.leaves, 5, 3);
		world.setBlock(x + 15, y + 9, z + 4, Blocks.leaves, 5, 3);
		world.setBlock(x + 16, y + 9, z + 4, Blocks.leaves, 5, 3);
		world.setBlock(x + 17, y + 9, z + 4, Blocks.leaves, 5, 3);
		world.setBlock(x + 18, y + 9, z + 4, Blocks.leaves, 5, 3);
		world.setBlock(x + 19, y + 9, z + 4, Blocks.leaves, 5, 3);
		world.setBlock(x + 20, y + 9, z + 4, Blocks.leaves, 5, 3);
		world.setBlock(x + 21, y + 9, z + 4, Blocks.leaves, 5, 3);
		world.setBlock(x + 22, y + 9, z + 4, Blocks.leaves, 5, 3);
		world.setBlock(x + 23, y + 9, z + 4, Blocks.leaves, 5, 3);
		world.setBlock(x + 24, y + 9, z + 4, Blocks.snow_layer, 0, 3);
		world.setBlock(x + 25, y + 9, z + 4, Blocks.snow_layer, 1, 3);
		world.setBlock(x + 26, y + 9, z + 4, Blocks.snow_layer, 0, 3);
		world.setBlock(x + 4, y + 9, z + 5, Blocks.snow_layer, 0, 3);
		world.setBlock(x + 5, y + 9, z + 5, Blocks.snow_layer, 0, 3);
		world.setBlock(x + 6, y + 9, z + 5, Blocks.snow_layer, 0, 3);
		world.setBlock(x + 7, y + 9, z + 5, Blocks.leaves, 5, 3);
		world.setBlock(x + 8, y + 9, z + 5, Blocks.leaves, 5, 3);
		world.setBlock(x + 9, y + 9, z + 5, Blocks.leaves, 5, 3);
		world.setBlock(x + 10, y + 9, z + 5, Blocks.leaves, 5, 3);
		world.setBlock(x + 11, y + 9, z + 5, Blocks.leaves, 5, 3);
		world.setBlock(x + 12, y + 9, z + 5, Blocks.leaves, 5, 3);
		world.setBlock(x + 13, y + 9, z + 5, Blocks.leaves, 5, 3);
		world.setBlock(x + 14, y + 9, z + 5, Blocks.leaves, 5, 3);
		world.setBlock(x + 15, y + 9, z + 5, Blocks.leaves, 5, 3);
		world.setBlock(x + 16, y + 9, z + 5, Blocks.leaves, 5, 3);
		world.setBlock(x + 17, y + 9, z + 5, Blocks.leaves, 5, 3);
		world.setBlock(x + 18, y + 9, z + 5, Blocks.leaves, 5, 3);
		world.setBlock(x + 19, y + 9, z + 5, Blocks.leaves, 5, 3);
		world.setBlock(x + 20, y + 9, z + 5, Blocks.leaves, 5, 3);
		world.setBlock(x + 21, y + 9, z + 5, Blocks.leaves, 5, 3);
		world.setBlock(x + 22, y + 9, z + 5, Blocks.leaves, 5, 3);
		world.setBlock(x + 23, y + 9, z + 5, Blocks.leaves, 5, 3);
		world.setBlock(x + 24, y + 9, z + 5, Blocks.leaves, 5, 3);
		world.setBlock(x + 25, y + 9, z + 5, Blocks.snow_layer, 0, 3);
		world.setBlock(x + 26, y + 9, z + 5, Blocks.snow_layer, 1, 3);
		world.setBlock(x + 27, y + 9, z + 5, Blocks.snow_layer, 0, 3);
		world.setBlock(x + 3, y + 9, z + 6, Blocks.snow_layer, 0, 3);
		world.setBlock(x + 4, y + 9, z + 6, Blocks.snow_layer, 0, 3);
		world.setBlock(x + 5, y + 9, z + 6, Blocks.snow_layer, 0, 3);
		world.setBlock(x + 6, y + 9, z + 6, Blocks.leaves, 5, 3);
		world.setBlock(x + 7, y + 9, z + 6, Blocks.leaves, 5, 3);
		world.setBlock(x + 8, y + 9, z + 6, Blocks.leaves, 5, 3);
		world.setBlock(x + 9, y + 9, z + 6, Blocks.leaves, 5, 3);
		world.setBlock(x + 10, y + 9, z + 6, Blocks.leaves, 5, 3);
		world.setBlock(x + 11, y + 9, z + 6, Blocks.leaves, 5, 3);
		world.setBlock(x + 12, y + 9, z + 6, Blocks.leaves, 5, 3);
		world.setBlock(x + 13, y + 9, z + 6, Blocks.leaves, 5, 3);
		world.setBlock(x + 14, y + 9, z + 6, Blocks.leaves, 5, 3);
		world.setBlock(x + 15, y + 9, z + 6, Blocks.leaves, 5, 3);
		world.setBlock(x + 16, y + 9, z + 6, Blocks.leaves, 5, 3);
		world.setBlock(x + 17, y + 9, z + 6, Blocks.leaves, 5, 3);
		world.setBlock(x + 18, y + 9, z + 6, Blocks.leaves, 5, 3);
		world.setBlock(x + 19, y + 9, z + 6, Blocks.leaves, 5, 3);
		world.setBlock(x + 20, y + 9, z + 6, Blocks.leaves, 5, 3);
		world.setBlock(x + 21, y + 9, z + 6, Blocks.leaves, 5, 3);
		world.setBlock(x + 22, y + 9, z + 6, Blocks.leaves, 5, 3);
		world.setBlock(x + 23, y + 9, z + 6, Blocks.leaves, 5, 3);
		world.setBlock(x + 24, y + 9, z + 6, Blocks.leaves, 5, 3);
		world.setBlock(x + 25, y + 9, z + 6, Blocks.leaves, 5, 3);
		world.setBlock(x + 26, y + 9, z + 6, Blocks.snow_layer, 0, 3);
		world.setBlock(x + 27, y + 9, z + 6, Blocks.snow_layer, 0, 3);
		world.setBlock(x + 28, y + 9, z + 6, Blocks.snow_layer, 0, 3);
		world.setBlock(x + 2, y + 9, z + 7, Blocks.snow_layer, 0, 3);
		world.setBlock(x + 3, y + 9, z + 7, Blocks.snow_layer, 1, 3);
		world.setBlock(x + 4, y + 9, z + 7, Blocks.snow_layer, 0, 3);
		world.setBlock(x + 5, y + 9, z + 7, Blocks.leaves, 5, 3);
		world.setBlock(x + 6, y + 9, z + 7, Blocks.leaves, 5, 3);
		world.setBlock(x + 7, y + 9, z + 7, Blocks.leaves, 5, 3);
		world.setBlock(x + 8, y + 9, z + 7, Blocks.leaves, 5, 3);
		world.setBlock(x + 9, y + 9, z + 7, Blocks.leaves, 5, 3);
		world.setBlock(x + 10, y + 9, z + 7, Blocks.leaves, 5, 3);
		world.setBlock(x + 11, y + 9, z + 7, Blocks.leaves, 5, 3);
		world.setBlock(x + 12, y + 9, z + 7, Blocks.leaves, 5, 3);
		world.setBlock(x + 13, y + 9, z + 7, Blocks.leaves, 5, 3);
		world.setBlock(x + 14, y + 9, z + 7, Blocks.leaves, 5, 3);
		world.setBlock(x + 15, y + 9, z + 7, Blocks.leaves, 5, 3);
		world.setBlock(x + 16, y + 9, z + 7, Blocks.leaves, 5, 3);
		world.setBlock(x + 17, y + 9, z + 7, Blocks.leaves, 5, 3);
		world.setBlock(x + 18, y + 9, z + 7, Blocks.leaves, 5, 3);
		world.setBlock(x + 19, y + 9, z + 7, Blocks.leaves, 5, 3);
		world.setBlock(x + 20, y + 9, z + 7, Blocks.leaves, 5, 3);
		world.setBlock(x + 21, y + 9, z + 7, Blocks.leaves, 5, 3);
		world.setBlock(x + 22, y + 9, z + 7, Blocks.leaves, 5, 3);
		world.setBlock(x + 23, y + 9, z + 7, Blocks.leaves, 5, 3);
		world.setBlock(x + 24, y + 9, z + 7, Blocks.leaves, 5, 3);
		world.setBlock(x + 25, y + 9, z + 7, Blocks.leaves, 5, 3);
		world.setBlock(x + 26, y + 9, z + 7, Blocks.leaves, 5, 3);
		world.setBlock(x + 27, y + 9, z + 7, Blocks.snow_layer, 0, 3);
		world.setBlock(x + 28, y + 9, z + 7, Blocks.snow_layer, 0, 3);
		world.setBlock(x + 29, y + 9, z + 7, Blocks.snow_layer, 0, 3);
		world.setBlock(x + 2, y + 9, z + 8, Blocks.snow_layer, 0, 3);
		world.setBlock(x + 3, y + 9, z + 8, Blocks.snow_layer, 1, 3);
		world.setBlock(x + 4, y + 9, z + 8, Blocks.leaves, 5, 3);
		world.setBlock(x + 5, y + 9, z + 8, Blocks.leaves, 5, 3);
		world.setBlock(x + 6, y + 9, z + 8, Blocks.leaves, 5, 3);
		world.setBlock(x + 7, y + 9, z + 8, Blocks.leaves, 5, 3);
		world.setBlock(x + 8, y + 9, z + 8, Blocks.leaves, 5, 3);
		world.setBlock(x + 9, y + 9, z + 8, Blocks.leaves, 5, 3);
		world.setBlock(x + 10, y + 9, z + 8, Blocks.leaves, 5, 3);
		world.setBlock(x + 11, y + 9, z + 8, Blocks.leaves, 5, 3);
		world.setBlock(x + 12, y + 9, z + 8, Blocks.leaves, 5, 3);
		world.setBlock(x + 13, y + 9, z + 8, Blocks.leaves, 5, 3);
		world.setBlock(x + 14, y + 9, z + 8, Blocks.leaves, 5, 3);
		world.setBlock(x + 15, y + 9, z + 8, Blocks.leaves, 5, 3);
		world.setBlock(x + 16, y + 9, z + 8, Blocks.leaves, 5, 3);
		world.setBlock(x + 17, y + 9, z + 8, Blocks.leaves, 5, 3);
		world.setBlock(x + 18, y + 9, z + 8, Blocks.leaves, 5, 3);
		world.setBlock(x + 19, y + 9, z + 8, Blocks.leaves, 5, 3);
		world.setBlock(x + 20, y + 9, z + 8, Blocks.leaves, 5, 3);
		world.setBlock(x + 21, y + 9, z + 8, Blocks.leaves, 5, 3);
		world.setBlock(x + 22, y + 9, z + 8, Blocks.leaves, 5, 3);
		world.setBlock(x + 23, y + 9, z + 8, Blocks.leaves, 5, 3);
		world.setBlock(x + 24, y + 9, z + 8, Blocks.leaves, 5, 3);
		world.setBlock(x + 25, y + 9, z + 8, Blocks.leaves, 5, 3);
		world.setBlock(x + 26, y + 9, z + 8, Blocks.leaves, 5, 3);
		world.setBlock(x + 27, y + 9, z + 8, Blocks.leaves, 5, 3);
		world.setBlock(x + 28, y + 9, z + 8, Blocks.wool, 11, 3);
		world.setBlock(x + 29, y + 9, z + 8, Blocks.snow_layer, 0, 3);
		world.setBlock(x + 1, y + 9, z + 9, Blocks.snow_layer, 0, 3);
		world.setBlock(x + 2, y + 9, z + 9, Blocks.snow_layer, 0, 3);
		world.setBlock(x + 3, y + 9, z + 9, Blocks.snow_layer, 0, 3);
		world.setBlock(x + 4, y + 9, z + 9, Blocks.leaves, 5, 3);
		world.setBlock(x + 5, y + 9, z + 9, Blocks.leaves, 5, 3);
		world.setBlock(x + 6, y + 9, z + 9, Blocks.leaves, 5, 3);
		world.setBlock(x + 7, y + 9, z + 9, Blocks.leaves, 5, 3);
		world.setBlock(x + 8, y + 9, z + 9, Blocks.leaves, 5, 3);
		world.setBlock(x + 9, y + 9, z + 9, Blocks.leaves, 5, 3);
		world.setBlock(x + 10, y + 9, z + 9, Blocks.leaves, 5, 3);
		world.setBlock(x + 11, y + 9, z + 9, Blocks.leaves, 5, 3);
		world.setBlock(x + 12, y + 9, z + 9, Blocks.leaves, 5, 3);
		world.setBlock(x + 13, y + 9, z + 9, Blocks.leaves, 5, 3);
		world.setBlock(x + 14, y + 9, z + 9, Blocks.leaves, 5, 3);
		world.setBlock(x + 15, y + 9, z + 9, Blocks.leaves, 5, 3);
		world.setBlock(x + 16, y + 9, z + 9, Blocks.leaves, 5, 3);
		world.setBlock(x + 17, y + 9, z + 9, Blocks.leaves, 5, 3);
		world.setBlock(x + 18, y + 9, z + 9, Blocks.leaves, 5, 3);
		world.setBlock(x + 19, y + 9, z + 9, Blocks.leaves, 5, 3);
		world.setBlock(x + 20, y + 9, z + 9, Blocks.leaves, 5, 3);
		world.setBlock(x + 21, y + 9, z + 9, Blocks.leaves, 5, 3);
		world.setBlock(x + 22, y + 9, z + 9, Blocks.leaves, 5, 3);
		world.setBlock(x + 23, y + 9, z + 9, Blocks.leaves, 5, 3);
		world.setBlock(x + 24, y + 9, z + 9, Blocks.leaves, 5, 3);
		world.setBlock(x + 25, y + 9, z + 9, Blocks.leaves, 5, 3);
		world.setBlock(x + 26, y + 9, z + 9, Blocks.leaves, 5, 3);
		world.setBlock(x + 27, y + 9, z + 9, Blocks.leaves, 5, 3);
		world.setBlock(x + 28, y + 9, z + 9, Blocks.snow_layer, 0, 3);
		world.setBlock(x + 29, y + 9, z + 9, Blocks.snow_layer, 0, 3);
		world.setBlock(x + 30, y + 9, z + 9, Blocks.snow_layer, 0, 3);
		world.setBlock(x + 1, y + 9, z + 10, Blocks.wool, 4, 3);
		world.setBlock(x + 2, y + 9, z + 10, Blocks.snow_layer, 0, 3);
		world.setBlock(x + 3, y + 9, z + 10, Blocks.leaves, 5, 3);
		world.setBlock(x + 4, y + 9, z + 10, Blocks.leaves, 5, 3);
		world.setBlock(x + 5, y + 9, z + 10, Blocks.leaves, 5, 3);
		world.setBlock(x + 6, y + 9, z + 10, Blocks.leaves, 5, 3);
		world.setBlock(x + 7, y + 9, z + 10, Blocks.leaves, 5, 3);
		world.setBlock(x + 8, y + 9, z + 10, Blocks.leaves, 5, 3);
		world.setBlock(x + 9, y + 9, z + 10, Blocks.leaves, 5, 3);
		world.setBlock(x + 10, y + 9, z + 10, Blocks.leaves, 5, 3);
		world.setBlock(x + 11, y + 9, z + 10, Blocks.leaves, 5, 3);
		world.setBlock(x + 12, y + 9, z + 10, Blocks.leaves, 5, 3);
		world.setBlock(x + 13, y + 9, z + 10, Blocks.leaves, 5, 3);
		world.setBlock(x + 14, y + 9, z + 10, Blocks.leaves, 5, 3);
		world.setBlock(x + 15, y + 9, z + 10, Blocks.leaves, 5, 3);
		world.setBlock(x + 16, y + 9, z + 10, Blocks.leaves, 5, 3);
		world.setBlock(x + 17, y + 9, z + 10, Blocks.leaves, 5, 3);
		world.setBlock(x + 18, y + 9, z + 10, Blocks.leaves, 5, 3);
		world.setBlock(x + 19, y + 9, z + 10, Blocks.leaves, 5, 3);
		world.setBlock(x + 20, y + 9, z + 10, Blocks.leaves, 5, 3);
		world.setBlock(x + 21, y + 9, z + 10, Blocks.leaves, 5, 3);
		world.setBlock(x + 22, y + 9, z + 10, Blocks.leaves, 5, 3);
		world.setBlock(x + 23, y + 9, z + 10, Blocks.leaves, 5, 3);
		world.setBlock(x + 24, y + 9, z + 10, Blocks.leaves, 5, 3);

		generate_r02(world, rand, x, y, z);
		return true;

	}
	public boolean generate_r02(World world, Random rand, int x, int y, int z)
	{

		world.setBlock(x + 25, y + 9, z + 10, Blocks.leaves, 5, 3);
		world.setBlock(x + 26, y + 9, z + 10, Blocks.leaves, 5, 3);
		world.setBlock(x + 27, y + 9, z + 10, Blocks.leaves, 5, 3);
		world.setBlock(x + 28, y + 9, z + 10, Blocks.leaves, 5, 3);
		world.setBlock(x + 29, y + 9, z + 10, Blocks.snow_layer, 0, 3);
		world.setBlock(x + 30, y + 9, z + 10, Blocks.wool, 4, 3);
		world.setBlock(x + 1, y + 9, z + 11, Blocks.snow_layer, 0, 3);
		world.setBlock(x + 2, y + 9, z + 11, Blocks.snow_layer, 0, 3);
		world.setBlock(x + 3, y + 9, z + 11, Blocks.leaves, 5, 3);
		world.setBlock(x + 4, y + 9, z + 11, Blocks.leaves, 5, 3);
		world.setBlock(x + 5, y + 9, z + 11, Blocks.leaves, 5, 3);
		world.setBlock(x + 6, y + 9, z + 11, Blocks.leaves, 5, 3);
		world.setBlock(x + 7, y + 9, z + 11, Blocks.leaves, 5, 3);
		world.setBlock(x + 8, y + 9, z + 11, Blocks.leaves, 5, 3);
		world.setBlock(x + 9, y + 9, z + 11, Blocks.leaves, 5, 3);
		world.setBlock(x + 10, y + 9, z + 11, Blocks.leaves, 5, 3);
		world.setBlock(x + 11, y + 9, z + 11, Blocks.leaves, 5, 3);
		world.setBlock(x + 12, y + 9, z + 11, Blocks.leaves, 5, 3);
		world.setBlock(x + 13, y + 9, z + 11, Blocks.leaves, 5, 3);
		world.setBlock(x + 14, y + 9, z + 11, Blocks.leaves, 5, 3);
		world.setBlock(x + 15, y + 9, z + 11, Blocks.leaves, 5, 3);
		world.setBlock(x + 16, y + 9, z + 11, Blocks.leaves, 5, 3);
		world.setBlock(x + 17, y + 9, z + 11, Blocks.leaves, 5, 3);
		world.setBlock(x + 18, y + 9, z + 11, Blocks.leaves, 5, 3);
		world.setBlock(x + 19, y + 9, z + 11, Blocks.leaves, 5, 3);
		world.setBlock(x + 20, y + 9, z + 11, Blocks.leaves, 5, 3);
		world.setBlock(x + 21, y + 9, z + 11, Blocks.leaves, 5, 3);
		world.setBlock(x + 22, y + 9, z + 11, Blocks.leaves, 5, 3);
		world.setBlock(x + 23, y + 9, z + 11, Blocks.leaves, 5, 3);
		world.setBlock(x + 24, y + 9, z + 11, Blocks.leaves, 5, 3);
		world.setBlock(x + 25, y + 9, z + 11, Blocks.leaves, 5, 3);
		world.setBlock(x + 26, y + 9, z + 11, Blocks.leaves, 5, 3);
		world.setBlock(x + 27, y + 9, z + 11, Blocks.leaves, 5, 3);
		world.setBlock(x + 28, y + 9, z + 11, Blocks.leaves, 5, 3);
		world.setBlock(x + 29, y + 9, z + 11, Blocks.snow_layer, 0, 3);
		world.setBlock(x + 30, y + 9, z + 11, Blocks.snow_layer, 0, 3);
		world.setBlock(x + 0, y + 9, z + 12, Blocks.snow_layer, 0, 3);
		world.setBlock(x + 1, y + 9, z + 12, Blocks.snow_layer, 0, 3);
		world.setBlock(x + 2, y + 9, z + 12, Blocks.leaves, 5, 3);
		world.setBlock(x + 3, y + 9, z + 12, Blocks.leaves, 5, 3);
		world.setBlock(x + 4, y + 9, z + 12, Blocks.leaves, 5, 3);
		world.setBlock(x + 5, y + 9, z + 12, Blocks.leaves, 5, 3);
		world.setBlock(x + 6, y + 9, z + 12, Blocks.leaves, 5, 3);
		world.setBlock(x + 7, y + 9, z + 12, Blocks.leaves, 5, 3);
		world.setBlock(x + 8, y + 9, z + 12, Blocks.leaves, 5, 3);
		world.setBlock(x + 9, y + 9, z + 12, Blocks.leaves, 5, 3);
		world.setBlock(x + 10, y + 9, z + 12, Blocks.leaves, 5, 3);
		world.setBlock(x + 11, y + 9, z + 12, Blocks.leaves, 5, 3);
		world.setBlock(x + 12, y + 9, z + 12, Blocks.leaves, 5, 3);
		world.setBlock(x + 13, y + 9, z + 12, Blocks.leaves, 5, 3);
		world.setBlock(x + 14, y + 9, z + 12, Blocks.log, 1, 3);
		world.setBlock(x + 15, y + 9, z + 12, Blocks.log, 1, 3);
		world.setBlock(x + 16, y + 9, z + 12, Blocks.log, 1, 3);
		world.setBlock(x + 17, y + 9, z + 12, Blocks.log, 1, 3);
		world.setBlock(x + 18, y + 9, z + 12, Blocks.leaves, 5, 3);
		world.setBlock(x + 19, y + 9, z + 12, Blocks.leaves, 5, 3);
		world.setBlock(x + 20, y + 9, z + 12, Blocks.leaves, 5, 3);
		world.setBlock(x + 21, y + 9, z + 12, Blocks.leaves, 5, 3);
		world.setBlock(x + 22, y + 9, z + 12, Blocks.leaves, 5, 3);
		world.setBlock(x + 23, y + 9, z + 12, Blocks.leaves, 5, 3);
		world.setBlock(x + 24, y + 9, z + 12, Blocks.leaves, 5, 3);
		world.setBlock(x + 25, y + 9, z + 12, Blocks.leaves, 5, 3);
		world.setBlock(x + 26, y + 9, z + 12, Blocks.leaves, 5, 3);
		world.setBlock(x + 27, y + 9, z + 12, Blocks.leaves, 5, 3);
		world.setBlock(x + 28, y + 9, z + 12, Blocks.leaves, 5, 3);
		world.setBlock(x + 29, y + 9, z + 12, Blocks.leaves, 5, 3);
		world.setBlock(x + 30, y + 9, z + 12, Blocks.snow_layer, 0, 3);
		world.setBlock(x + 31, y + 9, z + 12, Blocks.snow_layer, 0, 3);
		world.setBlock(x + 0, y + 9, z + 13, Blocks.snow_layer, 0, 3);
		world.setBlock(x + 1, y + 9, z + 13, Blocks.snow_layer, 0, 3);
		world.setBlock(x + 2, y + 9, z + 13, Blocks.leaves, 5, 3);
		world.setBlock(x + 3, y + 9, z + 13, Blocks.leaves, 5, 3);
		world.setBlock(x + 4, y + 9, z + 13, Blocks.leaves, 5, 3);
		world.setBlock(x + 5, y + 9, z + 13, Blocks.leaves, 5, 3);
		world.setBlock(x + 6, y + 9, z + 13, Blocks.leaves, 5, 3);
		world.setBlock(x + 7, y + 9, z + 13, Blocks.leaves, 5, 3);
		world.setBlock(x + 8, y + 9, z + 13, Blocks.leaves, 5, 3);
		world.setBlock(x + 9, y + 9, z + 13, Blocks.leaves, 5, 3);
		world.setBlock(x + 10, y + 9, z + 13, Blocks.leaves, 5, 3);
		world.setBlock(x + 11, y + 9, z + 13, Blocks.leaves, 5, 3);
		world.setBlock(x + 12, y + 9, z + 13, Blocks.leaves, 5, 3);
		world.setBlock(x + 13, y + 9, z + 13, Blocks.log, 1, 3);
		world.setBlock(x + 14, y + 9, z + 13, Blocks.log, 1, 3);
		world.setBlock(x + 15, y + 9, z + 13, Blocks.log, 1, 3);
		world.setBlock(x + 16, y + 9, z + 13, Blocks.log, 1, 3);
		world.setBlock(x + 17, y + 9, z + 13, Blocks.log, 1, 3);
		world.setBlock(x + 18, y + 9, z + 13, Blocks.log, 1, 3);
		world.setBlock(x + 19, y + 9, z + 13, Blocks.leaves, 5, 3);
		world.setBlock(x + 20, y + 9, z + 13, Blocks.leaves, 5, 3);
		world.setBlock(x + 21, y + 9, z + 13, Blocks.leaves, 5, 3);
		world.setBlock(x + 22, y + 9, z + 13, Blocks.leaves, 5, 3);
		world.setBlock(x + 23, y + 9, z + 13, Blocks.leaves, 5, 3);
		world.setBlock(x + 24, y + 9, z + 13, Blocks.leaves, 5, 3);
		world.setBlock(x + 25, y + 9, z + 13, Blocks.leaves, 5, 3);
		world.setBlock(x + 26, y + 9, z + 13, Blocks.leaves, 5, 3);
		world.setBlock(x + 27, y + 9, z + 13, Blocks.leaves, 5, 3);
		world.setBlock(x + 28, y + 9, z + 13, Blocks.leaves, 5, 3);
		world.setBlock(x + 29, y + 9, z + 13, Blocks.leaves, 5, 3);
		world.setBlock(x + 30, y + 9, z + 13, Blocks.snow_layer, 0, 3);
		world.setBlock(x + 31, y + 9, z + 13, Blocks.snow_layer, 0, 3);
		world.setBlock(x + 0, y + 9, z + 14, Blocks.snow_layer, 1, 3);
		world.setBlock(x + 1, y + 9, z + 14, Blocks.snow_layer, 0, 3);
		world.setBlock(x + 2, y + 9, z + 14, Blocks.leaves, 5, 3);
		world.setBlock(x + 3, y + 9, z + 14, Blocks.leaves, 5, 3);
		world.setBlock(x + 4, y + 9, z + 14, Blocks.leaves, 5, 3);
		world.setBlock(x + 5, y + 9, z + 14, Blocks.leaves, 5, 3);
		world.setBlock(x + 6, y + 9, z + 14, Blocks.leaves, 5, 3);
		world.setBlock(x + 7, y + 9, z + 14, Blocks.leaves, 5, 3);
		world.setBlock(x + 8, y + 9, z + 14, Blocks.leaves, 5, 3);
		world.setBlock(x + 9, y + 9, z + 14, Blocks.leaves, 5, 3);
		world.setBlock(x + 10, y + 9, z + 14, Blocks.leaves, 5, 3);
		world.setBlock(x + 11, y + 9, z + 14, Blocks.leaves, 5, 3);
		world.setBlock(x + 12, y + 9, z + 14, Blocks.log, 1, 3);
		world.setBlock(x + 13, y + 9, z + 14, Blocks.log, 1, 3);
