package beyondspace.world.generation.structures;

import java.util.Random;

import net.minecraft.init.Blocks;
import net.minecraft.world.World;

public class NewYearSprucePiece
{
	public boolean generate_piece(World world, Random rand, int x, int y, int z)
    {
		world.setBlock(x + 10, y + 29, z + 5, Blocks.leaves, 5, 3);
		world.setBlock(x + 11, y + 29, z + 5, Blocks.leaves, 5, 3);
		world.setBlock(x + 12, y + 29, z + 5, Blocks.leaves, 5, 3);
		world.setBlock(x + 13, y + 29, z + 5, Blocks.leaves, 5, 3);
		world.setBlock(x + 14, y + 29, z + 5, Blocks.leaves, 5, 3);
		world.setBlock(x + 15, y + 29, z + 5, Blocks.leaves, 5, 3);
		world.setBlock(x + 16, y + 29, z + 5, Blocks.leaves, 5, 3);
		world.setBlock(x + 17, y + 29, z + 5, Blocks.leaves, 5, 3);
		world.setBlock(x + 18, y + 29, z + 5, Blocks.leaves, 5, 3);
		world.setBlock(x + 19, y + 29, z + 5, Blocks.leaves, 5, 3);
		world.setBlock(x + 20, y + 29, z + 5, Blocks.leaves, 5, 3);
		world.setBlock(x + 21, y + 29, z + 5, Blocks.leaves, 5, 3);
		world.setBlock(x + 22, y + 29, z + 5, Blocks.leaves, 5, 3);
		world.setBlock(x + 8, y + 29, z + 6, Blocks.leaves, 5, 3);
		world.setBlock(x + 9, y + 29, z + 6, Blocks.leaves, 5, 3);
		world.setBlock(x + 10, y + 29, z + 6, Blocks.leaves, 5, 3);
		world.setBlock(x + 11, y + 29, z + 6, Blocks.leaves, 5, 3);
		world.setBlock(x + 12, y + 29, z + 6, Blocks.leaves, 5, 3);
		world.setBlock(x + 13, y + 29, z + 6, Blocks.leaves, 5, 3);
		world.setBlock(x + 14, y + 29, z + 6, Blocks.leaves, 5, 3);
		world.setBlock(x + 15, y + 29, z + 6, Blocks.leaves, 5, 3);
		world.setBlock(x + 16, y + 29, z + 6, Blocks.leaves, 5, 3);
		world.setBlock(x + 17, y + 29, z + 6, Blocks.leaves, 5, 3);
		world.setBlock(x + 18, y + 29, z + 6, Blocks.leaves, 5, 3);
		world.setBlock(x + 19, y + 29, z + 6, Blocks.leaves, 5, 3);
		world.setBlock(x + 20, y + 29, z + 6, Blocks.leaves, 5, 3);
		world.setBlock(x + 21, y + 29, z + 6, Blocks.leaves, 5, 3);
		world.setBlock(x + 22, y + 29, z + 6, Blocks.leaves, 5, 3);
		world.setBlock(x + 23, y + 29, z + 6, Blocks.leaves, 5, 3);
		world.setBlock(x + 7, y + 29, z + 7, Blocks.leaves, 5, 3);
		world.setBlock(x + 8, y + 29, z + 7, Blocks.leaves, 5, 3);
		world.setBlock(x + 9, y + 29, z + 7, Blocks.leaves, 5, 3);
		world.setBlock(x + 10, y + 29, z + 7, Blocks.leaves, 5, 3);
		world.setBlock(x + 11, y + 29, z + 7, Blocks.leaves, 5, 3);
		world.setBlock(x + 12, y + 29, z + 7, Blocks.leaves, 5, 3);
		world.setBlock(x + 13, y + 29, z + 7, Blocks.leaves, 5, 3);
		world.setBlock(x + 14, y + 29, z + 7, Blocks.leaves, 5, 3);
		world.setBlock(x + 15, y + 29, z + 7, Blocks.leaves, 5, 3);
		world.setBlock(x + 16, y + 29, z + 7, Blocks.leaves, 5, 3);
		world.setBlock(x + 17, y + 29, z + 7, Blocks.leaves, 5, 3);
		world.setBlock(x + 18, y + 29, z + 7, Blocks.leaves, 5, 3);
		world.setBlock(x + 19, y + 29, z + 7, Blocks.leaves, 5, 3);
		world.setBlock(x + 20, y + 29, z + 7, Blocks.leaves, 5, 3);
		world.setBlock(x + 21, y + 29, z + 7, Blocks.leaves, 5, 3);
		world.setBlock(x + 22, y + 29, z + 7, Blocks.leaves, 5, 3);
		world.setBlock(x + 23, y + 29, z + 7, Blocks.leaves, 5, 3);
		world.setBlock(x + 24, y + 29, z + 7, Blocks.leaves, 5, 3);
		world.setBlock(x + 6, y + 29, z + 8, Blocks.leaves, 5, 3);
		world.setBlock(x + 7, y + 29, z + 8, Blocks.leaves, 5, 3);
		world.setBlock(x + 8, y + 29, z + 8, Blocks.leaves, 5, 3);
		world.setBlock(x + 9, y + 29, z + 8, Blocks.leaves, 5, 3);
		world.setBlock(x + 10, y + 29, z + 8, Blocks.leaves, 5, 3);
		world.setBlock(x + 11, y + 29, z + 8, Blocks.leaves, 5, 3);
		world.setBlock(x + 12, y + 29, z + 8, Blocks.leaves, 5, 3);
		world.setBlock(x + 13, y + 29, z + 8, Blocks.leaves, 5, 3);
		world.setBlock(x + 14, y + 29, z + 8, Blocks.leaves, 5, 3);
		world.setBlock(x + 15, y + 29, z + 8, Blocks.leaves, 5, 3);
		world.setBlock(x + 16, y + 29, z + 8, Blocks.leaves, 5, 3);
		world.setBlock(x + 17, y + 29, z + 8, Blocks.leaves, 5, 3);
		world.setBlock(x + 18, y + 29, z + 8, Blocks.leaves, 5, 3);
		world.setBlock(x + 19, y + 29, z + 8, Blocks.leaves, 5, 3);
		world.setBlock(x + 20, y + 29, z + 8, Blocks.leaves, 5, 3);
		world.setBlock(x + 21, y + 29, z + 8, Blocks.leaves, 5, 3);
		world.setBlock(x + 22, y + 29, z + 8, Blocks.leaves, 5, 3);
		world.setBlock(x + 23, y + 29, z + 8, Blocks.leaves, 5, 3);
		world.setBlock(x + 24, y + 29, z + 8, Blocks.leaves, 5, 3);
		world.setBlock(x + 25, y + 29, z + 8, Blocks.leaves, 5, 3);
		world.setBlock(x + 5, y + 29, z + 9, Blocks.leaves, 5, 3);
		world.setBlock(x + 6, y + 29, z + 9, Blocks.leaves, 5, 3);
		world.setBlock(x + 7, y + 29, z + 9, Blocks.leaves, 5, 3);
		world.setBlock(x + 8, y + 29, z + 9, Blocks.leaves, 5, 3);
		world.setBlock(x + 9, y + 29, z + 9, Blocks.leaves, 5, 3);
		world.setBlock(x + 10, y + 29, z + 9, Blocks.leaves, 5, 3);
		world.setBlock(x + 11, y + 29, z + 9, Blocks.leaves, 5, 3);
		world.setBlock(x + 12, y + 29, z + 9, Blocks.leaves, 5, 3);
		world.setBlock(x + 13, y + 29, z + 9, Blocks.leaves, 5, 3);
		world.setBlock(x + 14, y + 29, z + 9, Blocks.leaves, 5, 3);
		world.setBlock(x + 15, y + 29, z + 9, Blocks.leaves, 5, 3);
		world.setBlock(x + 16, y + 29, z + 9, Blocks.leaves, 5, 3);
		world.setBlock(x + 17, y + 29, z + 9, Blocks.leaves, 5, 3);
		world.setBlock(x + 18, y + 29, z + 9, Blocks.leaves, 5, 3);
		world.setBlock(x + 19, y + 29, z + 9, Blocks.leaves, 5, 3);
		world.setBlock(x + 20, y + 29, z + 9, Blocks.leaves, 5, 3);
		world.setBlock(x + 21, y + 29, z + 9, Blocks.leaves, 5, 3);
		world.setBlock(x + 22, y + 29, z + 9, Blocks.leaves, 5, 3);
		world.setBlock(x + 23, y + 29, z + 9, Blocks.leaves, 5, 3);
		world.setBlock(x + 24, y + 29, z + 9, Blocks.leaves, 5, 3);
		world.setBlock(x + 25, y + 29, z + 9, Blocks.leaves, 5, 3);
		world.setBlock(x + 26, y + 29, z + 9, Blocks.leaves, 5, 3);
		world.setBlock(x + 4, y + 29, z + 10, Blocks.leaves, 5, 3);
		world.setBlock(x + 5, y + 29, z + 10, Blocks.leaves, 5, 3);
		world.setBlock(x + 6, y + 29, z + 10, Blocks.leaves, 5, 3);
		world.setBlock(x + 7, y + 29, z + 10, Blocks.leaves, 5, 3);
		world.setBlock(x + 8, y + 29, z + 10, Blocks.leaves, 5, 3);
		world.setBlock(x + 9, y + 29, z + 10, Blocks.leaves, 5, 3);
		world.setBlock(x + 10, y + 29, z + 10, Blocks.leaves, 5, 3);
		world.setBlock(x + 11, y + 29, z + 10, Blocks.leaves, 5, 3);
		world.setBlock(x + 12, y + 29, z + 10, Blocks.leaves, 5, 3);
		world.setBlock(x + 13, y + 29, z + 10, Blocks.leaves, 5, 3);
		world.setBlock(x + 14, y + 29, z + 10, Blocks.leaves, 5, 3);
		world.setBlock(x + 15, y + 29, z + 10, Blocks.leaves, 5, 3);
		world.setBlock(x + 16, y + 29, z + 10, Blocks.leaves, 5, 3);
		world.setBlock(x + 17, y + 29, z + 10, Blocks.leaves, 5, 3);
		world.setBlock(x + 18, y + 29, z + 10, Blocks.leaves, 5, 3);
		world.setBlock(x + 19, y + 29, z + 10, Blocks.leaves, 5, 3);
		world.setBlock(x + 20, y + 29, z + 10, Blocks.leaves, 5, 3);
		world.setBlock(x + 21, y + 29, z + 10, Blocks.leaves, 5, 3);
		world.setBlock(x + 22, y + 29, z + 10, Blocks.leaves, 5, 3);
		world.setBlock(x + 23, y + 29, z + 10, Blocks.leaves, 5, 3);
		world.setBlock(x + 24, y + 29, z + 10, Blocks.leaves, 5, 3);
		world.setBlock(x + 25, y + 29, z + 10, Blocks.leaves, 5, 3);
		world.setBlock(x + 26, y + 29, z + 10, Blocks.leaves, 5, 3);
		world.setBlock(x + 27, y + 29, z + 10, Blocks.leaves, 5, 3);
		world.setBlock(x + 4, y + 29, z + 11, Blocks.leaves, 5, 3);
		world.setBlock(x + 5, y + 29, z + 11, Blocks.leaves, 5, 3);
		world.setBlock(x + 6, y + 29, z + 11, Blocks.leaves, 5, 3);
		world.setBlock(x + 7, y + 29, z + 11, Blocks.leaves, 5, 3);
		world.setBlock(x + 8, y + 29, z + 11, Blocks.leaves, 5, 3);
		world.setBlock(x + 9, y + 29, z + 11, Blocks.leaves, 5, 3);
		world.setBlock(x + 10, y + 29, z + 11, Blocks.leaves, 5, 3);
		world.setBlock(x + 11, y + 29, z + 11, Blocks.leaves, 5, 3);
		world.setBlock(x + 12, y + 29, z + 11, Blocks.leaves, 5, 3);
		world.setBlock(x + 13, y + 29, z + 11, Blocks.leaves, 5, 3);
		world.setBlock(x + 14, y + 29, z + 11, Blocks.leaves, 5, 3);
		world.setBlock(x + 15, y + 29, z + 11, Blocks.leaves, 5, 3);
		world.setBlock(x + 16, y + 29, z + 11, Blocks.leaves, 5, 3);
		world.setBlock(x + 17, y + 29, z + 11, Blocks.leaves, 5, 3);
		world.setBlock(x + 18, y + 29, z + 11, Blocks.leaves, 5, 3);
		world.setBlock(x + 19, y + 29, z + 11, Blocks.leaves, 5, 3);
		world.setBlock(x + 20, y + 29, z + 11, Blocks.leaves, 5, 3);
		world.setBlock(x + 21, y + 29, z + 11, Blocks.leaves, 5, 3);
		world.setBlock(x + 22, y + 29, z + 11, Blocks.leaves, 5, 3);
		world.setBlock(x + 23, y + 29, z + 11, Blocks.leaves, 5, 3);
		world.setBlock(x + 24, y + 29, z + 11, Blocks.leaves, 5, 3);
		world.setBlock(x + 25, y + 29, z + 11, Blocks.leaves, 5, 3);
		world.setBlock(x + 26, y + 29, z + 11, Blocks.leaves, 5, 3);
		world.setBlock(x + 27, y + 29, z + 11, Blocks.leaves, 5, 3);
		world.setBlock(x + 4, y + 29, z + 12, Blocks.leaves, 5, 3);
		world.setBlock(x + 5, y + 29, z + 12, Blocks.leaves, 5, 3);
		world.setBlock(x + 6, y + 29, z + 12, Blocks.leaves, 5, 3);
		world.setBlock(x + 7, y + 29, z + 12, Blocks.leaves, 5, 3);
		world.setBlock(x + 8, y + 29, z + 12, Blocks.leaves, 5, 3);
		world.setBlock(x + 9, y + 29, z + 12, Blocks.leaves, 5, 3);
		world.setBlock(x + 10, y + 29, z + 12, Blocks.leaves, 5, 3);
		world.setBlock(x + 11, y + 29, z + 12, Blocks.leaves, 5, 3);
		world.setBlock(x + 12, y + 29, z + 12, Blocks.leaves, 5, 3);
		world.setBlock(x + 13, y + 29, z + 12, Blocks.leaves, 5, 3);
		world.setBlock(x + 14, y + 29, z + 12, Blocks.log, 1, 3);
		world.setBlock(x + 15, y + 29, z + 12, Blocks.log, 1, 3);
		world.setBlock(x + 16, y + 29, z + 12, Blocks.log, 1, 3);
		world.setBlock(x + 17, y + 29, z + 12, Blocks.log, 1, 3);
		world.setBlock(x + 18, y + 29, z + 12, Blocks.leaves, 5, 3);
		world.setBlock(x + 19, y + 29, z + 12, Blocks.leaves, 5, 3);
		world.setBlock(x + 20, y + 29, z + 12, Blocks.leaves, 5, 3);
		world.setBlock(x + 21, y + 29, z + 12, Blocks.leaves, 5, 3);
		world.setBlock(x + 22, y + 29, z + 12, Blocks.leaves, 5, 3);
		world.setBlock(x + 23, y + 29, z + 12, Blocks.leaves, 5, 3);
		world.setBlock(x + 24, y + 29, z + 12, Blocks.leaves, 5, 3);
		world.setBlock(x + 25, y + 29, z + 12, Blocks.leaves, 5, 3);
		world.setBlock(x + 26, y + 29, z + 12, Blocks.leaves, 5, 3);
		world.setBlock(x + 27, y + 29, z + 12, Blocks.leaves, 5, 3);
		world.setBlock(x + 3, y + 29, z + 13, Blocks.leaves, 5, 3);
		world.setBlock(x + 4, y + 29, z + 13, Blocks.leaves, 5, 3);
		world.setBlock(x + 5, y + 29, z + 13, Blocks.leaves, 5, 3);
		world.setBlock(x + 6, y + 29, z + 13, Blocks.leaves, 5, 3);
		world.setBlock(x + 7, y + 29, z + 13, Blocks.leaves, 5, 3);
		world.setBlock(x + 8, y + 29, z + 13, Blocks.leaves, 5, 3);
		world.setBlock(x + 9, y + 29, z + 13, Blocks.leaves, 5, 3);
		world.setBlock(x + 10, y + 29, z + 13, Blocks.leaves, 5, 3);
		world.setBlock(x + 11, y + 29, z + 13, Blocks.leaves, 5, 3);
		world.setBlock(x + 12, y + 29, z + 13, Blocks.leaves, 5, 3);
		world.setBlock(x + 13, y + 29, z + 13, Blocks.log, 1, 3);
		world.setBlock(x + 14, y + 29, z + 13, Blocks.log, 1, 3);
		world.setBlock(x + 15, y + 29, z + 13, Blocks.log, 1, 3);
		world.setBlock(x + 16, y + 29, z + 13, Blocks.log, 1, 3);
		world.setBlock(x + 17, y + 29, z + 13, Blocks.log, 1, 3);
		world.setBlock(x + 18, y + 29, z + 13, Blocks.log, 1, 3);
		world.setBlock(x + 19, y + 29, z + 13, Blocks.leaves, 5, 3);
		world.setBlock(x + 20, y + 29, z + 13, Blocks.leaves, 5, 3);
		world.setBlock(x + 21, y + 29, z + 13, Blocks.leaves, 5, 3);
		world.setBlock(x + 22, y + 29, z + 13, Blocks.leaves, 5, 3);
		world.setBlock(x + 23, y + 29, z + 13, Blocks.leaves, 5, 3);
		world.setBlock(x + 24, y + 29, z + 13, Blocks.leaves, 5, 3);
		world.setBlock(x + 25, y + 29, z + 13, Blocks.leaves, 5, 3);
		world.setBlock(x + 26, y + 29, z + 13, Blocks.leaves, 5, 3);
		world.setBlock(x + 27, y + 29, z + 13, Blocks.leaves, 5, 3);
		world.setBlock(x + 28, y + 29, z + 13, Blocks.leaves, 5, 3);
		world.setBlock(x + 3, y + 29, z + 14, Blocks.leaves, 5, 3);
		world.setBlock(x + 4, y + 29, z + 14, Blocks.leaves, 5, 3);
		world.setBlock(x + 5, y + 29, z + 14, Blocks.leaves, 5, 3);
		world.setBlock(x + 6, y + 29, z + 14, Blocks.leaves, 5, 3);
		world.setBlock(x + 7, y + 29, z + 14, Blocks.leaves, 5, 3);
		world.setBlock(x + 8, y + 29, z + 14, Blocks.leaves, 5, 3);
		world.setBlock(x + 9, y + 29, z + 14, Blocks.leaves, 5, 3);
		world.setBlock(x + 10, y + 29, z + 14, Blocks.leaves, 5, 3);
		world.setBlock(x + 11, y + 29, z + 14, Blocks.leaves, 5, 3);
		world.setBlock(x + 12, y + 29, z + 14, Blocks.log, 1, 3);
		world.setBlock(x + 13, y + 29, z + 14, Blocks.log, 1, 3);
		world.setBlock(x + 14, y + 29, z + 14, Blocks.log, 1, 3);
		world.setBlock(x + 15, y + 29, z + 14, Blocks.log, 1, 3);
		world.setBlock(x + 16, y + 29, z + 14, Blocks.log, 1, 3);
		world.setBlock(x + 17, y + 29, z + 14, Blocks.log, 1, 3);
		world.setBlock(x + 18, y + 29, z + 14, Blocks.log, 1, 3);
		world.setBlock(x + 19, y + 29, z + 14, Blocks.log, 1, 3);
		world.setBlock(x + 20, y + 29, z + 14, Blocks.leaves, 5, 3);
		world.setBlock(x + 21, y + 29, z + 14, Blocks.leaves, 5, 3);
		world.setBlock(x + 22, y + 29, z + 14, Blocks.leaves, 5, 3);
		world.setBlock(x + 23, y + 29, z + 14, Blocks.leaves, 5, 3);
		world.setBlock(x + 24, y + 29, z + 14, Blocks.leaves, 5, 3);
		world.setBlock(x + 25, y + 29, z + 14, Blocks.leaves, 5, 3);
		world.setBlock(x + 26, y + 29, z + 14, Blocks.leaves, 5, 3);
		world.setBlock(x + 27, y + 29, z + 14, Blocks.leaves, 5, 3);
		world.setBlock(x + 28, y + 29, z + 14, Blocks.leaves, 5, 3);
		world.setBlock(x + 3, y + 29, z + 15, Blocks.leaves, 5, 3);
		world.setBlock(x + 4, y + 29, z + 15, Blocks.leaves, 5, 3);
		world.setBlock(x + 5, y + 29, z + 15, Blocks.leaves, 5, 3);
		world.setBlock(x + 6, y + 29, z + 15, Blocks.leaves, 5, 3);
		world.setBlock(x + 7, y + 29, z + 15, Blocks.leaves, 5, 3);
		world.setBlock(x + 8, y + 29, z + 15, Blocks.leaves, 5, 3);
		world.setBlock(x + 9, y + 29, z + 15, Blocks.leaves, 5, 3);
		world.setBlock(x + 10, y + 29, z + 15, Blocks.leaves, 5, 3);
		world.setBlock(x + 11, y + 29, z + 15, Blocks.leaves, 5, 3);
		world.setBlock(x + 12, y + 29, z + 15, Blocks.log, 1, 3);
		world.setBlock(x + 13, y + 29, z + 15, Blocks.log, 1, 3);
		world.setBlock(x + 14, y + 29, z + 15, Blocks.log, 1, 3);
		world.setBlock(x + 15, y + 29, z + 15, Blocks.log, 1, 3);
		world.setBlock(x + 16, y + 29, z + 15, Blocks.log, 1, 3);
		world.setBlock(x + 17, y + 29, z + 15, Blocks.log, 1, 3);
		world.setBlock(x + 18, y + 29, z + 15, Blocks.log, 1, 3);
		world.setBlock(x + 19, y + 29, z + 15, Blocks.log, 1, 3);
		world.setBlock(x + 20, y + 29, z + 15, Blocks.leaves, 5, 3);
		world.setBlock(x + 21, y + 29, z + 15, Blocks.leaves, 5, 3);
		world.setBlock(x + 22, y + 29, z + 15, Blocks.leaves, 5, 3);
		world.setBlock(x + 23, y + 29, z + 15, Blocks.leaves, 5, 3);
		world.setBlock(x + 24, y + 29, z + 15, Blocks.leaves, 5, 3);
		world.setBlock(x + 25, y + 29, z + 15, Blocks.leaves, 5, 3);
		world.setBlock(x + 26, y + 29, z + 15, Blocks.leaves, 5, 3);
		world.setBlock(x + 27, y + 29, z + 15, Blocks.leaves, 5, 3);
		world.setBlock(x + 28, y + 29, z + 15, Blocks.leaves, 5, 3);
		world.setBlock(x + 3, y + 29, z + 16, Blocks.leaves, 5, 3);
		world.setBlock(x + 4, y + 29, z + 16, Blocks.leaves, 5, 3);
		world.setBlock(x + 5, y + 29, z + 16, Blocks.leaves, 5, 3);
		world.setBlock(x + 6, y + 29, z + 16, Blocks.leaves, 5, 3);
		world.setBlock(x + 7, y + 29, z + 16, Blocks.leaves, 5, 3);
		world.setBlock(x + 8, y + 29, z + 16, Blocks.leaves, 5, 3);
		world.setBlock(x + 9, y + 29, z + 16, Blocks.leaves, 5, 3);
		world.setBlock(x + 10, y + 29, z + 16, Blocks.leaves, 5, 3);
		world.setBlock(x + 11, y + 29, z + 16, Blocks.leaves, 5, 3);
		world.setBlock(x + 12, y + 29, z + 16, Blocks.log, 1, 3);
		world.setBlock(x + 13, y + 29, z + 16, Blocks.log, 1, 3);
		world.setBlock(x + 14, y + 29, z + 16, Blocks.log, 1, 3);
		world.setBlock(x + 15, y + 29, z + 16, Blocks.log, 1, 3);
		world.setBlock(x + 16, y + 29, z + 16, Blocks.log, 1, 3);
		world.setBlock(x + 17, y + 29, z + 16, Blocks.log, 1, 3);
		world.setBlock(x + 18, y + 29, z + 16, Blocks.log, 1, 3);
		world.setBlock(x + 19, y + 29, z + 16, Blocks.log, 1, 3);
		world.setBlock(x + 20, y + 29, z + 16, Blocks.leaves, 5, 3);
		world.setBlock(x + 21, y + 29, z + 16, Blocks.leaves, 5, 3);
		world.setBlock(x + 22, y + 29, z + 16, Blocks.leaves, 5, 3);
		world.setBlock(x + 23, y + 29, z + 16, Blocks.leaves, 5, 3);
		world.setBlock(x + 24, y + 29, z + 16, Blocks.leaves, 5, 3);
		world.setBlock(x + 25, y + 29, z + 16, Blocks.leaves, 5, 3);
		world.setBlock(x + 26, y + 29, z + 16, Blocks.leaves, 5, 3);
		world.setBlock(x + 27, y + 29, z + 16, Blocks.leaves, 5, 3);
		world.setBlock(x + 28, y + 29, z + 16, Blocks.leaves, 5, 3);
		world.setBlock(x + 3, y + 29, z + 17, Blocks.leaves, 5, 3);
		world.setBlock(x + 4, y + 29, z + 17, Blocks.leaves, 5, 3);
		world.setBlock(x + 5, y + 29, z + 17, Blocks.leaves, 5, 3);
		world.setBlock(x + 6, y + 29, z + 17, Blocks.leaves, 5, 3);
		world.setBlock(x + 7, y + 29, z + 17, Blocks.leaves, 5, 3);
		world.setBlock(x + 8, y + 29, z + 17, Blocks.leaves, 5, 3);
		world.setBlock(x + 9, y + 29, z + 17, Blocks.leaves, 5, 3);
		world.setBlock(x + 10, y + 29, z + 17, Blocks.leaves, 5, 3);
		world.setBlock(x + 11, y + 29, z + 17, Blocks.leaves, 5, 3);
		world.setBlock(x + 12, y + 29, z + 17, Blocks.log, 1, 3);
		world.setBlock(x + 13, y + 29, z + 17, Blocks.log, 1, 3);
		world.setBlock(x + 14, y + 29, z + 17, Blocks.log, 1, 3);
		world.setBlock(x + 15, y + 29, z + 17, Blocks.log, 1, 3);
		world.setBlock(x + 16, y + 29, z + 17, Blocks.log, 1, 3);
		world.setBlock(x + 17, y + 29, z + 17, Blocks.log, 1, 3);
		world.setBlock(x + 18, y + 29, z + 17, Blocks.log, 1, 3);
		world.setBlock(x + 19, y + 29, z + 17, Blocks.log, 1, 3);
		world.setBlock(x + 20, y + 29, z + 17, Blocks.leaves, 5, 3);
		world.setBlock(x + 21, y + 29, z + 17, Blocks.leaves, 5, 3);
		world.setBlock(x + 22, y + 29, z + 17, Blocks.leaves, 5, 3);
		world.setBlock(x + 23, y + 29, z + 17, Blocks.leaves, 5, 3);
		world.setBlock(x + 24, y + 29, z + 17, Blocks.leaves, 5, 3);
		world.setBlock(x + 25, y + 29, z + 17, Blocks.leaves, 5, 3);
		world.setBlock(x + 26, y + 29, z + 17, Blocks.leaves, 5, 3);
		world.setBlock(x + 27, y + 29, z + 17, Blocks.leaves, 5, 3);
		world.setBlock(x + 28, y + 29, z + 17, Blocks.leaves, 5, 3);
		world.setBlock(x + 3, y + 29, z + 18, Blocks.leaves, 5, 3);
		world.setBlock(x + 4, y + 29, z + 18, Blocks.leaves, 5, 3);
		world.setBlock(x + 5, y + 29, z + 18, Blocks.leaves, 5, 3);
		world.setBlock(x + 6, y + 29, z + 18, Blocks.leaves, 5, 3);
		world.setBlock(x + 7, y + 29, z + 18, Blocks.leaves, 5, 3);
		world.setBlock(x + 8, y + 29, z + 18, Blocks.leaves, 5, 3);
		world.setBlock(x + 9, y + 29, z + 18, Blocks.leaves, 5, 3);
		world.setBlock(x + 10, y + 29, z + 18, Blocks.leaves, 5, 3);
		world.setBlock(x + 11, y + 29, z + 18, Blocks.leaves, 5, 3);
		world.setBlock(x + 12, y + 29, z + 18, Blocks.leaves, 5, 3);
		world.setBlock(x + 13, y + 29, z + 18, Blocks.log, 1, 3);
		world.setBlock(x + 14, y + 29, z + 18, Blocks.log, 1, 3);
		world.setBlock(x + 15, y + 29, z + 18, Blocks.log, 1, 3);
		world.setBlock(x + 16, y + 29, z + 18, Blocks.log, 1, 3);
		world.setBlock(x + 17, y + 29, z + 18, Blocks.log, 1, 3);
		world.setBlock(x + 18, y + 29, z + 18, Blocks.log, 1, 3);
		world.setBlock(x + 19, y + 29, z + 18, Blocks.leaves, 5, 3);
		world.setBlock(x + 20, y + 29, z + 18, Blocks.leaves, 5, 3);
		world.setBlock(x + 21, y + 29, z + 18, Blocks.leaves, 5, 3);
		world.setBlock(x + 22, y + 29, z + 18, Blocks.leaves, 5, 3);
		world.setBlock(x + 23, y + 29, z + 18, Blocks.leaves, 5, 3);
		world.setBlock(x + 24, y + 29, z + 18, Blocks.leaves, 5, 3);
		world.setBlock(x + 25, y + 29, z + 18, Blocks.leaves, 5, 3);
		world.setBlock(x + 26, y + 29, z + 18, Blocks.leaves, 5, 3);
		world.setBlock(x + 27, y + 29, z + 18, Blocks.leaves, 5, 3);
		world.setBlock(x + 28, y + 29, z + 18, Blocks.leaves, 5, 3);
		world.setBlock(x + 4, y + 29, z + 19, Blocks.leaves, 5, 3);
		world.setBlock(x + 5, y + 29, z + 19, Blocks.leaves, 5, 3);
		world.setBlock(x + 6, y + 29, z + 19, Blocks.leaves, 5, 3);
		world.setBlock(x + 7, y + 29, z + 19, Blocks.leaves, 5, 3);
		world.setBlock(x + 8, y + 29, z + 19, Blocks.leaves, 5, 3);
		world.setBlock(x + 9, y + 29, z + 19, Blocks.leaves, 5, 3);
		world.setBlock(x + 10, y + 29, z + 19, Blocks.leaves, 5, 3);
		world.setBlock(x + 11, y + 29, z + 19, Blocks.leaves, 5, 3);
		world.setBlock(x + 12, y + 29, z + 19, Blocks.leaves, 5, 3);
		world.setBlock(x + 13, y + 29, z + 19, Blocks.leaves, 5, 3);
		world.setBlock(x + 14, y + 29, z + 19, Blocks.log, 1, 3);
		world.setBlock(x + 15, y + 29, z + 19, Blocks.log, 1, 3);
		world.setBlock(x + 16, y + 29, z + 19, Blocks.log, 1, 3);
		world.setBlock(x + 17, y + 29, z + 19, Blocks.log, 1, 3);
		world.setBlock(x + 18, y + 29, z + 19, Blocks.leaves, 5, 3);
		world.setBlock(x + 19, y + 29, z + 19, Blocks.leaves, 5, 3);
		world.setBlock(x + 20, y + 29, z + 19, Blocks.leaves, 5, 3);
		world.setBlock(x + 21, y + 29, z + 19, Blocks.leaves, 5, 3);
		world.setBlock(x + 22, y + 29, z + 19, Blocks.leaves, 5, 3);
		world.setBlock(x + 23, y + 29, z + 19, Blocks.leaves, 5, 3);
		world.setBlock(x + 24, y + 29, z + 19, Blocks.leaves, 5, 3);
		world.setBlock(x + 25, y + 29, z + 19, Blocks.leaves, 5, 3);
		world.setBlock(x + 26, y + 29, z + 19, Blocks.leaves, 5, 3);
		world.setBlock(x + 27, y + 29, z + 19, Blocks.leaves, 5, 3);
		world.setBlock(x + 4, y + 29, z + 20, Blocks.leaves, 5, 3);
		world.setBlock(x + 5, y + 29, z + 20, Blocks.leaves, 5, 3);
		world.setBlock(x + 6, y + 29, z + 20, Blocks.leaves, 5, 3);
		world.setBlock(x + 7, y + 29, z + 20, Blocks.leaves, 5, 3);
		world.setBlock(x + 8, y + 29, z + 20, Blocks.leaves, 5, 3);
		world.setBlock(x + 9, y + 29, z + 20, Blocks.leaves, 5, 3);
		world.setBlock(x + 10, y + 29, z + 20, Blocks.leaves, 5, 3);
		world.setBlock(x + 11, y + 29, z + 20, Blocks.leaves, 5, 3);
		world.setBlock(x + 12, y + 29, z + 20, Blocks.leaves, 5, 3);
		world.setBlock(x + 13, y + 29, z + 20, Blocks.leaves, 5, 3);
		world.setBlock(x + 14, y + 29, z + 20, Blocks.leaves, 5, 3);
		world.setBlock(x + 15, y + 29, z + 20, Blocks.leaves, 5, 3);
		world.setBlock(x + 16, y + 29, z + 20, Blocks.leaves, 5, 3);
		world.setBlock(x + 17, y + 29, z + 20, Blocks.leaves, 5, 3);
		world.setBlock(x + 18, y + 29, z + 20, Blocks.leaves, 5, 3);
		world.setBlock(x + 19, y + 29, z + 20, Blocks.leaves, 5, 3);
		world.setBlock(x + 20, y + 29, z + 20, Blocks.leaves, 5, 3);
		world.setBlock(x + 21, y + 29, z + 20, Blocks.leaves, 5, 3);
		world.setBlock(x + 22, y + 29, z + 20, Blocks.leaves, 5, 3);
		world.setBlock(x + 23, y + 29, z + 20, Blocks.leaves, 5, 3);
		world.setBlock(x + 24, y + 29, z + 20, Blocks.leaves, 5, 3);
		world.setBlock(x + 25, y + 29, z + 20, Blocks.leaves, 5, 3);
		world.setBlock(x + 26, y + 29, z + 20, Blocks.leaves, 5, 3);
		world.setBlock(x + 27, y + 29, z + 20, Blocks.leaves, 5, 3);
		world.setBlock(x + 4, y + 29, z + 21, Blocks.leaves, 5, 3);
		world.setBlock(x + 5, y + 29, z + 21, Blocks.leaves, 5, 3);
		world.setBlock(x + 6, y + 29, z + 21, Blocks.leaves, 5, 3);
		world.setBlock(x + 7, y + 29, z + 21, Blocks.leaves, 5, 3);
		world.setBlock(x + 8, y + 29, z + 21, Blocks.leaves, 5, 3);
		world.setBlock(x + 9, y + 29, z + 21, Blocks.leaves, 5, 3);
		world.setBlock(x + 10, y + 29, z + 21, Blocks.leaves, 5, 3);
		world.setBlock(x + 11, y + 29, z + 21, Blocks.leaves, 5, 3);
		world.setBlock(x + 12, y + 29, z + 21, Blocks.leaves, 5, 3);
		world.setBlock(x + 13, y + 29, z + 21, Blocks.leaves, 5, 3);
		world.setBlock(x + 14, y + 29, z + 21, Blocks.leaves, 5, 3);
		world.setBlock(x + 15, y + 29, z + 21, Blocks.leaves, 5, 3);
		world.setBlock(x + 16, y + 29, z + 21, Blocks.leaves, 5, 3);
		world.setBlock(x + 17, y + 29, z + 21, Blocks.leaves, 5, 3);
		world.setBlock(x + 18, y + 29, z + 21, Blocks.leaves, 5, 3);
		world.setBlock(x + 19, y + 29, z + 21, Blocks.leaves, 5, 3);
		world.setBlock(x + 20, y + 29, z + 21, Blocks.leaves, 5, 3);
		world.setBlock(x + 21, y + 29, z + 21, Blocks.leaves, 5, 3);
		world.setBlock(x + 22, y + 29, z + 21, Blocks.leaves, 5, 3);
		world.setBlock(x + 23, y + 29, z + 21, Blocks.leaves, 5, 3);
		world.setBlock(x + 24, y + 29, z + 21, Blocks.leaves, 5, 3);
		world.setBlock(x + 25, y + 29, z + 21, Blocks.leaves, 5, 3);
		world.setBlock(x + 26, y + 29, z + 21, Blocks.leaves, 5, 3);
		world.setBlock(x + 27, y + 29, z + 21, Blocks.leaves, 5, 3);
		world.setBlock(x + 5, y + 29, z + 22, Blocks.leaves, 5, 3);
		world.setBlock(x + 6, y + 29, z + 22, Blocks.leaves, 5, 3);
		world.setBlock(x + 7, y + 29, z + 22, Blocks.leaves, 5, 3);
		world.setBlock(x + 8, y + 29, z + 22, Blocks.leaves, 5, 3);
		world.setBlock(x + 9, y + 29, z + 22, Blocks.leaves, 5, 3);
		world.setBlock(x + 10, y + 29, z + 22, Blocks.leaves, 5, 3);
		world.setBlock(x + 11, y + 29, z + 22, Blocks.leaves, 5, 3);
		world.setBlock(x + 12, y + 29, z + 22, Blocks.leaves, 5, 3);
		world.setBlock(x + 13, y + 29, z + 22, Blocks.leaves, 5, 3);
		world.setBlock(x + 14, y + 29, z + 22, Blocks.leaves, 5, 3);
		world.setBlock(x + 15, y + 29, z + 22, Blocks.leaves, 5, 3);
		world.setBlock(x + 16, y + 29, z + 22, Blocks.leaves, 5, 3);
		world.setBlock(x + 17, y + 29, z + 22, Blocks.leaves, 5, 3);
		world.setBlock(x + 18, y + 29, z + 22, Blocks.leaves, 5, 3);
		world.setBlock(x + 19, y + 29, z + 22, Blocks.leaves, 5, 3);
		world.setBlock(x + 20, y + 29, z + 22, Blocks.leaves, 5, 3);
		world.setBlock(x + 21, y + 29, z + 22, Blocks.leaves, 5, 3);
		world.setBlock(x + 22, y + 29, z + 22, Blocks.leaves, 5, 3);
		world.setBlock(x + 23, y + 29, z + 22, Blocks.leaves, 5, 3);
		world.setBlock(x + 24, y + 29, z + 22, Blocks.leaves, 5, 3);
		world.setBlock(x + 25, y + 29, z + 22, Blocks.leaves, 5, 3);
		world.setBlock(x + 26, y + 29, z + 22, Blocks.leaves, 5, 3);
		world.setBlock(x + 6, y + 29, z + 23, Blocks.leaves, 5, 3);
		world.setBlock(x + 7, y + 29, z + 23, Blocks.leaves, 5, 3);
		world.setBlock(x + 8, y + 29, z + 23, Blocks.leaves, 5, 3);
		world.setBlock(x + 9, y + 29, z + 23, Blocks.leaves, 5, 3);
		world.setBlock(x + 10, y + 29, z + 23, Blocks.leaves, 5, 3);
		world.setBlock(x + 11, y + 29, z + 23, Blocks.leaves, 5, 3);
		world.setBlock(x + 12, y + 29, z + 23, Blocks.leaves, 5, 3);
		world.setBlock(x + 13, y + 29, z + 23, Blocks.leaves, 5, 3);
		world.setBlock(x + 14, y + 29, z + 23, Blocks.leaves, 5, 3);
		world.setBlock(x + 15, y + 29, z + 23, Blocks.leaves, 5, 3);
		world.setBlock(x + 16, y + 29, z + 23, Blocks.leaves, 5, 3);
		world.setBlock(x + 17, y + 29, z + 23, Blocks.leaves, 5, 3);
		world.setBlock(x + 18, y + 29, z + 23, Blocks.leaves, 5, 3);
		world.setBlock(x + 19, y + 29, z + 23, Blocks.leaves, 5, 3);
		world.setBlock(x + 20, y + 29, z + 23, Blocks.leaves, 5, 3);
		world.setBlock(x + 21, y + 29, z + 23, Blocks.leaves, 5, 3);
		world.setBlock(x + 22, y + 29, z + 23, Blocks.leaves, 5, 3);
		world.setBlock(x + 23, y + 29, z + 23, Blocks.leaves, 5, 3);
		world.setBlock(x + 24, y + 29, z + 23, Blocks.leaves, 5, 3);
		world.setBlock(x + 25, y + 29, z + 23, Blocks.leaves, 5, 3);
		world.setBlock(x + 7, y + 29, z + 24, Blocks.leaves, 5, 3);
		world.setBlock(x + 8, y + 29, z + 24, Blocks.leaves, 5, 3);
		world.setBlock(x + 9, y + 29, z + 24, Blocks.leaves, 5, 3);
		world.setBlock(x + 10, y + 29, z + 24, Blocks.leaves, 5, 3);
		world.setBlock(x + 11, y + 29, z + 24, Blocks.leaves, 5, 3);
		world.setBlock(x + 12, y + 29, z + 24, Blocks.leaves, 5, 3);
		world.setBlock(x + 13, y + 29, z + 24, Blocks.leaves, 5, 3);
		world.setBlock(x + 14, y + 29, z + 24, Blocks.leaves, 5, 3);
		world.setBlock(x + 15, y + 29, z + 24, Blocks.leaves, 5, 3);
		world.setBlock(x + 16, y + 29, z + 24, Blocks.leaves, 5, 3);
		world.setBlock(x + 17, y + 29, z + 24, Blocks.leaves, 5, 3);
		world.setBlock(x + 18, y + 29, z + 24, Blocks.leaves, 5, 3);
		world.setBlock(x + 19, y + 29, z + 24, Blocks.leaves, 5, 3);
		world.setBlock(x + 20, y + 29, z + 24, Blocks.leaves, 5, 3);
		world.setBlock(x + 21, y + 29, z + 24, Blocks.leaves, 5, 3);
		world.setBlock(x + 22, y + 29, z + 24, Blocks.leaves, 5, 3);
		world.setBlock(x + 23, y + 29, z + 24, Blocks.leaves, 5, 3);
		world.setBlock(x + 24, y + 29, z + 24, Blocks.leaves, 5, 3);
		world.setBlock(x + 8, y + 29, z + 25, Blocks.leaves, 5, 3);
		world.setBlock(x + 9, y + 29, z + 25, Blocks.leaves, 5, 3);
		world.setBlock(x + 10, y + 29, z + 25, Blocks.leaves, 5, 3);
		world.setBlock(x + 11, y + 29, z + 25, Blocks.leaves, 5, 3);
		world.setBlock(x + 12, y + 29, z + 25, Blocks.leaves, 5, 3);
		world.setBlock(x + 13, y + 29, z + 25, Blocks.leaves, 5, 3);
		world.setBlock(x + 14, y + 29, z + 25, Blocks.leaves, 5, 3);
		world.setBlock(x + 15, y + 29, z + 25, Blocks.leaves, 5, 3);
		world.setBlock(x + 16, y + 29, z + 25, Blocks.leaves, 5, 3);
		world.setBlock(x + 17, y + 29, z + 25, Blocks.leaves, 5, 3);
		world.setBlock(x + 18, y + 29, z + 25, Blocks.leaves, 5, 3);
		world.setBlock(x + 19, y + 29, z + 25, Blocks.leaves, 5, 3);
		world.setBlock(x + 20, y + 29, z + 25, Blocks.leaves, 5, 3);
		world.setBlock(x + 21, y + 29, z + 25, Blocks.leaves, 5, 3);
		world.setBlock(x + 22, y + 29, z + 25, Blocks.leaves, 5, 3);
		world.setBlock(x + 23, y + 29, z + 25, Blocks.leaves, 5, 3);
		world.setBlock(x + 9, y + 29, z + 26, Blocks.leaves, 5, 3);
		world.setBlock(x + 10, y + 29, z + 26, Blocks.leaves, 5, 3);
		world.setBlock(x + 11, y + 29, z + 26, Blocks.leaves, 5, 3);
		world.setBlock(x + 12, y + 29, z + 26, Blocks.leaves, 5, 3);
		world.setBlock(x + 13, y + 29, z + 26, Blocks.leaves, 5, 3);
		world.setBlock(x + 14, y + 29, z + 26, Blocks.leaves, 5, 3);
		world.setBlock(x + 15, y + 29, z + 26, Blocks.leaves, 5, 3);
		world.setBlock(x + 16, y + 29, z + 26, Blocks.leaves, 5, 3);
		world.setBlock(x + 17, y + 29, z + 26, Blocks.leaves, 5, 3);
		world.setBlock(x + 18, y + 29, z + 26, Blocks.leaves, 5, 3);
		world.setBlock(x + 19, y + 29, z + 26, Blocks.leaves, 5, 3);
		world.setBlock(x + 20, y + 29, z + 26, Blocks.leaves, 5, 3);
		world.setBlock(x + 21, y + 29, z + 26, Blocks.leaves, 5, 3);
		world.setBlock(x + 22, y + 29, z + 26, Blocks.leaves, 5, 3);
		world.setBlock(x + 10, y + 29, z + 27, Blocks.leaves, 5, 3);
		world.setBlock(x + 11, y + 29, z + 27, Blocks.leaves, 5, 3);
		world.setBlock(x + 12, y + 29, z + 27, Blocks.leaves, 5, 3);
		world.setBlock(x + 13, y + 29, z + 27, Blocks.leaves, 5, 3);
		world.setBlock(x + 14, y + 29, z + 27, Blocks.leaves, 5, 3);
		world.setBlock(x + 15, y + 29, z + 27, Blocks.leaves, 5, 3);
		world.setBlock(x + 16, y + 29, z + 27, Blocks.leaves, 5, 3);
		world.setBlock(x + 17, y + 29, z + 27, Blocks.leaves, 5, 3);
		world.setBlock(x + 18, y + 29, z + 27, Blocks.leaves, 5, 3);
		world.setBlock(x + 19, y + 29, z + 27, Blocks.leaves, 5, 3);
		world.setBlock(x + 20, y + 29, z + 27, Blocks.leaves, 5, 3);
		world.setBlock(x + 21, y + 29, z + 27, Blocks.leaves, 5, 3);
		world.setBlock(x + 13, y + 29, z + 28, Blocks.leaves, 5, 3);
		world.setBlock(x + 14, y + 29, z + 28, Blocks.leaves, 5, 3);
		world.setBlock(x + 15, y + 29, z + 28, Blocks.leaves, 5, 3);
		world.setBlock(x + 16, y + 29, z + 28, Blocks.leaves, 5, 3);
		world.setBlock(x + 17, y + 29, z + 28, Blocks.leaves, 5, 3);
		world.setBlock(x + 18, y + 29, z + 28, Blocks.leaves, 5, 3);
		world.setBlock(x + 13, y + 30, z + 3, Blocks.snow_layer, 0, 3);
		world.setBlock(x + 14, y + 30, z + 3, Blocks.wool, 4, 3);
		world.setBlock(x + 15, y + 30, z + 3, Blocks.snow_layer, 0, 3);
		world.setBlock(x + 16, y + 30, z + 3, Blocks.snow_layer, 2, 3);
		world.setBlock(x + 17, y + 30, z + 3, Blocks.snow_layer, 0, 3);
		world.setBlock(x + 18, y + 30, z + 3, Blocks.snow_layer, 0, 3);
		world.setBlock(x + 10, y + 30, z + 4, Blocks.snow_layer, 0, 3);
		world.setBlock(x + 11, y + 30, z + 4, Blocks.snow_layer, 1, 3);
		world.setBlock(x + 12, y + 30, z + 4, Blocks.snow_layer, 1, 3);
		world.setBlock(x + 13, y + 30, z + 4, Blocks.snow_layer, 0, 3);
		world.setBlock(x + 14, y + 30, z + 4, Blocks.snow_layer, 0, 3);
		world.setBlock(x + 15, y + 30, z + 4, Blocks.snow_layer, 0, 3);
		world.setBlock(x + 16, y + 30, z + 4, Blocks.snow_layer, 0, 3);
		world.setBlock(x + 17, y + 30, z + 4, Blocks.snow_layer, 0, 3);
		world.setBlock(x + 18, y + 30, z + 4, Blocks.snow_layer, 1, 3);
		world.setBlock(x + 19, y + 30, z + 4, Blocks.snow_layer, 0, 3);
		world.setBlock(x + 20, y + 30, z + 4, Blocks.snow_layer, 0, 3);
		world.setBlock(x + 21, y + 30, z + 4, Blocks.snow_layer, 0, 3);
		world.setBlock(x + 9, y + 30, z + 5, Blocks.snow_layer, 0, 3);
		world.setBlock(x + 10, y + 30, z + 5, Blocks.snow_layer, 1, 3);
		world.setBlock(x + 11, y + 30, z + 5, Blocks.snow_layer, 0, 3);
		world.setBlock(x + 12, y + 30, z + 5, Blocks.snow_layer, 0, 3);
		world.setBlock(x + 13, y + 30, z + 5, Blocks.leaves, 5, 3);
		world.setBlock(x + 14, y + 30, z + 5, Blocks.leaves, 5, 3);
		world.setBlock(x + 15, y + 30, z + 5, Blocks.leaves, 5, 3);
		world.setBlock(x + 16, y + 30, z + 5, Blocks.leaves, 5, 3);
		world.setBlock(x + 17, y + 30, z + 5, Blocks.leaves, 5, 3);
		world.setBlock(x + 18, y + 30, z + 5, Blocks.leaves, 5, 3);
		world.setBlock(x + 19, y + 30, z + 5, Blocks.wool, 10, 3);
		world.setBlock(x + 20, y + 30, z + 5, Blocks.snow_layer, 1, 3);
		world.setBlock(x + 21, y + 30, z + 5, Blocks.snow_layer, 0, 3);
		world.setBlock(x + 22, y + 30, z + 5, Blocks.snow_layer, 0, 3);
		world.setBlock(x + 8, y + 30, z + 6, Blocks.snow_layer, 0, 3);
		world.setBlock(x + 9, y + 30, z + 6, Blocks.wool, 14, 3);
		world.setBlock(x + 10, y + 30, z + 6, Blocks.snow_layer, 0, 3);
		world.setBlock(x + 11, y + 30, z + 6, Blocks.leaves, 5, 3);
		world.setBlock(x + 12, y + 30, z + 6, Blocks.leaves, 5, 3);
		world.setBlock(x + 13, y + 30, z + 6, Blocks.leaves, 5, 3);
		world.setBlock(x + 14, y + 30, z + 6, Blocks.leaves, 5, 3);
		world.setBlock(x + 15, y + 30, z + 6, Blocks.leaves, 5, 3);
		world.setBlock(x + 16, y + 30, z + 6, Blocks.leaves, 5, 3);
		world.setBlock(x + 17, y + 30, z + 6, Blocks.leaves, 5, 3);
		world.setBlock(x + 18, y + 30, z + 6, Blocks.leaves, 5, 3);
		world.setBlock(x + 19, y + 30, z + 6, Blocks.leaves, 5, 3);
		world.setBlock(x + 20, y + 30, z + 6, Blocks.leaves, 5, 3);
		world.setBlock(x + 21, y + 30, z + 6, Blocks.snow_layer, 1, 3);
		world.setBlock(x + 22, y + 30, z + 6, Blocks.snow_layer, 0, 3);
		world.setBlock(x + 23, y + 30, z + 6, Blocks.snow_layer, 0, 3);
		world.setBlock(x + 7, y + 30, z + 7, Blocks.snow_layer, 0, 3);
		world.setBlock(x + 8, y + 30, z + 7, Blocks.snow_layer, 0, 3);
		world.setBlock(x + 9, y + 30, z + 7, Blocks.leaves, 5, 3);
		world.setBlock(x + 10, y + 30, z + 7, Blocks.leaves, 5, 3);
		world.setBlock(x + 11, y + 30, z + 7, Blocks.leaves, 5, 3);
		world.setBlock(x + 12, y + 30, z + 7, Blocks.leaves, 5, 3);
		world.setBlock(x + 13, y + 30, z + 7, Blocks.leaves, 5, 3);
		world.setBlock(x + 14, y + 30, z + 7, Blocks.leaves, 5, 3);
		world.setBlock(x + 15, y + 30, z + 7, Blocks.leaves, 5, 3);
		world.setBlock(x + 16, y + 30, z + 7, Blocks.leaves, 5, 3);
		world.setBlock(x + 17, y + 30, z + 7, Blocks.leaves, 5, 3);
		world.setBlock(x + 18, y + 30, z + 7, Blocks.leaves, 5, 3);
		world.setBlock(x + 19, y + 30, z + 7, Blocks.leaves, 5, 3);
		world.setBlock(x + 20, y + 30, z + 7, Blocks.leaves, 5, 3);
		world.setBlock(x + 21, y + 30, z + 7, Blocks.leaves, 5, 3);
		world.setBlock(x + 22, y + 30, z + 7, Blocks.leaves, 5, 3);
		world.setBlock(x + 23, y + 30, z + 7, Blocks.wool, 1, 3);
		world.setBlock(x + 24, y + 30, z + 7, Blocks.snow_layer, 1, 3);
		world.setBlock(x + 6, y + 30, z + 8, Blocks.snow_layer, 1, 3);
		world.setBlock(x + 7, y + 30, z + 8, Blocks.snow_layer, 0, 3);
		world.setBlock(x + 8, y + 30, z + 8, Blocks.leaves, 5, 3);
		world.setBlock(x + 9, y + 30, z + 8, Blocks.leaves, 5, 3);
		world.setBlock(x + 10, y + 30, z + 8, Blocks.leaves, 5, 3);
		world.setBlock(x + 11, y + 30, z + 8, Blocks.leaves, 5, 3);
		world.setBlock(x + 12, y + 30, z + 8, Blocks.leaves, 5, 3);
		world.setBlock(x + 13, y + 30, z + 8, Blocks.leaves, 5, 3);
		world.setBlock(x + 14, y + 30, z + 8, Blocks.leaves, 5, 3);
		world.setBlock(x + 15, y + 30, z + 8, Blocks.leaves, 5, 3);
		world.setBlock(x + 16, y + 30, z + 8, Blocks.leaves, 5, 3);
		world.setBlock(x + 17, y + 30, z + 8, Blocks.leaves, 5, 3);
		world.setBlock(x + 18, y + 30, z + 8, Blocks.leaves, 5, 3);
		world.setBlock(x + 19, y + 30, z + 8, Blocks.leaves, 5, 3);
		world.setBlock(x + 20, y + 30, z + 8, Blocks.leaves, 5, 3);
		world.setBlock(x + 21, y + 30, z + 8, Blocks.leaves, 5, 3);
		world.setBlock(x + 22, y + 30, z + 8, Blocks.leaves, 5, 3);
		world.setBlock(x + 23, y + 30, z + 8, Blocks.leaves, 5, 3);
		world.setBlock(x + 24, y + 30, z + 8, Blocks.snow_layer, 1, 3);
		world.setBlock(x + 25, y + 30, z + 8, Blocks.snow_layer, 1, 3);
		world.setBlock(x + 5, y + 30, z + 9, Blocks.wool, 10, 3);
		world.setBlock(x + 6, y + 30, z + 9, Blocks.snow_layer, 0, 3);
		world.setBlock(x + 7, y + 30, z + 9, Blocks.leaves, 5, 3);
		world.setBlock(x + 8, y + 30, z + 9, Blocks.leaves, 5, 3);
		world.setBlock(x + 9, y + 30, z + 9, Blocks.leaves, 5, 3);
		world.setBlock(x + 10, y + 30, z + 9, Blocks.leaves, 5, 3);
		world.setBlock(x + 11, y + 30, z + 9, Blocks.leaves, 5, 3);
		world.setBlock(x + 12, y + 30, z + 9, Blocks.leaves, 5, 3);
		world.setBlock(x + 13, y + 30, z + 9, Blocks.leaves, 5, 3);
		world.setBlock(x + 14, y + 30, z + 9, Blocks.leaves, 5, 3);
		world.setBlock(x + 15, y + 30, z + 9, Blocks.leaves, 5, 3);
		world.setBlock(x + 16, y + 30, z + 9, Blocks.leaves, 5, 3);
		world.setBlock(x + 17, y + 30, z + 9, Blocks.leaves, 5, 3);
		world.setBlock(x + 18, y + 30, z + 9, Blocks.leaves, 5, 3);
		world.setBlock(x + 19, y + 30, z + 9, Blocks.leaves, 5, 3);
		world.setBlock(x + 20, y + 30, z + 9, Blocks.leaves, 5, 3);
		world.setBlock(x + 21, y + 30, z + 9, Blocks.leaves, 5, 3);
		world.setBlock(x + 22, y + 30, z + 9, Blocks.leaves, 5, 3);
		world.setBlock(x + 23, y + 30, z + 9, Blocks.leaves, 5, 3);
		world.setBlock(x + 24, y + 30, z + 9, Blocks.leaves, 5, 3);
		world.setBlock(x + 25, y + 30, z + 9, Blocks.snow_layer, 1, 3);
		world.setBlock(x + 26, y + 30, z + 9, Blocks.snow_layer, 0, 3);
		world.setBlock(x + 4, y + 30, z + 10, Blocks.snow_layer, 1, 3);
		world.setBlock(x + 5, y + 30, z + 10, Blocks.snow_layer, 0, 3);
		world.setBlock(x + 6, y + 30, z + 10, Blocks.snow_layer, 1, 3);
		world.setBlock(x + 7, y + 30, z + 10, Blocks.leaves, 5, 3);
		world.setBlock(x + 8, y + 30, z + 10, Blocks.leaves, 5, 3);
		world.setBlock(x + 9, y + 30, z + 10, Blocks.leaves, 5, 3);
		world.setBlock(x + 10, y + 30, z + 10, Blocks.leaves, 5, 3);
		world.setBlock(x + 11, y + 30, z + 10, Blocks.leaves, 5, 3);
		world.setBlock(x + 12, y + 30, z + 10, Blocks.leaves, 5, 3);
		world.setBlock(x + 13, y + 30, z + 10, Blocks.leaves, 5, 3);
		world.setBlock(x + 14, y + 30, z + 10, Blocks.leaves, 5, 3);
		world.setBlock(x + 15, y + 30, z + 10, Blocks.leaves, 5, 3);
		world.setBlock(x + 16, y + 30, z + 10, Blocks.leaves, 5, 3);
		world.setBlock(x + 17, y + 30, z + 10, Blocks.leaves, 5, 3);
		world.setBlock(x + 18, y + 30, z + 10, Blocks.leaves, 5, 3);
		world.setBlock(x + 19, y + 30, z + 10, Blocks.leaves, 5, 3);
		world.setBlock(x + 20, y + 30, z + 10, Blocks.leaves, 5, 3);
		world.setBlock(x + 21, y + 30, z + 10, Blocks.leaves, 5, 3);
		world.setBlock(x + 22, y + 30, z + 10, Blocks.leaves, 5, 3);
		world.setBlock(x + 23, y + 30, z + 10, Blocks.leaves, 5, 3);
		world.setBlock(x + 24, y + 30, z + 10, Blocks.leaves, 5, 3);
		world.setBlock(x + 25, y + 30, z + 10, Blocks.snow_layer, 1, 3);
		world.setBlock(x + 26, y + 30, z + 10, Blocks.snow_layer, 0, 3);
		world.setBlock(x + 27, y + 30, z + 10, Blocks.wool, 11, 3);
		world.setBlock(x + 4, y + 30, z + 11, Blocks.snow_layer, 0, 3);
		world.setBlock(x + 5, y + 30, z + 11, Blocks.snow_layer, 0, 3);
		world.setBlock(x + 6, y + 30, z + 11, Blocks.leaves, 5, 3);
		world.setBlock(x + 7, y + 30, z + 11, Blocks.leaves, 5, 3);
		world.setBlock(x + 8, y + 30, z + 11, Blocks.leaves, 5, 3);
		world.setBlock(x + 9, y + 30, z + 11, Blocks.leaves, 5, 3);
		world.setBlock(x + 10, y + 30, z + 11, Blocks.leaves, 5, 3);
		world.setBlock(x + 11, y + 30, z + 11, Blocks.leaves, 5, 3);
		world.setBlock(x + 12, y + 30, z + 11, Blocks.leaves, 5, 3);
		world.setBlock(x + 13, y + 30, z + 11, Blocks.leaves, 5, 3);
		world.setBlock(x + 14, y + 30, z + 11, Blocks.leaves, 5, 3);
		world.setBlock(x + 15, y + 30, z + 11, Blocks.leaves, 5, 3);
		world.setBlock(x + 16, y + 30, z + 11, Blocks.leaves, 5, 3);
		world.setBlock(x + 17, y + 30, z + 11, Blocks.leaves, 5, 3);
		world.setBlock(x + 18, y + 30, z + 11, Blocks.leaves, 5, 3);
		world.setBlock(x + 19, y + 30, z + 11, Blocks.leaves, 5, 3);
		world.setBlock(x + 20, y + 30, z + 11, Blocks.leaves, 5, 3);
		world.setBlock(x + 21, y + 30, z + 11, Blocks.leaves, 5, 3);
		world.setBlock(x + 22, y + 30, z + 11, Blocks.leaves, 5, 3);
		world.setBlock(x + 23, y + 30, z + 11, Blocks.leaves, 5, 3);
		world.setBlock(x + 24, y + 30, z + 11, Blocks.leaves, 5, 3);
		world.setBlock(x + 25, y + 30, z + 11, Blocks.leaves, 5, 3);
		world.setBlock(x + 26, y + 30, z + 11, Blocks.snow_layer, 0, 3);
		world.setBlock(x + 27, y + 30, z + 11, Blocks.snow_layer, 0, 3);
		world.setBlock(x + 4, y + 30, z + 12, Blocks.snow_layer, 1, 3);
		world.setBlock(x + 5, y + 30, z + 12, Blocks.wool, 1, 3);
		world.setBlock(x + 6, y + 30, z + 12, Blocks.leaves, 5, 3);
		world.setBlock(x + 7, y + 30, z + 12, Blocks.leaves, 5, 3);
		world.setBlock(x + 8, y + 30, z + 12, Blocks.leaves, 5, 3);
		world.setBlock(x + 9, y + 30, z + 12, Blocks.leaves, 5, 3);
		world.setBlock(x + 10, y + 30, z + 12, Blocks.leaves, 5, 3);
		world.setBlock(x + 11, y + 30, z + 12, Blocks.leaves, 5, 3);
		world.setBlock(x + 12, y + 30, z + 12, Blocks.leaves, 5, 3);
		world.setBlock(x + 13, y + 30, z + 12, Blocks.leaves, 5, 3);
		world.setBlock(x + 14, y + 30, z + 12, Blocks.log, 1, 3);
		world.setBlock(x + 15, y + 30, z + 12, Blocks.log, 1, 3);
		world.setBlock(x + 16, y + 30, z + 12, Blocks.log, 1, 3);
		world.setBlock(x + 17, y + 30, z + 12, Blocks.log, 1, 3);
		world.setBlock(x + 18, y + 30, z + 12, Blocks.leaves, 5, 3);
		world.setBlock(x + 19, y + 30, z + 12, Blocks.leaves, 5, 3);
		world.setBlock(x + 20, y + 30, z + 12, Blocks.leaves, 5, 3);
		world.setBlock(x + 21, y + 30, z + 12, Blocks.leaves, 5, 3);
		world.setBlock(x + 22, y + 30, z + 12, Blocks.leaves, 5, 3);
		world.setBlock(x + 23, y + 30, z + 12, Blocks.leaves, 5, 3);
		world.setBlock(x + 24, y + 30, z + 12, Blocks.leaves, 5, 3);
		world.setBlock(x + 25, y + 30, z + 12, Blocks.leaves, 5, 3);
		world.setBlock(x + 26, y + 30, z + 12, Blocks.wool, 14, 3);
		world.setBlock(x + 27, y + 30, z + 12, Blocks.snow_layer, 1, 3);
		world.setBlock(x + 3, y + 30, z + 13, Blocks.snow_layer, 0, 3);
		world.setBlock(x + 4, y + 30, z + 13, Blocks.snow_layer, 1, 3);
		world.setBlock(x + 5, y + 30, z + 13, Blocks.leaves, 5, 3);
		world.setBlock(x + 6, y + 30, z + 13, Blocks.leaves, 5, 3);
		world.setBlock(x + 7, y + 30, z + 13, Blocks.leaves, 5, 3);
		world.setBlock(x + 8, y + 30, z + 13, Blocks.leaves, 5, 3);
		world.setBlock(x + 9, y + 30, z + 13, Blocks.leaves, 5, 3);
		world.setBlock(x + 10, y + 30, z + 13, Blocks.leaves, 5, 3);
		world.setBlock(x + 11, y + 30, z + 13, Blocks.leaves, 5, 3);
		world.setBlock(x + 12, y + 30, z + 13, Blocks.leaves, 5, 3);
		world.setBlock(x + 13, y + 30, z + 13, Blocks.log, 1, 3);
		world.setBlock(x + 14, y + 30, z + 13, Blocks.log, 1, 3);
		world.setBlock(x + 15, y + 30, z + 13, Blocks.log, 1, 3);
		world.setBlock(x + 16, y + 30, z + 13, Blocks.log, 1, 3);
		world.setBlock(x + 17, y + 30, z + 13, Blocks.log, 1, 3);
		world.setBlock(x + 18, y + 30, z + 13, Blocks.log, 1, 3);
		world.setBlock(x + 19, y + 30, z + 13, Blocks.leaves, 5, 3);
		world.setBlock(x + 20, y + 30, z + 13, Blocks.leaves, 5, 3);
		world.setBlock(x + 21, y + 30, z + 13, Blocks.leaves, 5, 3);
		world.setBlock(x + 22, y + 30, z + 13, Blocks.leaves, 5, 3);
		world.setBlock(x + 23, y + 30, z + 13, Blocks.leaves, 5, 3);
		world.setBlock(x + 24, y + 30, z + 13, Blocks.leaves, 5, 3);
		world.setBlock(x + 25, y + 30, z + 13, Blocks.leaves, 5, 3);
		world.setBlock(x + 26, y + 30, z + 13, Blocks.leaves, 5, 3);
		world.setBlock(x + 27, y + 30, z + 13, Blocks.snow_layer, 0, 3);
		world.setBlock(x + 28, y + 30, z + 13, Blocks.snow_layer, 1, 3);
		world.setBlock(x + 3, y + 30, z + 14, Blocks.snow_layer, 0, 3);
		world.setBlock(x + 4, y + 30, z + 14, Blocks.snow_layer, 0, 3);
		world.setBlock(x + 5, y + 30, z + 14, Blocks.leaves, 5, 3);
		world.setBlock(x + 6, y + 30, z + 14, Blocks.leaves, 5, 3);
		world.setBlock(x + 7, y + 30, z + 14, Blocks.leaves, 5, 3);
		world.setBlock(x + 8, y + 30, z + 14, Blocks.leaves, 5, 3);
		world.setBlock(x + 9, y + 30, z + 14, Blocks.leaves, 5, 3);
		world.setBlock(x + 10, y + 30, z + 14, Blocks.leaves, 5, 3);
		world.setBlock(x + 11, y + 30, z + 14, Blocks.leaves, 5, 3);
		world.setBlock(x + 12, y + 30, z + 14, Blocks.log, 1, 3);
		world.setBlock(x + 13, y + 30, z + 14, Blocks.log, 1, 3);
		world.setBlock(x + 14, y + 30, z + 14, Blocks.log, 1, 3);
		world.setBlock(x + 15, y + 30, z + 14, Blocks.log, 1, 3);
		world.setBlock(x + 16, y + 30, z + 14, Blocks.log, 1, 3);
		world.setBlock(x + 17, y + 30, z + 14, Blocks.log, 1, 3);
		world.setBlock(x + 18, y + 30, z + 14, Blocks.log, 1, 3);
		world.setBlock(x + 19, y + 30, z + 14, Blocks.log, 1, 3);
		world.setBlock(x + 20, y + 30, z + 14, Blocks.leaves, 5, 3);
		world.setBlock(x + 21, y + 30, z + 14, Blocks.leaves, 5, 3);
		world.setBlock(x + 22, y + 30, z + 14, Blocks.leaves, 5, 3);
		world.setBlock(x + 23, y + 30, z + 14, Blocks.leaves, 5, 3);
		world.setBlock(x + 24, y + 30, z + 14, Blocks.leaves, 5, 3);
		world.setBlock(x + 25, y + 30, z + 14, Blocks.leaves, 5, 3);
		world.setBlock(x + 26, y + 30, z + 14, Blocks.leaves, 5, 3);
		world.setBlock(x + 27, y + 30, z + 14, Blocks.snow_layer, 0, 3);
		world.setBlock(x + 28, y + 30, z + 14, Blocks.snow_layer, 1, 3);
		world.setBlock(x + 3, y + 30, z + 15, Blocks.snow_layer, 0, 3);
		world.setBlock(x + 4, y + 30, z + 15, Blocks.snow_layer, 0, 3);
		world.setBlock(x + 5, y + 30, z + 15, Blocks.leaves, 5, 3);
		world.setBlock(x + 6, y + 30, z + 15, Blocks.leaves, 5, 3);
		world.setBlock(x + 7, y + 30, z + 15, Blocks.leaves, 5, 3);
		world.setBlock(x + 8, y + 30, z + 15, Blocks.leaves, 5, 3);
		world.setBlock(x + 9, y + 30, z + 15, Blocks.leaves, 5, 3);
		world.setBlock(x + 10, y + 30, z + 15, Blocks.leaves, 5, 3);
		world.setBlock(x + 11, y + 30, z + 15, Blocks.leaves, 5, 3);
		world.setBlock(x + 12, y + 30, z + 15, Blocks.log, 1, 3);
		world.setBlock(x + 13, y + 30, z + 15, Blocks.log, 1, 3);
		world.setBlock(x + 14, y + 30, z + 15, Blocks.log, 1, 3);
		world.setBlock(x + 15, y + 30, z + 15, Blocks.log, 1, 3);
		world.setBlock(x + 16, y + 30, z + 15, Blocks.log, 1, 3);
		world.setBlock(x + 17, y + 30, z + 15, Blocks.log, 1, 3);
		world.setBlock(x + 18, y + 30, z + 15, Blocks.log, 1, 3);
		world.setBlock(x + 19, y + 30, z + 15, Blocks.log, 1, 3);
		world.setBlock(x + 20, y + 30, z + 15, Blocks.leaves, 5, 3);
		world.setBlock(x + 21, y + 30, z + 15, Blocks.leaves, 5, 3);
		world.setBlock(x + 22, y + 30, z + 15, Blocks.leaves, 5, 3);
		world.setBlock(x + 23, y + 30, z + 15, Blocks.leaves, 5, 3);
		world.setBlock(x + 24, y + 30, z + 15, Blocks.leaves, 5, 3);
		world.setBlock(x + 25, y + 30, z + 15, Blocks.leaves, 5, 3);
		world.setBlock(x + 26, y + 30, z + 15, Blocks.leaves, 5, 3);
		world.setBlock(x + 27, y + 30, z + 15, Blocks.snow_layer, 0, 3);
		world.setBlock(x + 28, y + 30, z + 15, Blocks.snow_layer, 0, 3);
		world.setBlock(x + 3, y + 30, z + 16, Blocks.snow_layer, 0, 3);
		world.setBlock(x + 4, y + 30, z + 16, Blocks.snow_layer, 1, 3);
		world.setBlock(x + 5, y + 30, z + 16, Blocks.leaves, 5, 3);
		world.setBlock(x + 6, y + 30, z + 16, Blocks.leaves, 5, 3);
		world.setBlock(x + 7, y + 30, z + 16, Blocks.leaves, 5, 3);
		world.setBlock(x + 8, y + 30, z + 16, Blocks.leaves, 5, 3);
		world.setBlock(x + 9, y + 30, z + 16, Blocks.leaves, 5, 3);
		world.setBlock(x + 10, y + 30, z + 16, Blocks.leaves, 5, 3);
		world.setBlock(x + 11, y + 30, z + 16, Blocks.leaves, 5, 3);
		world.setBlock(x + 12, y + 30, z + 16, Blocks.log, 1, 3);
		world.setBlock(x + 13, y + 30, z + 16, Blocks.log, 1, 3);
		world.setBlock(x + 14, y + 30, z + 16, Blocks.log, 1, 3);
		world.setBlock(x + 15, y + 30, z + 16, Blocks.log, 1, 3);
		world.setBlock(x + 16, y + 30, z + 16, Blocks.log, 1, 3);
		world.setBlock(x + 17, y + 30, z + 16, Blocks.log, 1, 3);
		world.setBlock(x + 18, y + 30, z + 16, Blocks.log, 1, 3);
		world.setBlock(x + 19, y + 30, z + 16, Blocks.log, 1, 3);
		world.setBlock(x + 20, y + 30, z + 16, Blocks.leaves, 5, 3);
		world.setBlock(x + 21, y + 30, z + 16, Blocks.leaves, 5, 3);
		world.setBlock(x + 22, y + 30, z + 16, Blocks.leaves, 5, 3);
		world.setBlock(x + 23, y + 30, z + 16, Blocks.leaves, 5, 3);
		world.setBlock(x + 24, y + 30, z + 16, Blocks.leaves, 5, 3);
		world.setBlock(x + 25, y + 30, z + 16, Blocks.leaves, 5, 3);
		world.setBlock(x + 26, y + 30, z + 16, Blocks.leaves, 5, 3);
		world.setBlock(x + 27, y + 30, z + 16, Blocks.snow_layer, 1, 3);
		world.setBlock(x + 28, y + 30, z + 16, Blocks.snow_layer, 0, 3);
		world.setBlock(x + 3, y + 30, z + 17, Blocks.snow_layer, 2, 3);
		world.setBlock(x + 4, y + 30, z + 17, Blocks.snow_layer, 0, 3);
		world.setBlock(x + 5, y + 30, z + 17, Blocks.leaves, 5, 3);
		world.setBlock(x + 6, y + 30, z + 17, Blocks.leaves, 5, 3);
		world.setBlock(x + 7, y + 30, z + 17, Blocks.leaves, 5, 3);
		world.setBlock(x + 8, y + 30, z + 17, Blocks.leaves, 5, 3);
		world.setBlock(x + 9, y + 30, z + 17, Blocks.leaves, 5, 3);
		world.setBlock(x + 10, y + 30, z + 17, Blocks.leaves, 5, 3);
		world.setBlock(x + 11, y + 30, z + 17, Blocks.leaves, 5, 3);
		world.setBlock(x + 12, y + 30, z + 17, Blocks.log, 1, 3);
		world.setBlock(x + 13, y + 30, z + 17, Blocks.log, 1, 3);
		world.setBlock(x + 14, y + 30, z + 17, Blocks.log, 1, 3);
		world.setBlock(x + 15, y + 30, z + 17, Blocks.log, 1, 3);
		world.setBlock(x + 16, y + 30, z + 17, Blocks.log, 1, 3);
		world.setBlock(x + 17, y + 30, z + 17, Blocks.log, 1, 3);
		world.setBlock(x + 18, y + 30, z + 17, Blocks.log, 1, 3);
		world.setBlock(x + 19, y + 30, z + 17, Blocks.log, 1, 3);
		world.setBlock(x + 20, y + 30, z + 17, Blocks.leaves, 5, 3);
		world.setBlock(x + 21, y + 30, z + 17, Blocks.leaves, 5, 3);
		world.setBlock(x + 22, y + 30, z + 17, Blocks.leaves, 5, 3);
		world.setBlock(x + 23, y + 30, z + 17, Blocks.leaves, 5, 3);
		world.setBlock(x + 24, y + 30, z + 17, Blocks.leaves, 5, 3);
		world.setBlock(x + 25, y + 30, z + 17, Blocks.leaves, 5, 3);
		world.setBlock(x + 26, y + 30, z + 17, Blocks.leaves, 5, 3);
		world.setBlock(x + 27, y + 30, z + 17, Blocks.wool, 1, 3);
		world.setBlock(x + 28, y + 30, z + 17, Blocks.snow_layer, 0, 3);
		world.setBlock(x + 3, y + 30, z + 18, Blocks.snow_layer, 1, 3);
		world.setBlock(x + 4, y + 30, z + 18, Blocks.snow_layer, 0, 3);
		world.setBlock(x + 5, y + 30, z + 18, Blocks.leaves, 5, 3);
		world.setBlock(x + 6, y + 30, z + 18, Blocks.leaves, 5, 3);
		world.setBlock(x + 7, y + 30, z + 18, Blocks.leaves, 5, 3);
		world.setBlock(x + 8, y + 30, z + 18, Blocks.leaves, 5, 3);
		world.setBlock(x + 9, y + 30, z + 18, Blocks.leaves, 5, 3);
		world.setBlock(x + 10, y + 30, z + 18, Blocks.leaves, 5, 3);
		world.setBlock(x + 11, y + 30, z + 18, Blocks.leaves, 5, 3);
		world.setBlock(x + 12, y + 30, z + 18, Blocks.leaves, 5, 3);
		world.setBlock(x + 13, y + 30, z + 18, Blocks.log, 1, 3);
		world.setBlock(x + 14, y + 30, z + 18, Blocks.log, 1, 3);
		world.setBlock(x + 15, y + 30, z + 18, Blocks.log, 1, 3);
		world.setBlock(x + 16, y + 30, z + 18, Blocks.log, 1, 3);
		world.setBlock(x + 17, y + 30, z + 18, Blocks.log, 1, 3);
		world.setBlock(x + 18, y + 30, z + 18, Blocks.log, 1, 3);
		world.setBlock(x + 19, y + 30, z + 18, Blocks.leaves, 5, 3);
		world.setBlock(x + 20, y + 30, z + 18, Blocks.leaves, 5, 3);
		world.setBlock(x + 21, y + 30, z + 18, Blocks.leaves, 5, 3);
		world.setBlock(x + 22, y + 30, z + 18, Blocks.leaves, 5, 3);
		world.setBlock(x + 23, y + 30, z + 18, Blocks.leaves, 5, 3);
		world.setBlock(x + 24, y + 30, z + 18, Blocks.leaves, 5, 3);
		world.setBlock(x + 25, y + 30, z + 18, Blocks.leaves, 5, 3);
		world.setBlock(x + 26, y + 30, z + 18, Blocks.leaves, 5, 3);
		world.setBlock(x + 27, y + 30, z + 18, Blocks.snow_layer, 0, 3);
		world.setBlock(x + 28, y + 30, z + 18, Blocks.snow_layer, 0, 3);
		world.setBlock(x + 4, y + 30, z + 19, Blocks.snow_layer, 0, 3);
		world.setBlock(x + 5, y + 30, z + 19, Blocks.wool, 14, 3);
		world.setBlock(x + 6, y + 30, z + 19, Blocks.leaves, 5, 3);
		world.setBlock(x + 7, y + 30, z + 19, Blocks.leaves, 5, 3);
		world.setBlock(x + 8, y + 30, z + 19, Blocks.leaves, 5, 3);
		world.setBlock(x + 9, y + 30, z + 19, Blocks.leaves, 5, 3);
		world.setBlock(x + 10, y + 30, z + 19, Blocks.leaves, 5, 3);
		world.setBlock(x + 11, y + 30, z + 19, Blocks.leaves, 5, 3);
		world.setBlock(x + 12, y + 30, z + 19, Blocks.leaves, 5, 3);
		world.setBlock(x + 13, y + 30, z + 19, Blocks.leaves, 5, 3);
		world.setBlock(x + 14, y + 30, z + 19, Blocks.log, 1, 3);
		world.setBlock(x + 15, y + 30, z + 19, Blocks.log, 1, 3);
		world.setBlock(x + 16, y + 30, z + 19, Blocks.log, 1, 3);
		world.setBlock(x + 17, y + 30, z + 19, Blocks.log, 1, 3);
		world.setBlock(x + 18, y + 30, z + 19, Blocks.leaves, 5, 3);
		world.setBlock(x + 19, y + 30, z + 19, Blocks.leaves, 5, 3);
		world.setBlock(x + 20, y + 30, z + 19, Blocks.leaves, 5, 3);
		world.setBlock(x + 21, y + 30, z + 19, Blocks.leaves, 5, 3);
		world.setBlock(x + 22, y + 30, z + 19, Blocks.leaves, 5, 3);
		world.setBlock(x + 23, y + 30, z + 19, Blocks.leaves, 5, 3);
		world.setBlock(x + 24, y + 30, z + 19, Blocks.leaves, 5, 3);
		world.setBlock(x + 25, y + 30, z + 19, Blocks.leaves, 5, 3);
		world.setBlock(x + 26, y + 30, z + 19, Blocks.snow_layer, 0, 3);
		world.setBlock(x + 27, y + 30, z + 19, Blocks.snow_layer, 1, 3);
		world.setBlock(x + 4, y + 30, z + 20, Blocks.snow_layer, 0, 3);
		world.setBlock(x + 5, y + 30, z + 20, Blocks.snow_layer, 3, 3);
		world.setBlock(x + 6, y + 30, z + 20, Blocks.leaves, 5, 3);
		world.setBlock(x + 7, y + 30, z + 20, Blocks.leaves, 5, 3);
		world.setBlock(x + 8, y + 30, z + 20, Blocks.leaves, 5, 3);
		world.setBlock(x + 9, y + 30, z + 20, Blocks.leaves, 5, 3);
		world.setBlock(x + 10, y + 30, z + 20, Blocks.leaves, 5, 3);
		world.setBlock(x + 11, y + 30, z + 20, Blocks.leaves, 5, 3);
		world.setBlock(x + 12, y + 30, z + 20, Blocks.leaves, 5, 3);
		world.setBlock(x + 13, y + 30, z + 20, Blocks.leaves, 5, 3);
		world.setBlock(x + 14, y + 30, z + 20, Blocks.leaves, 5, 3);
		world.setBlock(x + 15, y + 30, z + 20, Blocks.leaves, 5, 3);
		world.setBlock(x + 16, y + 30, z + 20, Blocks.leaves, 5, 3);
		world.setBlock(x + 17, y + 30, z + 20, Blocks.leaves, 5, 3);
		world.setBlock(x + 18, y + 30, z + 20, Blocks.leaves, 5, 3);
		world.setBlock(x + 19, y + 30, z + 20, Blocks.leaves, 5, 3);
		world.setBlock(x + 20, y + 30, z + 20, Blocks.leaves, 5, 3);
		world.setBlock(x + 21, y + 30, z + 20, Blocks.leaves, 5, 3);
		world.setBlock(x + 22, y + 30, z + 20, Blocks.leaves, 5, 3);
		world.setBlock(x + 23, y + 30, z + 20, Blocks.leaves, 5, 3);
		world.setBlock(x + 24, y + 30, z + 20, Blocks.leaves, 5, 3);
		world.setBlock(x + 25, y + 30, z + 20, Blocks.leaves, 5, 3);
		world.setBlock(x + 26, y + 30, z + 20, Blocks.snow_layer, 0, 3);
		world.setBlock(x + 27, y + 30, z + 20, Blocks.snow_layer, 1, 3);
		world.setBlock(x + 4, y + 30, z + 21, Blocks.snow_layer, 0, 3);
		world.setBlock(x + 5, y + 30, z + 21, Blocks.snow_layer, 0, 3);
		world.setBlock(x + 6, y + 30, z + 21, Blocks.snow_layer, 0, 3);
		world.setBlock(x + 7, y + 30, z + 21, Blocks.leaves, 5, 3);
		world.setBlock(x + 8, y + 30, z + 21, Blocks.leaves, 5, 3);
		world.setBlock(x + 9, y + 30, z + 21, Blocks.leaves, 5, 3);
		world.setBlock(x + 10, y + 30, z + 21, Blocks.leaves, 5, 3);
		world.setBlock(x + 11, y + 30, z + 21, Blocks.leaves, 5, 3);
		world.setBlock(x + 12, y + 30, z + 21, Blocks.leaves, 5, 3);
		world.setBlock(x + 13, y + 30, z + 21, Blocks.leaves, 5, 3);
		world.setBlock(x + 14, y + 30, z + 21, Blocks.leaves, 5, 3);
		world.setBlock(x + 15, y + 30, z + 21, Blocks.leaves, 5, 3);
		world.setBlock(x + 16, y + 30, z + 21, Blocks.leaves, 5, 3);
		world.setBlock(x + 17, y + 30, z + 21, Blocks.leaves, 5, 3);
		world.setBlock(x + 18, y + 30, z + 21, Blocks.leaves, 5, 3);
		world.setBlock(x + 19, y + 30, z + 21, Blocks.leaves, 5, 3);
		world.setBlock(x + 20, y + 30, z + 21, Blocks.leaves, 5, 3);
		world.setBlock(x + 21, y + 30, z + 21, Blocks.leaves, 5, 3);
		world.setBlock(x + 22, y + 30, z + 21, Blocks.leaves, 5, 3);
		world.setBlock(x + 23, y + 30, z + 21, Blocks.leaves, 5, 3);
		world.setBlock(x + 24, y + 30, z + 21, Blocks.leaves, 5, 3);
		world.setBlock(x + 25, y + 30, z + 21, Blocks.wool, 4, 3);
		world.setBlock(x + 26, y + 30, z + 21, Blocks.snow_layer, 1, 3);
		world.setBlock(x + 27, y + 30, z + 21, Blocks.snow_layer, 0, 3);
		world.setBlock(x + 5, y + 30, z + 22, Blocks.snow_layer, 0, 3);
		world.setBlock(x + 6, y + 30, z + 22, Blocks.snow_layer, 0, 3);
		world.setBlock(x + 7, y + 30, z + 22, Blocks.leaves, 5, 3);
		world.setBlock(x + 8, y + 30, z + 22, Blocks.leaves, 5, 3);
		world.setBlock(x + 9, y + 30, z + 22, Blocks.leaves, 5, 3);
		world.setBlock(x + 10, y + 30, z + 22, Blocks.leaves, 5, 3);
		world.setBlock(x + 11, y + 30, z + 22, Blocks.leaves, 5, 3);
		world.setBlock(x + 12, y + 30, z + 22, Blocks.leaves, 5, 3);
		world.setBlock(x + 13, y + 30, z + 22, Blocks.leaves, 5, 3);
		world.setBlock(x + 14, y + 30, z + 22, Blocks.leaves, 5, 3);
		world.setBlock(x + 15, y + 30, z + 22, Blocks.leaves, 5, 3);
		world.setBlock(x + 16, y + 30, z + 22, Blocks.leaves, 5, 3);
		world.setBlock(x + 17, y + 30, z + 22, Blocks.leaves, 5, 3);
		world.setBlock(x + 18, y + 30, z + 22, Blocks.leaves, 5, 3);
		world.setBlock(x + 19, y + 30, z + 22, Blocks.leaves, 5, 3);
		world.setBlock(x + 20, y + 30, z + 22, Blocks.leaves, 5, 3);
		world.setBlock(x + 21, y + 30, z + 22, Blocks.leaves, 5, 3);
		world.setBlock(x + 22, y + 30, z + 22, Blocks.leaves, 5, 3);
		world.setBlock(x + 23, y + 30, z + 22, Blocks.leaves, 5, 3);
		world.setBlock(x + 24, y + 30, z + 22, Blocks.leaves, 5, 3);
		world.setBlock(x + 25, y + 30, z + 22, Blocks.snow_layer, 0, 3);
		world.setBlock(x + 26, y + 30, z + 22, Blocks.snow_layer, 0, 3);
		world.setBlock(x + 6, y + 30, z + 23, Blocks.snow_layer, 0, 3);
		world.setBlock(x + 7, y + 30, z + 23, Blocks.snow_layer, 0, 3);
		world.setBlock(x + 8, y + 30, z + 23, Blocks.leaves, 5, 3);
		world.setBlock(x + 9, y + 30, z + 23, Blocks.leaves, 5, 3);
		world.setBlock(x + 10, y + 30, z + 23, Blocks.leaves, 5, 3);
		world.setBlock(x + 11, y + 30, z + 23, Blocks.leaves, 5, 3);
		world.setBlock(x + 12, y + 30, z + 23, Blocks.leaves, 5, 3);
		world.setBlock(x + 13, y + 30, z + 23, Blocks.leaves, 5, 3);
		world.setBlock(x + 14, y + 30, z + 23, Blocks.leaves, 5, 3);
		world.setBlock(x + 15, y + 30, z + 23, Blocks.leaves, 5, 3);
		world.setBlock(x + 16, y + 30, z + 23, Blocks.leaves, 5, 3);
		world.setBlock(x + 17, y + 30, z + 23, Blocks.leaves, 5, 3);
		world.setBlock(x + 18, y + 30, z + 23, Blocks.leaves, 5, 3);
		world.setBlock(x + 19, y + 30, z + 23, Blocks.leaves, 5, 3);
		world.setBlock(x + 20, y + 30, z + 23, Blocks.leaves, 5, 3);
		world.setBlock(x + 21, y + 30, z + 23, Blocks.leaves, 5, 3);
		world.setBlock(x + 22, y + 30, z + 23, Blocks.leaves, 5, 3);
		world.setBlock(x + 23, y + 30, z + 23, Blocks.leaves, 5, 3);
		world.setBlock(x + 24, y + 30, z + 23, Blocks.snow_layer, 0, 3);
		world.setBlock(x + 25, y + 30, z + 23, Blocks.snow_layer, 0, 3);
		world.setBlock(x + 7, y + 30, z + 24, Blocks.snow_layer, 0, 3);
		world.setBlock(x + 8, y + 30, z + 24, Blocks.wool, 4, 3);
		world.setBlock(x + 9, y + 30, z + 24, Blocks.leaves, 5, 3);
		world.setBlock(x + 10, y + 30, z + 24, Blocks.leaves, 5, 3);
		world.setBlock(x + 11, y + 30, z + 24, Blocks.leaves, 5, 3);
		world.setBlock(x + 12, y + 30, z + 24, Blocks.leaves, 5, 3);
		world.setBlock(x + 13, y + 30, z + 24, Blocks.leaves, 5, 3);
		world.setBlock(x + 14, y + 30, z + 24, Blocks.leaves, 5, 3);
		world.setBlock(x + 15, y + 30, z + 24, Blocks.leaves, 5, 3);
		world.setBlock(x + 16, y + 30, z + 24, Blocks.leaves, 5, 3);
		world.setBlock(x + 17, y + 30, z + 24, Blocks.leaves, 5, 3);
		world.setBlock(x + 18, y + 30, z + 24, Blocks.leaves, 5, 3);
		world.setBlock(x + 19, y + 30, z + 24, Blocks.leaves, 5, 3);
		world.setBlock(x + 20, y + 30, z + 24, Blocks.leaves, 5, 3);
		world.setBlock(x + 21, y + 30, z + 24, Blocks.leaves, 5, 3);
		world.setBlock(x + 22, y + 30, z + 24, Blocks.leaves, 5, 3);
		world.setBlock(x + 23, y + 30, z + 24, Blocks.snow_layer, 0, 3);
		world.setBlock(x + 24, y + 30, z + 24, Blocks.snow_layer, 0, 3);
		world.setBlock(x + 8, y + 30, z + 25, Blocks.snow_layer, 0, 3);
		world.setBlock(x + 9, y + 30, z + 25, Blocks.snow_layer, 2, 3);
		world.setBlock(x + 10, y + 30, z + 25, Blocks.snow_layer, 0, 3);
		world.setBlock(x + 11, y + 30, z + 25, Blocks.leaves, 5, 3);
		world.setBlock(x + 12, y + 30, z + 25, Blocks.leaves, 5, 3);
		world.setBlock(x + 13, y + 30, z + 25, Blocks.leaves, 5, 3);
		world.setBlock(x + 14, y + 30, z + 25, Blocks.leaves, 5, 3);
		world.setBlock(x + 15, y + 30, z + 25, Blocks.leaves, 5, 3);
		world.setBlock(x + 16, y + 30, z + 25, Blocks.leaves, 5, 3);
		world.setBlock(x + 17, y + 30, z + 25, Blocks.leaves, 5, 3);
		world.setBlock(x + 18, y + 30, z + 25, Blocks.leaves, 5, 3);
		world.setBlock(x + 19, y + 30, z + 25, Blocks.leaves, 5, 3);
		world.setBlock(x + 20, y + 30, z + 25, Blocks.leaves, 5, 3);
		world.setBlock(x + 21, y + 30, z + 25, Blocks.snow_layer, 0, 3);
		world.setBlock(x + 22, y + 30, z + 25, Blocks.wool, 14, 3);
		world.setBlock(x + 23, y + 30, z + 25, Blocks.snow_layer, 0, 3);
		world.setBlock(x + 9, y + 30, z + 26, Blocks.snow_layer, 0, 3);
		world.setBlock(x + 10, y + 30, z + 26, Blocks.snow_layer, 0, 3);
		world.setBlock(x + 11, y + 30, z + 26, Blocks.snow_layer, 0, 3);
		world.setBlock(x + 12, y + 30, z + 26, Blocks.wool, 14, 3);
		world.setBlock(x + 13, y + 30, z + 26, Blocks.leaves, 5, 3);
		world.setBlock(x + 14, y + 30, z + 26, Blocks.leaves, 5, 3);
		world.setBlock(x + 15, y + 30, z + 26, Blocks.leaves, 5, 3);
		world.setBlock(x + 16, y + 30, z + 26, Blocks.leaves, 5, 3);
		world.setBlock(x + 17, y + 30, z + 26, Blocks.leaves, 5, 3);
		world.setBlock(x + 18, y + 30, z + 26, Blocks.leaves, 5, 3);
		world.setBlock(x + 19, y + 30, z + 26, Blocks.wool, 5, 3);
		world.setBlock(x + 20, y + 30, z + 26, Blocks.snow_layer, 2, 3);
		world.setBlock(x + 21, y + 30, z + 26, Blocks.snow_layer, 1, 3);
		world.setBlock(x + 22, y + 30, z + 26, Blocks.snow_layer, 0, 3);
		world.setBlock(x + 10, y + 30, z + 27, Blocks.wool, 10, 3);
		world.setBlock(x + 11, y + 30, z + 27, Blocks.snow_layer, 0, 3);
		world.setBlock(x + 12, y + 30, z + 27, Blocks.snow_layer, 0, 3);
		world.setBlock(x + 13, y + 30, z + 27, Blocks.snow_layer, 0, 3);
		world.setBlock(x + 14, y + 30, z + 27, Blocks.snow_layer, 0, 3);
		world.setBlock(x + 15, y + 30, z + 27, Blocks.snow_layer, 0, 3);
		world.setBlock(x + 16, y + 30, z + 27, Blocks.wool, 1, 3);
		world.setBlock(x + 17, y + 30, z + 27, Blocks.snow_layer, 0, 3);
		world.setBlock(x + 18, y + 30, z + 27, Blocks.snow_layer, 0, 3);
		world.setBlock(x + 19, y + 30, z + 27, Blocks.snow_layer, 0, 3);
		world.setBlock(x + 20, y + 30, z + 27, Blocks.snow_layer, 0, 3);
		world.setBlock(x + 21, y + 30, z + 27, Blocks.snow_layer, 0, 3);
		world.setBlock(x + 13, y + 30, z + 28, Blocks.wool, 11, 3);
		world.setBlock(x + 14, y + 30, z + 28, Blocks.snow_layer, 0, 3);
		world.setBlock(x + 15, y + 30, z + 28, Blocks.snow_layer, 1, 3);
		world.setBlock(x + 16, y + 30, z + 28, Blocks.snow_layer, 0, 3);
		world.setBlock(x + 17, y + 30, z + 28, Blocks.snow_layer, 0, 3);
		world.setBlock(x + 18, y + 30, z + 28, Blocks.snow_layer, 0, 3);
		world.setBlock(x + 14, y + 31, z + 3, Blocks.snow_layer, 1, 3);
		world.setBlock(x + 13, y + 31, z + 5, Blocks.snow_layer, 1, 3);
		world.setBlock(x + 14, y + 31, z + 5, Blocks.snow_layer, 1, 3);
		world.setBlock(x + 15, y + 31, z + 5, Blocks.snow_layer, 0, 3);
		world.setBlock(x + 16, y + 31, z + 5, Blocks.snow_layer, 2, 3);
		world.setBlock(x + 17, y + 31, z + 5, Blocks.snow_layer, 1, 3);
		world.setBlock(x + 18, y + 31, z + 5, Blocks.snow_layer, 0, 3);
		world.setBlock(x + 19, y + 31, z + 5, Blocks.snow_layer, 0, 3);
		world.setBlock(x + 9, y + 31, z + 6, Blocks.snow_layer, 1, 3);
		world.setBlock(x + 11, y + 31, z + 6, Blocks.snow_layer, 0, 3);
		world.setBlock(x + 12, y + 31, z + 6, Blocks.snow_layer, 1, 3);
		world.setBlock(x + 13, y + 31, z + 6, Blocks.snow_layer, 0, 3);
		world.setBlock(x + 14, y + 31, z + 6, Blocks.snow_layer, 0, 3);
		world.setBlock(x + 15, y + 31, z + 6, Blocks.wool, 5, 3);
		world.setBlock(x + 16, y + 31, z + 6, Blocks.snow_layer, 0, 3);
		world.setBlock(x + 17, y + 31, z + 6, Blocks.snow_layer, 0, 3);
		world.setBlock(x + 18, y + 31, z + 6, Blocks.snow_layer, 0, 3);
		world.setBlock(x + 19, y + 31, z + 6, Blocks.snow_layer, 0, 3);
		world.setBlock(x + 20, y + 31, z + 6, Blocks.snow_layer, 0, 3);
		world.setBlock(x + 9, y + 31, z + 7, Blocks.snow_layer, 0, 3);
		world.setBlock(x + 10, y + 31, z + 7, Blocks.snow_layer, 0, 3);
		world.setBlock(x + 11, y + 31, z + 7, Blocks.snow_layer, 0, 3);
		world.setBlock(x + 12, y + 31, z + 7, Blocks.snow_layer, 0, 3);
		world.setBlock(x + 13, y + 31, z + 7, Blocks.leaves, 5, 3);
		world.setBlock(x + 14, y + 31, z + 7, Blocks.leaves, 5, 3);
		world.setBlock(x + 15, y + 31, z + 7, Blocks.leaves, 5, 3);
		world.setBlock(x + 16, y + 31, z + 7, Blocks.leaves, 5, 3);
		world.setBlock(x + 17, y + 31, z + 7, Blocks.leaves, 5, 3);
		world.setBlock(x + 18, y + 31, z + 7, Blocks.leaves, 5, 3);
		world.setBlock(x + 19, y + 31, z + 7, Blocks.wool, 14, 3);
		world.setBlock(x + 20, y + 31, z + 7, Blocks.snow_layer, 0, 3);
		world.setBlock(x + 21, y + 31, z + 7, Blocks.snow_layer, 0, 3);
		world.setBlock(x + 22, y + 31, z + 7, Blocks.snow_layer, 0, 3);
		world.setBlock(x + 23, y + 31, z + 7, Blocks.snow_layer, 1, 3);
		world.setBlock(x + 8, y + 31, z + 8, Blocks.snow_layer, 0, 3);
		world.setBlock(x + 9, y + 31, z + 8, Blocks.snow_layer, 0, 3);
		world.setBlock(x + 10, y + 31, z + 8, Blocks.snow_layer, 1, 3);
		world.setBlock(x + 11, y + 31, z + 8, Blocks.leaves, 5, 3);
		world.setBlock(x + 12, y + 31, z + 8, Blocks.leaves, 5, 3);
		world.setBlock(x + 13, y + 31, z + 8, Blocks.leaves, 5, 3);
		world.setBlock(x + 14, y + 31, z + 8, Blocks.leaves, 5, 3);
		world.setBlock(x + 15, y + 31, z + 8, Blocks.leaves, 5, 3);
		world.setBlock(x + 16, y + 31, z + 8, Blocks.leaves, 5, 3);
		world.setBlock(x + 17, y + 31, z + 8, Blocks.leaves, 5, 3);
		world.setBlock(x + 18, y + 31, z + 8, Blocks.leaves, 5, 3);
		world.setBlock(x + 19, y + 31, z + 8, Blocks.leaves, 5, 3);
		world.setBlock(x + 20, y + 31, z + 8, Blocks.leaves, 5, 3);
		world.setBlock(x + 21, y + 31, z + 8, Blocks.snow_layer, 0, 3);
		world.setBlock(x + 22, y + 31, z + 8, Blocks.snow_layer, 1, 3);
		world.setBlock(x + 23, y + 31, z + 8, Blocks.snow_layer, 2, 3);
		world.setBlock(x + 5, y + 31, z + 9, Blocks.snow_layer, 0, 3);
		world.setBlock(x + 7, y + 31, z + 9, Blocks.snow_layer, 2, 3);
		world.setBlock(x + 8, y + 31, z + 9, Blocks.snow_layer, 0, 3);
		world.setBlock(x + 9, y + 31, z + 9, Blocks.wool, 11, 3);
		world.setBlock(x + 10, y + 31, z + 9, Blocks.leaves, 5, 3);
		world.setBlock(x + 11, y + 31, z + 9, Blocks.leaves, 5, 3);
		world.setBlock(x + 12, y + 31, z + 9, Blocks.leaves, 5, 3);
		world.setBlock(x + 13, y + 31, z + 9, Blocks.leaves, 5, 3);
		world.setBlock(x + 14, y + 31, z + 9, Blocks.leaves, 5, 3);
		world.setBlock(x + 15, y + 31, z + 9, Blocks.leaves, 5, 3);
		world.setBlock(x + 16, y + 31, z + 9, Blocks.leaves, 5, 3);
		world.setBlock(x + 17, y + 31, z + 9, Blocks.leaves, 5, 3);
		world.setBlock(x + 18, y + 31, z + 9, Blocks.leaves, 5, 3);
		world.setBlock(x + 19, y + 31, z + 9, Blocks.leaves, 5, 3);
		world.setBlock(x + 20, y + 31, z + 9, Blocks.leaves, 5, 3);
		world.setBlock(x + 21, y + 31, z + 9, Blocks.leaves, 5, 3);
		world.setBlock(x + 22, y + 31, z + 9, Blocks.snow_layer, 0, 3);
		world.setBlock(x + 23, y + 31, z + 9, Blocks.snow_layer, 0, 3);
		world.setBlock(x + 24, y + 31, z + 9, Blocks.snow_layer, 0, 3);
		world.setBlock(x + 7, y + 31, z + 10, Blocks.snow_layer, 0, 3);
		world.setBlock(x + 8, y + 31, z + 10, Blocks.snow_layer, 0, 3);
		world.setBlock(x + 9, y + 31, z + 10, Blocks.leaves, 5, 3);
		world.setBlock(x + 10, y + 31, z + 10, Blocks.leaves, 5, 3);
		world.setBlock(x + 11, y + 31, z + 10, Blocks.leaves, 5, 3);
		world.setBlock(x + 12, y + 31, z + 10, Blocks.leaves, 5, 3);
		world.setBlock(x + 13, y + 31, z + 10, Blocks.leaves, 5, 3);
		world.setBlock(x + 14, y + 31, z + 10, Blocks.leaves, 5, 3);
		world.setBlock(x + 15, y + 31, z + 10, Blocks.leaves, 5, 3);
		world.setBlock(x + 16, y + 31, z + 10, Blocks.leaves, 5, 3);
		world.setBlock(x + 17, y + 31, z + 10, Blocks.leaves, 5, 3);
		world.setBlock(x + 18, y + 31, z + 10, Blocks.leaves, 5, 3);
		world.setBlock(x + 19, y + 31, z + 10, Blocks.leaves, 5, 3);
		world.setBlock(x + 20, y + 31, z + 10, Blocks.leaves, 5, 3);
		world.setBlock(x + 21, y + 31, z + 10, Blocks.leaves, 5, 3);
		world.setBlock(x + 22, y + 31, z + 10, Blocks.leaves, 5, 3);
		world.setBlock(x + 23, y + 31, z + 10, Blocks.wool, 5, 3);
		world.setBlock(x + 24, y + 31, z + 10, Blocks.snow_layer, 0, 3);
		world.setBlock(x + 27, y + 31, z + 10, Blocks.snow_layer, 0, 3);
		world.setBlock(x + 6, y + 31, z + 11, Blocks.snow_layer, 0, 3);
		world.setBlock(x + 7, y + 31, z + 11, Blocks.snow_layer, 0, 3);
		world.setBlock(x + 8, y + 31, z + 11, Blocks.leaves, 5, 3);
		world.setBlock(x + 9, y + 31, z + 11, Blocks.leaves, 5, 3);
		world.setBlock(x + 10, y + 31, z + 11, Blocks.leaves, 5, 3);
		world.setBlock(x + 11, y + 31, z + 11, Blocks.leaves, 5, 3);
		world.setBlock(x + 12, y + 31, z + 11, Blocks.leaves, 5, 3);
		world.setBlock(x + 13, y + 31, z + 11, Blocks.leaves, 5, 3);
		world.setBlock(x + 14, y + 31, z + 11, Blocks.leaves, 5, 3);
		world.setBlock(x + 15, y + 31, z + 11, Blocks.leaves, 5, 3);
		world.setBlock(x + 16, y + 31, z + 11, Blocks.leaves, 5, 3);
		world.setBlock(x + 17, y + 31, z + 11, Blocks.leaves, 5, 3);
		world.setBlock(x + 18, y + 31, z + 11, Blocks.leaves, 5, 3);
		world.setBlock(x + 19, y + 31, z + 11, Blocks.leaves, 5, 3);
		world.setBlock(x + 20, y + 31, z + 11, Blocks.leaves, 5, 3);
		world.setBlock(x + 21, y + 31, z + 11, Blocks.leaves, 5, 3);
		world.setBlock(x + 22, y + 31, z + 11, Blocks.leaves, 5, 3);
		world.setBlock(x + 23, y + 31, z + 11, Blocks.leaves, 5, 3);
		world.setBlock(x + 24, y + 31, z + 11, Blocks.snow_layer, 2, 3);
		world.setBlock(x + 25, y + 31, z + 11, Blocks.snow_layer, 0, 3);
		world.setBlock(x + 5, y + 31, z + 12, Blocks.snow_layer, 0, 3);
		world.setBlock(x + 6, y + 31, z + 12, Blocks.snow_layer, 2, 3);
		world.setBlock(x + 7, y + 31, z + 12, Blocks.wool, 4, 3);
		world.setBlock(x + 8, y + 31, z + 12, Blocks.leaves, 5, 3);
		world.setBlock(x + 9, y + 31, z + 12, Blocks.leaves, 5, 3);
		world.setBlock(x + 10, y + 31, z + 12, Blocks.leaves, 5, 3);
		world.setBlock(x + 11, y + 31, z + 12, Blocks.leaves, 5, 3);
		world.setBlock(x + 12, y + 31, z + 12, Blocks.leaves, 5, 3);
		world.setBlock(x + 13, y + 31, z + 12, Blocks.leaves, 5, 3);
		world.setBlock(x + 14, y + 31, z + 12, Blocks.log, 1, 3);
		world.setBlock(x + 15, y + 31, z + 12, Blocks.log, 1, 3);
		world.setBlock(x + 16, y + 31, z + 12, Blocks.log, 1, 3);
		world.setBlock(x + 17, y + 31, z + 12, Blocks.log, 1, 3);
		world.setBlock(x + 18, y + 31, z + 12, Blocks.leaves, 5, 3);
		world.setBlock(x + 19, y + 31, z + 12, Blocks.leaves, 5, 3);
		world.setBlock(x + 20, y + 31, z + 12, Blocks.leaves, 5, 3);
		world.setBlock(x + 21, y + 31, z + 12, Blocks.leaves, 5, 3);
		world.setBlock(x + 22, y + 31, z + 12, Blocks.leaves, 5, 3);
		world.setBlock(x + 23, y + 31, z + 12, Blocks.leaves, 5, 3);
		world.setBlock(x + 24, y + 31, z + 12, Blocks.snow_layer, 0, 3);
		world.setBlock(x + 25, y + 31, z + 12, Blocks.snow_layer, 1, 3);
		world.setBlock(x + 26, y + 31, z + 12, Blocks.snow_layer, 0, 3);
		world.setBlock(x + 5, y + 31, z + 13, Blocks.snow_layer, 0, 3);
		world.setBlock(x + 6, y + 31, z + 13, Blocks.snow_layer, 0, 3);
		world.setBlock(x + 7, y + 31, z + 13, Blocks.leaves, 5, 3);
		world.setBlock(x + 8, y + 31, z + 13, Blocks.leaves, 5, 3);
		world.setBlock(x + 9, y + 31, z + 13, Blocks.leaves, 5, 3);
		world.setBlock(x + 10, y + 31, z + 13, Blocks.leaves, 5, 3);
		world.setBlock(x + 11, y + 31, z + 13, Blocks.leaves, 5, 3);
		world.setBlock(x + 12, y + 31, z + 13, Blocks.leaves, 5, 3);
		world.setBlock(x + 13, y + 31, z + 13, Blocks.log, 1, 3);
		world.setBlock(x + 14, y + 31, z + 13, Blocks.log, 1, 3);
		world.setBlock(x + 15, y + 31, z + 13, Blocks.log, 1, 3);
		world.setBlock(x + 16, y + 31, z + 13, Blocks.log, 1, 3);
		world.setBlock(x + 17, y + 31, z + 13, Blocks.log, 1, 3);
		world.setBlock(x + 18, y + 31, z + 13, Blocks.log, 1, 3);
		world.setBlock(x + 19, y + 31, z + 13, Blocks.leaves, 5, 3);
		world.setBlock(x + 20, y + 31, z + 13, Blocks.leaves, 5, 3);
		world.setBlock(x + 21, y + 31, z + 13, Blocks.leaves, 5, 3);
		world.setBlock(x + 22, y + 31, z + 13, Blocks.leaves, 5, 3);
		world.setBlock(x + 23, y + 31, z + 13, Blocks.leaves, 5, 3);
		world.setBlock(x + 24, y + 31, z + 13, Blocks.leaves, 5, 3);
		world.setBlock(x + 25, y + 31, z + 13, Blocks.snow_layer, 0, 3);
		world.setBlock(x + 26, y + 31, z + 13, Blocks.snow_layer, 1, 3);
		world.setBlock(x + 5, y + 31, z + 14, Blocks.snow_layer, 1, 3);
		world.setBlock(x + 6, y + 31, z + 14, Blocks.snow_layer, 1, 3);
		world.setBlock(x + 7, y + 31, z + 14, Blocks.leaves, 5, 3);
		world.setBlock(x + 8, y + 31, z + 14, Blocks.leaves, 5, 3);
		world.setBlock(x + 9, y + 31, z + 14, Blocks.leaves, 5, 3);
		world.setBlock(x + 10, y + 31, z + 14, Blocks.leaves, 5, 3);
		world.setBlock(x + 11, y + 31, z + 14, Blocks.leaves, 5, 3);
		world.setBlock(x + 12, y + 31, z + 14, Blocks.log, 1, 3);
		world.setBlock(x + 13, y + 31, z + 14, Blocks.log, 1, 3);
		world.setBlock(x + 14, y + 31, z + 14, Blocks.log, 1, 3);
		world.setBlock(x + 15, y + 31, z + 14, Blocks.log, 1, 3);
		world.setBlock(x + 16, y + 31, z + 14, Blocks.log, 1, 3);
		world.setBlock(x + 17, y + 31, z + 14, Blocks.log, 1, 3);
		world.setBlock(x + 18, y + 31, z + 14, Blocks.log, 1, 3);
		world.setBlock(x + 19, y + 31, z + 14, Blocks.log, 1, 3);
		world.setBlock(x + 20, y + 31, z + 14, Blocks.leaves, 5, 3);
		world.setBlock(x + 21, y + 31, z + 14, Blocks.leaves, 5, 3);
		world.setBlock(x + 22, y + 31, z + 14, Blocks.leaves, 5, 3);
		world.setBlock(x + 23, y + 31, z + 14, Blocks.leaves, 5, 3);
		world.setBlock(x + 24, y + 31, z + 14, Blocks.leaves, 5, 3);
		world.setBlock(x + 25, y + 31, z + 14, Blocks.wool, 4, 3);
		world.setBlock(x + 26, y + 31, z + 14, Blocks.snow_layer, 0, 3);
		world.setBlock(x + 5, y + 31, z + 15, Blocks.snow_layer, 0, 3);
		world.setBlock(x + 6, y + 31, z + 15, Blocks.snow_layer, 0, 3);
		world.setBlock(x + 7, y + 31, z + 15, Blocks.leaves, 5, 3);
		world.setBlock(x + 8, y + 31, z + 15, Blocks.leaves, 5, 3);
		world.setBlock(x + 9, y + 31, z + 15, Blocks.leaves, 5, 3);
		world.setBlock(x + 10, y + 31, z + 15, Blocks.leaves, 5, 3);
		world.setBlock(x + 11, y + 31, z + 15, Blocks.leaves, 5, 3);
		world.setBlock(x + 12, y + 31, z + 15, Blocks.log, 1, 3);
		world.setBlock(x + 13, y + 31, z + 15, Blocks.log, 1, 3);
		world.setBlock(x + 14, y + 31, z + 15, Blocks.log, 1, 3);
		world.setBlock(x + 15, y + 31, z + 15, Blocks.log, 1, 3);
		world.setBlock(x + 16, y + 31, z + 15, Blocks.log, 1, 3);
		world.setBlock(x + 17, y + 31, z + 15, Blocks.log, 1, 3);
		world.setBlock(x + 18, y + 31, z + 15, Blocks.log, 1, 3);
		world.setBlock(x + 19, y + 31, z + 15, Blocks.log, 1, 3);
		world.setBlock(x + 20, y + 31, z + 15, Blocks.leaves, 5, 3);
		world.setBlock(x + 21, y + 31, z + 15, Blocks.leaves, 5, 3);
		world.setBlock(x + 22, y + 31, z + 15, Blocks.leaves, 5, 3);
		world.setBlock(x + 23, y + 31, z + 15, Blocks.leaves, 5, 3);
		world.setBlock(x + 24, y + 31, z + 15, Blocks.leaves, 5, 3);
		world.setBlock(x + 25, y + 31, z + 15, Blocks.snow_layer, 0, 3);
		world.setBlock(x + 26, y + 31, z + 15, Blocks.snow_layer, 0, 3);
		world.setBlock(x + 5, y + 31, z + 16, Blocks.wool, 11, 3);
		world.setBlock(x + 6, y + 31, z + 16, Blocks.snow_layer, 0, 3);
		world.setBlock(x + 7, y + 31, z + 16, Blocks.leaves, 5, 3);
		world.setBlock(x + 8, y + 31, z + 16, Blocks.leaves, 5, 3);
		world.setBlock(x + 9, y + 31, z + 16, Blocks.leaves, 5, 3);
		world.setBlock(x + 10, y + 31, z + 16, Blocks.leaves, 5, 3);
		world.setBlock(x + 11, y + 31, z + 16, Blocks.leaves, 5, 3);
		world.setBlock(x + 12, y + 31, z + 16, Blocks.log, 1, 3);
		world.setBlock(x + 13, y + 31, z + 16, Blocks.log, 1, 3);
		world.setBlock(x + 14, y + 31, z + 16, Blocks.log, 1, 3);
		world.setBlock(x + 15, y + 31, z + 16, Blocks.log, 1, 3);
		world.setBlock(x + 16, y + 31, z + 16, Blocks.log, 1, 3);
		world.setBlock(x + 17, y + 31, z + 16, Blocks.log, 1, 3);
		world.setBlock(x + 18, y + 31, z + 16, Blocks.log, 1, 3);
		world.setBlock(x + 19, y + 31, z + 16, Blocks.log, 1, 3);
		world.setBlock(x + 20, y + 31, z + 16, Blocks.leaves, 5, 3);
		world.setBlock(x + 21, y + 31, z + 16, Blocks.leaves, 5, 3);
		world.setBlock(x + 22, y + 31, z + 16, Blocks.leaves, 5, 3);
		world.setBlock(x + 23, y + 31, z + 16, Blocks.leaves, 5, 3);
		world.setBlock(x + 24, y + 31, z + 16, Blocks.leaves, 5, 3);
		world.setBlock(x + 25, y + 31, z + 16, Blocks.snow_layer, 0, 3);
		world.setBlock(x + 26, y + 31, z + 16, Blocks.snow_layer, 1, 3);
		world.setBlock(x + 5, y + 31, z + 17, Blocks.snow_layer, 1, 3);
		world.setBlock(x + 6, y + 31, z + 17, Blocks.snow_layer, 1, 3);
		world.setBlock(x + 7, y + 31, z + 17, Blocks.leaves, 5, 3);
		world.setBlock(x + 8, y + 31, z + 17, Blocks.leaves, 5, 3);
		world.setBlock(x + 9, y + 31, z + 17, Blocks.leaves, 5, 3);
		world.setBlock(x + 10, y + 31, z + 17, Blocks.leaves, 5, 3);
		world.setBlock(x + 11, y + 31, z + 17, Blocks.leaves, 5, 3);
		world.setBlock(x + 12, y + 31, z + 17, Blocks.log, 1, 3);
		world.setBlock(x + 13, y + 31, z + 17, Blocks.log, 1, 3);
		world.setBlock(x + 14, y + 31, z + 17, Blocks.log, 1, 3);
		world.setBlock(x + 15, y + 31, z + 17, Blocks.log, 1, 3);
		world.setBlock(x + 16, y + 31, z + 17, Blocks.log, 1, 3);
		world.setBlock(x + 17, y + 31, z + 17, Blocks.log, 1, 3);
		world.setBlock(x + 18, y + 31, z + 17, Blocks.log, 1, 3);
		world.setBlock(x + 19, y + 31, z + 17, Blocks.log, 1, 3);
		world.setBlock(x + 20, y + 31, z + 17, Blocks.leaves, 5, 3);
		world.setBlock(x + 21, y + 31, z + 17, Blocks.leaves, 5, 3);
		world.setBlock(x + 22, y + 31, z + 17, Blocks.leaves, 5, 3);
		world.setBlock(x + 23, y + 31, z + 17, Blocks.leaves, 5, 3);
		world.setBlock(x + 24, y + 31, z + 17, Blocks.leaves, 5, 3);
		world.setBlock(x + 25, y + 31, z + 17, Blocks.snow_layer, 1, 3);
		world.setBlock(x + 26, y + 31, z + 17, Blocks.snow_layer, 1, 3);
		world.setBlock(x + 27, y + 31, z + 17, Blocks.snow_layer, 1, 3);
		world.setBlock(x + 5, y + 31, z + 18, Blocks.snow_layer, 1, 3);
		world.setBlock(x + 6, y + 31, z + 18, Blocks.snow_layer, 1, 3);
		world.setBlock(x + 7, y + 31, z + 18, Blocks.leaves, 5, 3);
		world.setBlock(x + 8, y + 31, z + 18, Blocks.leaves, 5, 3);
		world.setBlock(x + 9, y + 31, z + 18, Blocks.leaves, 5, 3);
		world.setBlock(x + 10, y + 31, z + 18, Blocks.leaves, 5, 3);
		world.setBlock(x + 11, y + 31, z + 18, Blocks.leaves, 5, 3);
		world.setBlock(x + 12, y + 31, z + 18, Blocks.leaves, 5, 3);
		world.setBlock(x + 13, y + 31, z + 18, Blocks.log, 1, 3);
		world.setBlock(x + 14, y + 31, z + 18, Blocks.log, 1, 3);
		world.setBlock(x + 15, y + 31, z + 18, Blocks.log, 1, 3);
		world.setBlock(x + 16, y + 31, z + 18, Blocks.log, 1, 3);
		world.setBlock(x + 17, y + 31, z + 18, Blocks.log, 1, 3);
		world.setBlock(x + 18, y + 31, z + 18, Blocks.log, 1, 3);
		world.setBlock(x + 19, y + 31, z + 18, Blocks.leaves, 5, 3);
		world.setBlock(x + 20, y + 31, z + 18, Blocks.leaves, 5, 3);
		world.setBlock(x + 21, y + 31, z + 18, Blocks.leaves, 5, 3);
		world.setBlock(x + 22, y + 31, z + 18, Blocks.leaves, 5, 3);
		world.setBlock(x + 23, y + 31, z + 18, Blocks.leaves, 5, 3);
		world.setBlock(x + 24, y + 31, z + 18, Blocks.leaves, 5, 3);
		world.setBlock(x + 25, y + 31, z + 18, Blocks.snow_layer, 0, 3);
		world.setBlock(x + 26, y + 31, z + 18, Blocks.snow_layer, 0, 3);
		world.setBlock(x + 5, y + 31, z + 19, Blocks.snow_layer, 2, 3);
		world.setBlock(x + 6, y + 31, z + 19, Blocks.snow_layer, 0, 3);
		world.setBlock(x + 7, y + 31, z + 19, Blocks.snow_layer, 1, 3);
		world.setBlock(x + 8, y + 31, z + 19, Blocks.leaves, 5, 3);
		world.setBlock(x + 9, y + 31, z + 19, Blocks.leaves, 5, 3);
		world.setBlock(x + 10, y + 31, z + 19, Blocks.leaves, 5, 3);
		world.setBlock(x + 11, y + 31, z + 19, Blocks.leaves, 5, 3);
		world.setBlock(x + 12, y + 31, z + 19, Blocks.leaves, 5, 3);
		world.setBlock(x + 13, y + 31, z + 19, Blocks.leaves, 5, 3);
		world.setBlock(x + 14, y + 31, z + 19, Blocks.log, 1, 3);
		world.setBlock(x + 15, y + 31, z + 19, Blocks.log, 1, 3);
		world.setBlock(x + 16, y + 31, z + 19, Blocks.log, 1, 3);
		world.setBlock(x + 17, y + 31, z + 19, Blocks.log, 1, 3);
		world.setBlock(x + 18, y + 31, z + 19, Blocks.leaves, 5, 3);
		world.setBlock(x + 19, y + 31, z + 19, Blocks.leaves, 5, 3);
		world.setBlock(x + 20, y + 31, z + 19, Blocks.leaves, 5, 3);
		world.setBlock(x + 21, y + 31, z + 19, Blocks.leaves, 5, 3);
		world.setBlock(x + 22, y + 31, z + 19, Blocks.leaves, 5, 3);
		world.setBlock(x + 23, y + 31, z + 19, Blocks.leaves, 5, 3);
		world.setBlock(x + 24, y + 31, z + 19, Blocks.snow_layer, 0, 3);
		world.setBlock(x + 25, y + 31, z + 19, Blocks.snow_layer, 0, 3);
		world.setBlock(x + 6, y + 31, z + 20, Blocks.snow_layer, 0, 3);
		world.setBlock(x + 7, y + 31, z + 20, Blocks.snow_layer, 0, 3);
		world.setBlock(x + 8, y + 31, z + 20, Blocks.leaves, 5, 3);
		world.setBlock(x + 9, y + 31, z + 20, Blocks.leaves, 5, 3);
		world.setBlock(x + 10, y + 31, z + 20, Blocks.leaves, 5, 3);
		world.setBlock(x + 11, y + 31, z + 20, Blocks.leaves, 5, 3);
		world.setBlock(x + 12, y + 31, z + 20, Blocks.leaves, 5, 3);
		world.setBlock(x + 13, y + 31, z + 20, Blocks.leaves, 5, 3);
		world.setBlock(x + 14, y + 31, z + 20, Blocks.leaves, 5, 3);
		world.setBlock(x + 15, y + 31, z + 20, Blocks.leaves, 5, 3);
		world.setBlock(x + 16, y + 31, z + 20, Blocks.leaves, 5, 3);
		world.setBlock(x + 17, y + 31, z + 20, Blocks.leaves, 5, 3);
		world.setBlock(x + 18, y + 31, z + 20, Blocks.leaves, 5, 3);
		world.setBlock(x + 19, y + 31, z + 20, Blocks.leaves, 5, 3);
		world.setBlock(x + 20, y + 31, z + 20, Blocks.leaves, 5, 3);
		world.setBlock(x + 21, y + 31, z + 20, Blocks.leaves, 5, 3);
		world.setBlock(x + 22, y + 31, z + 20, Blocks.leaves, 5, 3);
		world.setBlock(x + 23, y + 31, z + 20, Blocks.leaves, 5, 3);
		world.setBlock(x + 24, y + 31, z + 20, Blocks.wool, 1, 3);
		world.setBlock(x + 25, y + 31, z + 20, Blocks.snow_layer, 0, 3);
		world.setBlock(x + 7, y + 31, z + 21, Blocks.snow_layer, 0, 3);
		world.setBlock(x + 8, y + 31, z + 21, Blocks.snow_layer, 1, 3);
		world.setBlock(x + 9, y + 31, z + 21, Blocks.leaves, 5, 3);
		world.setBlock(x + 10, y + 31, z + 21, Blocks.leaves, 5, 3);
		world.setBlock(x + 11, y + 31, z + 21, Blocks.leaves, 5, 3);
		world.setBlock(x + 12, y + 31, z + 21, Blocks.leaves, 5, 3);
		world.setBlock(x + 13, y + 31, z + 21, Blocks.leaves, 5, 3);
		world.setBlock(x + 14, y + 31, z + 21, Blocks.leaves, 5, 3);
		world.setBlock(x + 15, y + 31, z + 21, Blocks.leaves, 5, 3);
		world.setBlock(x + 16, y + 31, z + 21, Blocks.leaves, 5, 3);
		world.setBlock(x + 17, y + 31, z + 21, Blocks.leaves, 5, 3);
		world.setBlock(x + 18, y + 31, z + 21, Blocks.leaves, 5, 3);
		world.setBlock(x + 19, y + 31, z + 21, Blocks.leaves, 5, 3);
		world.setBlock(x + 20, y + 31, z + 21, Blocks.leaves, 5, 3);
		world.setBlock(x + 21, y + 31, z + 21, Blocks.leaves, 5, 3);
		world.setBlock(x + 22, y + 31, z + 21, Blocks.leaves, 5, 3);
		world.setBlock(x + 23, y + 31, z + 21, Blocks.snow_layer, 0, 3);
		world.setBlock(x + 24, y + 31, z + 21, Blocks.snow_layer, 0, 3);
		world.setBlock(x + 25, y + 31, z + 21, Blocks.snow_layer, 2, 3);
		world.setBlock(x + 7, y + 31, z + 22, Blocks.wool, 10, 3);
		world.setBlock(x + 8, y + 31, z + 22, Blocks.snow_layer, 1, 3);
		world.setBlock(x + 9, y + 31, z + 22, Blocks.wool, 11, 3);
		world.setBlock(x + 10, y + 31, z + 22, Blocks.leaves, 5, 3);
		world.setBlock(x + 11, y + 31, z + 22, Blocks.leaves, 5, 3);
		world.setBlock(x + 12, y + 31, z + 22, Blocks.leaves, 5, 3);
		world.setBlock(x + 13, y + 31, z + 22, Blocks.leaves, 5, 3);
		world.setBlock(x + 14, y + 31, z + 22, Blocks.leaves, 5, 3);
		world.setBlock(x + 15, y + 31, z + 22, Blocks.leaves, 5, 3);
		world.setBlock(x + 16, y + 31, z + 22, Blocks.leaves, 5, 3);
		world.setBlock(x + 17, y + 31, z + 22, Blocks.leaves, 5, 3);
		world.setBlock(x + 18, y + 31, z + 22, Blocks.leaves, 5, 3);
		world.setBlock(x + 19, y + 31, z + 22, Blocks.leaves, 5, 3);
		world.setBlock(x + 20, y + 31, z + 22, Blocks.leaves, 5, 3);
		world.setBlock(x + 21, y + 31, z + 22, Blocks.leaves, 5, 3);
		world.setBlock(x + 22, y + 31, z + 22, Blocks.wool, 11, 3);
		world.setBlock(x + 23, y + 31, z + 22, Blocks.snow_layer, 0, 3);
		world.setBlock(x + 24, y + 31, z + 22, Blocks.snow_layer, 1, 3);
		world.setBlock(x + 8, y + 31, z + 23, Blocks.snow_layer, 0, 3);
		world.setBlock(x + 9, y + 31, z + 23, Blocks.snow_layer, 0, 3);
		world.setBlock(x + 10, y + 31, z + 23, Blocks.snow_layer, 0, 3);
		world.setBlock(x + 11, y + 31, z + 23, Blocks.leaves, 5, 3);
		world.setBlock(x + 12, y + 31, z + 23, Blocks.leaves, 5, 3);
		world.setBlock(x + 13, y + 31, z + 23, Blocks.leaves, 5, 3);
		world.setBlock(x + 14, y + 31, z + 23, Blocks.leaves, 5, 3);
		world.setBlock(x + 15, y + 31, z + 23, Blocks.leaves, 5, 3);
		world.setBlock(x + 16, y + 31, z + 23, Blocks.leaves, 5, 3);
		world.setBlock(x + 17, y + 31, z + 23, Blocks.leaves, 5, 3);
		world.setBlock(x + 18, y + 31, z + 23, Blocks.leaves, 5, 3);
		world.setBlock(x + 19, y + 31, z + 23, Blocks.leaves, 5, 3);
		world.setBlock(x + 20, y + 31, z + 23, Blocks.leaves, 5, 3);
		world.setBlock(x + 21, y + 31, z + 23, Blocks.snow_layer, 0, 3);
		world.setBlock(x + 22, y + 31, z + 23, Blocks.snow_layer, 0, 3);
		world.setBlock(x + 23, y + 31, z + 23, Blocks.snow_layer, 1, 3);
		world.setBlock(x + 8, y + 31, z + 24, Blocks.snow_layer, 2, 3);
		world.setBlock(x + 9, y + 31, z + 24, Blocks.snow_layer, 0, 3);
		world.setBlock(x + 10, y + 31, z + 24, Blocks.snow_layer, 0, 3);
		world.setBlock(x + 11, y + 31, z + 24, Blocks.snow_layer, 0, 3);
		world.setBlock(x + 12, y + 31, z + 24, Blocks.snow_layer, 0, 3);
		world.setBlock(x + 13, y + 31, z + 24, Blocks.leaves, 5, 3);
		world.setBlock(x + 14, y + 31, z + 24, Blocks.leaves, 5, 3);
		world.setBlock(x + 15, y + 31, z + 24, Blocks.leaves, 5, 3);
		world.setBlock(x + 16, y + 31, z + 24, Blocks.leaves, 5, 3);
		world.setBlock(x + 17, y + 31, z + 24, Blocks.leaves, 5, 3);
		world.setBlock(x + 18, y + 31, z + 24, Blocks.leaves, 5, 3);
		world.setBlock(x + 19, y + 31, z + 24, Blocks.snow_layer, 1, 3);
		world.setBlock(x + 20, y + 31, z + 24, Blocks.snow_layer, 0, 3);
		world.setBlock(x + 21, y + 31, z + 24, Blocks.snow_layer, 2, 3);
		world.setBlock(x + 22, y + 31, z + 24, Blocks.snow_layer, 0, 3);
		world.setBlock(x + 11, y + 31, z + 25, Blocks.snow_layer, 0, 3);
		world.setBlock(x + 12, y + 31, z + 25, Blocks.snow_layer, 1, 3);
		world.setBlock(x + 13, y + 31, z + 25, Blocks.snow_layer, 0, 3);
		world.setBlock(x + 14, y + 31, z + 25, Blocks.wool, 5, 3);
		world.setBlock(x + 15, y + 31, z + 25, Blocks.snow_layer, 0, 3);
		world.setBlock(x + 16, y + 31, z + 25, Blocks.snow_layer, 0, 3);
		world.setBlock(x + 17, y + 31, z + 25, Blocks.snow_layer, 0, 3);
		world.setBlock(x + 18, y + 31, z + 25, Blocks.snow_layer, 0, 3);
		world.setBlock(x + 19, y + 31, z + 25, Blocks.snow_layer, 2, 3);
		world.setBlock(x + 20, y + 31, z + 25, Blocks.snow_layer, 0, 3);
		world.setBlock(x + 22, y + 31, z + 25, Blocks.snow_layer, 0, 3);
		world.setBlock(x + 12, y + 31, z + 26, Blocks.snow_layer, 0, 3);
		world.setBlock(x + 13, y + 31, z + 26, Blocks.snow_layer, 1, 3);
		world.setBlock(x + 14, y + 31, z + 26, Blocks.snow_layer, 0, 3);
		world.setBlock(x + 15, y + 31, z + 26, Blocks.snow_layer, 0, 3);
		world.setBlock(x + 16, y + 31, z + 26, Blocks.snow_layer, 1, 3);
		world.setBlock(x + 17, y + 31, z + 26, Blocks.snow_layer, 0, 3);
		world.setBlock(x + 18, y + 31, z + 26, Blocks.snow_layer, 1, 3);
		world.setBlock(x + 19, y + 31, z + 26, Blocks.snow_layer, 2, 3);
		world.setBlock(x + 10, y + 31, z + 27, Blocks.snow_layer, 0, 3);
		world.setBlock(x + 16, y + 31, z + 27, Blocks.snow_layer, 0, 3);
		world.setBlock(x + 13, y + 31, z + 28, Blocks.snow_layer, 1, 3);
		world.setBlock(x + 15, y + 32, z + 6, Blocks.snow_layer, 2, 3);
		world.setBlock(x + 13, y + 32, z + 7, Blocks.snow_layer, 1, 3);
		world.setBlock(x + 14, y + 32, z + 7, Blocks.snow_layer, 2, 3);
		world.setBlock(x + 15, y + 32, z + 7, Blocks.snow_layer, 0, 3);
		world.setBlock(x + 16, y + 32, z + 7, Blocks.snow_layer, 1, 3);
		world.setBlock(x + 17, y + 32, z + 7, Blocks.snow_layer, 0, 3);
		world.setBlock(x + 18, y + 32, z + 7, Blocks.snow_layer, 0, 3);
		world.setBlock(x + 19, y + 32, z + 7, Blocks.snow_layer, 1, 3);
		world.setBlock(x + 11, y + 32, z + 8, Blocks.snow_layer, 2, 3);
		world.setBlock(x + 12, y + 32, z + 8, Blocks.snow_layer, 0, 3);
		world.setBlock(x + 13, y + 32, z + 8, Blocks.snow_layer, 0, 3);
		world.setBlock(x + 14, y + 32, z + 8, Blocks.snow_layer, 1, 3);
		world.setBlock(x + 15, y + 32, z + 8, Blocks.snow_layer, 0, 3);
		world.setBlock(x + 16, y + 32, z + 8, Blocks.wool, 4, 3);
		world.setBlock(x + 17, y + 32, z + 8, Blocks.snow_layer, 0, 3);
		world.setBlock(x + 18, y + 32, z + 8, Blocks.snow_layer, 0, 3);
		world.setBlock(x + 19, y + 32, z + 8, Blocks.snow_layer, 0, 3);
		world.setBlock(x + 20, y + 32, z + 8, Blocks.snow_layer, 0, 3);
		world.setBlock(x + 9, y + 32, z + 9, Blocks.snow_layer, 0, 3);
		world.setBlock(x + 10, y + 32, z + 9, Blocks.snow_layer, 1, 3);
		world.setBlock(x + 11, y + 32, z + 9, Blocks.snow_layer, 0, 3);
		world.setBlock(x + 12, y + 32, z + 9, Blocks.snow_layer, 0, 3);
		world.setBlock(x + 13, y + 32, z + 9, Blocks.wool, 1, 3);
		world.setBlock(x + 14, y + 32, z + 9, Blocks.leaves, 5, 3);
		world.setBlock(x + 15, y + 32, z + 9, Blocks.leaves, 5, 3);
		world.setBlock(x + 16, y + 32, z + 9, Blocks.leaves, 5, 3);
		world.setBlock(x + 17, y + 32, z + 9, Blocks.leaves, 5, 3);
		world.setBlock(x + 18, y + 32, z + 9, Blocks.wool, 11, 3);
		world.setBlock(x + 19, y + 32, z + 9, Blocks.snow_layer, 0, 3);
		world.setBlock(x + 20, y + 32, z + 9, Blocks.snow_layer, 0, 3);
		world.setBlock(x + 21, y + 32, z + 9, Blocks.snow_layer, 0, 3);
		world.setBlock(x + 9, y + 32, z + 10, Blocks.snow_layer, 1, 3);
		world.setBlock(x + 10, y + 32, z + 10, Blocks.snow_layer, 0, 3);
		world.setBlock(x + 11, y + 32, z + 10, Blocks.snow_layer, 0, 3);
		world.setBlock(x + 12, y + 32, z + 10, Blocks.leaves, 5, 3);
		world.setBlock(x + 13, y + 32, z + 10, Blocks.leaves, 5, 3);
		world.setBlock(x + 14, y + 32, z + 10, Blocks.leaves, 5, 3);
		world.setBlock(x + 15, y + 32, z + 10, Blocks.leaves, 5, 3);
		world.setBlock(x + 16, y + 32, z + 10, Blocks.leaves, 5, 3);
		world.setBlock(x + 17, y + 32, z + 10, Blocks.leaves, 5, 3);
		world.setBlock(x + 18, y + 32, z + 10, Blocks.leaves, 5, 3);
		world.setBlock(x + 19, y + 32, z + 10, Blocks.leaves, 5, 3);
		world.setBlock(x + 20, y + 32, z + 10, Blocks.snow_layer, 0, 3);
		world.setBlock(x + 21, y + 32, z + 10, Blocks.snow_layer, 0, 3);
		world.setBlock(x + 22, y + 32, z + 10, Blocks.snow_layer, 0, 3);
		world.setBlock(x + 23, y + 32, z + 10, Blocks.snow_layer, 1, 3);
		world.setBlock(x + 8, y + 32, z + 11, Blocks.snow_layer, 1, 3);
		world.setBlock(x + 9, y + 32, z + 11, Blocks.snow_layer, 0, 3);
		world.setBlock(x + 10, y + 32, z + 11, Blocks.snow_layer, 0, 3);
		world.setBlock(x + 11, y + 32, z + 11, Blocks.leaves, 5, 3);
		world.setBlock(x + 12, y + 32, z + 11, Blocks.leaves, 5, 3);
		world.setBlock(x + 13, y + 32, z + 11, Blocks.leaves, 5, 3);
		world.setBlock(x + 14, y + 32, z + 11, Blocks.leaves, 5, 3);
		world.setBlock(x + 15, y + 32, z + 11, Blocks.leaves, 5, 3);
		world.setBlock(x + 16, y + 32, z + 11, Blocks.leaves, 5, 3);
		world.setBlock(x + 17, y + 32, z + 11, Blocks.leaves, 5, 3);
		world.setBlock(x + 18, y + 32, z + 11, Blocks.leaves, 5, 3);
		world.setBlock(x + 19, y + 32, z + 11, Blocks.leaves, 5, 3);
		world.setBlock(x + 20, y + 32, z + 11, Blocks.leaves, 5, 3);
		world.setBlock(x + 21, y + 32, z + 11, Blocks.snow_layer, 0, 3);
		world.setBlock(x + 22, y + 32, z + 11, Blocks.snow_layer, 0, 3);
		world.setBlock(x + 23, y + 32, z + 11, Blocks.snow_layer, 0, 3);
		world.setBlock(x + 7, y + 32, z + 12, Blocks.snow_layer, 0, 3);
		world.setBlock(x + 8, y + 32, z + 12, Blocks.snow_layer, 0, 3);
		world.setBlock(x + 9, y + 32, z + 12, Blocks.snow_layer, 0, 3);
		world.setBlock(x + 10, y + 32, z + 12, Blocks.leaves, 5, 3);
		world.setBlock(x + 11, y + 32, z + 12, Blocks.leaves, 5, 3);
		world.setBlock(x + 12, y + 32, z + 12, Blocks.leaves, 5, 3);
		world.setBlock(x + 13, y + 32, z + 12, Blocks.leaves, 5, 3);
		world.setBlock(x + 14, y + 32, z + 12, Blocks.log, 1, 3);
		world.setBlock(x + 15, y + 32, z + 12, Blocks.log, 1, 3);
		world.setBlock(x + 16, y + 32, z + 12, Blocks.log, 1, 3);
		world.setBlock(x + 17, y + 32, z + 12, Blocks.log, 1, 3);
		world.setBlock(x + 18, y + 32, z + 12, Blocks.leaves, 5, 3);
		world.setBlock(x + 19, y + 32, z + 12, Blocks.leaves, 5, 3);
		world.setBlock(x + 20, y + 32, z + 12, Blocks.leaves, 5, 3);
		world.setBlock(x + 21, y + 32, z + 12, Blocks.leaves, 5, 3);
		world.setBlock(x + 22, y + 32, z + 12, Blocks.wool, 11, 3);
		world.setBlock(x + 23, y + 32, z + 12, Blocks.snow_layer, 0, 3);
		world.setBlock(x + 7, y + 32, z + 13, Blocks.snow_layer, 2, 3);
		world.setBlock(x + 8, y + 32, z + 13, Blocks.snow_layer, 0, 3);
		world.setBlock(x + 9, y + 32, z + 13, Blocks.wool, 5, 3);
		world.setBlock(x + 10, y + 32, z + 13, Blocks.leaves, 5, 3);
		world.setBlock(x + 11, y + 32, z + 13, Blocks.leaves, 5, 3);
		world.setBlock(x + 12, y + 32, z + 13, Blocks.leaves, 5, 3);
		world.setBlock(x + 13, y + 32, z + 13, Blocks.log, 1, 3);
		world.setBlock(x + 14, y + 32, z + 13, Blocks.log, 1, 3);
		world.setBlock(x + 15, y + 32, z + 13, Blocks.log, 1, 3);
		world.setBlock(x + 16, y + 32, z + 13, Blocks.log, 1, 3);
		world.setBlock(x + 17, y + 32, z + 13, Blocks.log, 1, 3);
		world.setBlock(x + 18, y + 32, z + 13, Blocks.log, 1, 3);
		world.setBlock(x + 19, y + 32, z + 13, Blocks.leaves, 5, 3);
		world.setBlock(x + 20, y + 32, z + 13, Blocks.leaves, 5, 3);

		generate_r01(world, rand, x, y, z);
		return true;

	}
	public boolean generate_r01(World world, Random rand, int x, int y, int z)
	{

		world.setBlock(x + 21, y + 32, z + 13, Blocks.leaves, 5, 3);
		world.setBlock(x + 22, y + 32, z + 13, Blocks.snow_layer, 1, 3);
		world.setBlock(x + 23, y + 32, z + 13, Blocks.snow_layer, 0, 3);
		world.setBlock(x + 24, y + 32, z + 13, Blocks.snow_layer, 0, 3);
		world.setBlock(x + 7, y + 32, z + 14, Blocks.snow_layer, 1, 3);
		world.setBlock(x + 8, y + 32, z + 14, Blocks.snow_layer, 0, 3);
		world.setBlock(x + 9, y + 32, z + 14, Blocks.leaves, 5, 3);
		world.setBlock(x + 10, y + 32, z + 14, Blocks.leaves, 5, 3);
		world.setBlock(x + 11, y + 32, z + 14, Blocks.leaves, 5, 3);
		world.setBlock(x + 12, y + 32, z + 14, Blocks.log, 1, 3);
		world.setBlock(x + 13, y + 32, z + 14, Blocks.log, 1, 3);
		world.setBlock(x + 14, y + 32, z + 14, Blocks.log, 1, 3);
		world.setBlock(x + 15, y + 32, z + 14, Blocks.log, 1, 3);
		world.setBlock(x + 16, y + 32, z + 14, Blocks.log, 1, 3);
		world.setBlock(x + 17, y + 32, z + 14, Blocks.log, 1, 3);
		world.setBlock(x + 18, y + 32, z + 14, Blocks.log, 1, 3);
		world.setBlock(x + 19, y + 32, z + 14, Blocks.log, 1, 3);
		world.setBlock(x + 20, y + 32, z + 14, Blocks.leaves, 5, 3);
		world.setBlock(x + 21, y + 32, z + 14, Blocks.leaves, 5, 3);
		world.setBlock(x + 22, y + 32, z + 14, Blocks.leaves, 5, 3);
		world.setBlock(x + 23, y + 32, z + 14, Blocks.wool, 10, 3);
		world.setBlock(x + 24, y + 32, z + 14, Blocks.snow_layer, 0, 3);
		world.setBlock(x + 25, y + 32, z + 14, Blocks.snow_layer, 2, 3);
		world.setBlock(x + 7, y + 32, z + 15, Blocks.snow_layer, 0, 3);
		world.setBlock(x + 8, y + 32, z + 15, Blocks.snow_layer, 0, 3);
		world.setBlock(x + 9, y + 32, z + 15, Blocks.leaves, 5, 3);
		world.setBlock(x + 10, y + 32, z + 15, Blocks.leaves, 5, 3);
		world.setBlock(x + 11, y + 32, z + 15, Blocks.leaves, 5, 3);
		world.setBlock(x + 12, y + 32, z + 15, Blocks.log, 1, 3);
		world.setBlock(x + 13, y + 32, z + 15, Blocks.log, 1, 3);
		world.setBlock(x + 14, y + 32, z + 15, Blocks.log, 1, 3);
		world.setBlock(x + 15, y + 32, z + 15, Blocks.log, 1, 3);
		world.setBlock(x + 16, y + 32, z + 15, Blocks.log, 1, 3);
		world.setBlock(x + 17, y + 32, z + 15, Blocks.log, 1, 3);
		world.setBlock(x + 18, y + 32, z + 15, Blocks.log, 1, 3);
		world.setBlock(x + 19, y + 32, z + 15, Blocks.log, 1, 3);
		world.setBlock(x + 20, y + 32, z + 15, Blocks.leaves, 5, 3);
		world.setBlock(x + 21, y + 32, z + 15, Blocks.leaves, 5, 3);
		world.setBlock(x + 22, y + 32, z + 15, Blocks.leaves, 5, 3);
		world.setBlock(x + 23, y + 32, z + 15, Blocks.snow_layer, 0, 3);
		world.setBlock(x + 24, y + 32, z + 15, Blocks.snow_layer, 1, 3);
		world.setBlock(x + 5, y + 32, z + 16, Blocks.snow_layer, 0, 3);
		world.setBlock(x + 7, y + 32, z + 16, Blocks.snow_layer, 0, 3);
		world.setBlock(x + 8, y + 32, z + 16, Blocks.snow_layer, 1, 3);
		world.setBlock(x + 9, y + 32, z + 16, Blocks.leaves, 5, 3);
		world.setBlock(x + 10, y + 32, z + 16, Blocks.leaves, 5, 3);
		world.setBlock(x + 11, y + 32, z + 16, Blocks.leaves, 5, 3);
		world.setBlock(x + 12, y + 32, z + 16, Blocks.log, 1, 3);
		world.setBlock(x + 13, y + 32, z + 16, Blocks.log, 1, 3);
		world.setBlock(x + 14, y + 32, z + 16, Blocks.log, 1, 3);
		world.setBlock(x + 15, y + 32, z + 16, Blocks.log, 1, 3);
		world.setBlock(x + 16, y + 32, z + 16, Blocks.log, 1, 3);
		world.setBlock(x + 17, y + 32, z + 16, Blocks.log, 1, 3);
		world.setBlock(x + 18, y + 32, z + 16, Blocks.log, 1, 3);
		world.setBlock(x + 19, y + 32, z + 16, Blocks.log, 1, 3);
		world.setBlock(x + 20, y + 32, z + 16, Blocks.leaves, 5, 3);
		world.setBlock(x + 21, y + 32, z + 16, Blocks.leaves, 5, 3);
		world.setBlock(x + 22, y + 32, z + 16, Blocks.leaves, 5, 3);
		world.setBlock(x + 23, y + 32, z + 16, Blocks.snow_layer, 0, 3);
		world.setBlock(x + 24, y + 32, z + 16, Blocks.snow_layer, 2, 3);
		world.setBlock(x + 7, y + 32, z + 17, Blocks.snow_layer, 0, 3);
		world.setBlock(x + 8, y + 32, z + 17, Blocks.snow_layer, 0, 3);
		world.setBlock(x + 9, y + 32, z + 17, Blocks.leaves, 5, 3);
		world.setBlock(x + 10, y + 32, z + 17, Blocks.leaves, 5, 3);
		world.setBlock(x + 11, y + 32, z + 17, Blocks.leaves, 5, 3);
		world.setBlock(x + 12, y + 32, z + 17, Blocks.log, 1, 3);
		world.setBlock(x + 13, y + 32, z + 17, Blocks.log, 1, 3);
		world.setBlock(x + 14, y + 32, z + 17, Blocks.log, 1, 3);
		world.setBlock(x + 15, y + 32, z + 17, Blocks.log, 1, 3);
		world.setBlock(x + 16, y + 32, z + 17, Blocks.log, 1, 3);
		world.setBlock(x + 17, y + 32, z + 17, Blocks.log, 1, 3);
		world.setBlock(x + 18, y + 32, z + 17, Blocks.log, 1, 3);
		world.setBlock(x + 19, y + 32, z + 17, Blocks.log, 1, 3);
		world.setBlock(x + 20, y + 32, z + 17, Blocks.leaves, 5, 3);
		world.setBlock(x + 21, y + 32, z + 17, Blocks.leaves, 5, 3);
		world.setBlock(x + 22, y + 32, z + 17, Blocks.leaves, 5, 3);
		world.setBlock(x + 23, y + 32, z + 17, Blocks.snow_layer, 1, 3);
		world.setBlock(x + 24, y + 32, z + 17, Blocks.wool, 5, 3);
		world.setBlock(x + 7, y + 32, z + 18, Blocks.snow_layer, 0, 3);
		world.setBlock(x + 8, y + 32, z + 18, Blocks.snow_layer, 0, 3);
		world.setBlock(x + 9, y + 32, z + 18, Blocks.snow_layer, 0, 3);
